File: examples/data/A_1.txt
#EXPORTTYPE:DATA ALL
#FILE:
#FORMAT:NETZSCH5
#FTYPE:ANSI
#IDENTITY:
#DECIMAL:POINT
#SEPARATOR:SEMICOLON
#MTYPE:DSC
#INSTRUMENT:NETZSCH DSC 200F3
#PROJECT:
#DATE/TIME:19.03.2025 11:40
#CORR. FILE:
#TEMPCAL:temp_cal_3Kmin.ngb-td5
#SENSITIVITY:sens_cal_3Kmin.ngb-ed5
#LABORATORY:
#OPERATOR:
#REMARK:CR 1370.2,7; SS(80.7) 50.5; W 277.8-50.5=27.3; tot 1447.4
#SAMPLE:
#SAMPLE MASS /mg:77.8
#MATERIAL:
#REFERENCE:Ref.
#REFERENCE MASS /mg:0
#TYPE OF CRUCIBLE:High pressure, steel
#SAMPLE CRUCIBLE MASS /mg:1370.2
#REFERENCE CRUCIBLE MASS /mg:1385.5
#M.RANGE /�V:5000
#TAU-R:---
#CORR. CODE:000
#EXO:-1
#RANGE:25�C....200�C/-7.0....7.0K/min
#SEGMENT:S1-5/5
#SEG. 1:25�C/7.0(K/min)/50�C
#SEG. 2:50�C/00:15/50�C
#SEG. 3:50�C/5.0(K/min)/200�C
#SEG. 4:200�C/00:30/200�C
#SEG. 5:200�C/7.0(K/min)/50�C

##Temp./C;Time/min;DSC/(mW/mg);Gas Flow(purge2)/(ml/min);Gas Flow(protective)/(ml/min);Sensit./(uV/mW);Segment
 24.96900; 0.00000;-9.661650e-004;50.00000;100.00000;2.76076;1
 24.97100; 0.13333;-9.342663e-004;50.00000;100.00000;2.76077;1
 25.01500; 0.26667; 4.139216e-004;50.00000;100.00000;2.76089;1
 25.17200; 0.40000; 6.058414e-003;50.00000;100.00000;2.76133;1
 25.48900; 0.53333; 1.871227e-002;50.00000;100.00000;2.76221;1
 25.95600; 0.66667; 3.900221e-002;50.00000;100.00000;2.76350;1
 26.54100; 0.80000; 6.586915e-002;50.00000;100.00000;2.76512;1
 27.21200; 0.93333; 9.765929e-002;50.00000;100.00000;2.76696;1
 27.94500; 1.06667;       0.13254;50.00000;100.00000;2.76896;1
 28.72100; 1.20000;       0.16899;50.00000;100.00000;2.77107;1
 29.52900; 1.33333;       0.20559;50.00000;100.00000;2.77325;1
 30.35800; 1.46667;       0.24146;50.00000;100.00000;2.77547;1
 31.20500; 1.60000;       0.27580;50.00000;100.00000;2.77773;1
 32.06700; 1.73333;       0.30813;50.00000;100.00000;2.78000;1
 32.93800; 1.86667;       0.33813;50.00000;100.00000;2.78229;1
 33.81700; 2.00000;       0.36549;50.00000;100.00000;2.78458;1
 34.70500; 2.13333;       0.39091;50.00000;100.00000;2.78688;1
 35.59600; 2.26667;       0.41454;50.00000;100.00000;2.78916;1
 36.49400; 2.40000;       0.43644;50.00000;100.00000;2.79145;1
 37.39700; 2.53333;       0.45662;50.00000;100.00000;2.79373;1
 38.30400; 2.66667;       0.47511;50.00000;100.00000;2.79600;1
 39.21300; 2.80000;       0.49196;50.00000;100.00000;2.79826;1
 40.12800; 2.93333;       0.50748;50.00000;100.00000;2.80052;1
 41.04300; 3.06667;       0.52161;50.00000;100.00000;2.80275;1
 41.96200; 3.20000;       0.53450;50.00000;100.00000;2.80498;1
 42.88300; 3.33333;       0.54614;50.00000;100.00000;2.80719;1
 43.80500; 3.46667;       0.55671;50.00000;100.00000;2.80939;1
 44.64700; 3.58750;       0.56537;50.00000;100.00000;2.81138;2
 45.53700; 3.72083;       0.57314;50.00000;100.00000;2.81347;2
 46.29800; 3.85417;       0.57505;50.00000;100.00000;2.81523;2
 46.92700; 3.98750;       0.56984;50.00000;100.00000;2.81669;2
 47.44400; 4.12083;       0.55794;50.00000;100.00000;2.81787;2
 47.87400; 4.25417;       0.54037;50.00000;100.00000;2.81885;2
 48.23300; 4.38750;       0.51837;50.00000;100.00000;2.81967;2
 48.53500; 4.52083;       0.49328;50.00000;100.00000;2.82036;2
 48.78800; 4.65417;       0.46620;50.00000;100.00000;2.82093;2
 49.00500; 4.78750;       0.43802;50.00000;100.00000;2.82142;2
 49.19000; 4.92083;       0.40963;50.00000;100.00000;2.82183;2
 49.35000; 5.05417;       0.38149;50.00000;100.00000;2.82219;2
 49.48700; 5.18750;       0.35407;50.00000;100.00000;2.82250;2
 49.60600; 5.32083;       0.32760;50.00000;100.00000;2.82277;2
 49.70700; 5.45417;       0.30234;50.00000;100.00000;2.82299;2
 49.79600; 5.58750;       0.27840;50.00000;100.00000;2.82319;2
 49.87000; 5.72083;       0.25586;50.00000;100.00000;2.82336;2
 49.94100; 5.85417;       0.23474;50.00000;100.00000;2.82352;2
 49.99900; 5.98750;       0.21499;50.00000;100.00000;2.82365;2
 50.05000; 6.12083;       0.19664;50.00000;100.00000;2.82376;2
 50.09600; 6.25417;       0.17966;50.00000;100.00000;2.82386;2
 50.13600; 6.38750;       0.16394;50.00000;100.00000;2.82395;2
 50.17200; 6.52083;       0.14950;50.00000;100.00000;2.82403;2
 50.20200; 6.65417;       0.13612;50.00000;100.00000;2.82410;2
 50.22900; 6.78750;       0.12384;50.00000;100.00000;2.82416;2
 50.25400; 6.92083;       0.11257;50.00000;100.00000;2.82421;2
 50.27500; 7.05417;       0.10222;50.00000;100.00000;2.82426;2
 50.29400; 7.18750; 9.273926e-002;50.00000;100.00000;2.82430;2
 50.31000; 7.32083; 8.406765e-002;50.00000;100.00000;2.82434;2
 50.32400; 7.45417; 7.616380e-002;50.00000;100.00000;2.82437;2
 50.33700; 7.58750; 6.898239e-002;50.00000;100.00000;2.82440;2
 50.35000; 7.72083; 6.240872e-002;50.00000;100.00000;2.82443;2
 50.36100; 7.85417; 5.644989e-002;50.00000;100.00000;2.82445;2
 50.37100; 7.98750; 5.097036e-002;50.00000;100.00000;2.82447;2
 50.37800; 8.12083; 4.599109e-002;50.00000;100.00000;2.82449;2
 50.38700; 8.25417; 4.147698e-002;50.00000;100.00000;2.82451;2
 50.39200; 8.38750; 3.735550e-002;50.00000;100.00000;2.82452;2
 50.39800; 8.52083; 3.361591e-002;50.00000;100.00000;2.82453;2
 50.40400; 8.65417; 3.023048e-002;50.00000;100.00000;2.82455;2
 50.40900; 8.78750; 2.715414e-002;50.00000;100.00000;2.82456;2
 50.41200; 8.92083; 2.431748e-002;50.00000;100.00000;2.82456;2
 50.41600; 9.05417; 2.181407e-002;50.00000;100.00000;2.82457;2
 50.41800; 9.18750; 1.946702e-002;50.00000;100.00000;2.82458;2
 50.42200; 9.32083; 1.741498e-002;50.00000;100.00000;2.82459;2
 50.42400; 9.45417; 1.550539e-002;50.00000;100.00000;2.82459;2
 50.42700; 9.58750; 1.380754e-002;50.00000;100.00000;2.82460;2
 50.43000; 9.72083; 1.227288e-002;50.00000;100.00000;2.82461;2
 50.43200; 9.85417; 1.083200e-002;50.00000;100.00000;2.82461;2
 50.43300; 9.98750; 9.592531e-003;50.00000;100.00000;2.82461;2
 50.43400;10.12083; 8.446803e-003;50.00000;100.00000;2.82461;2
 50.43500;10.25417; 7.415645e-003;50.00000;100.00000;2.82462;2
 50.43700;10.38750; 6.488602e-003;50.00000;100.00000;2.82462;2
 50.43800;10.52083; 5.644923e-003;50.00000;100.00000;2.82462;2
 50.43900;10.65417; 4.881096e-003;50.00000;100.00000;2.82462;2
 50.44300;10.78750; 4.158816e-003;50.00000;100.00000;2.82463;2
 50.44400;10.92083; 3.537335e-003;50.00000;100.00000;2.82464;2
 50.44300;11.05417; 2.957591e-003;50.00000;100.00000;2.82463;2
 50.44200;11.18750; 2.468111e-003;50.00000;100.00000;2.82463;2
 50.44400;11.32083; 2.089617e-003;50.00000;100.00000;2.82464;2
 50.44700;11.45417; 1.679841e-003;50.00000;100.00000;2.82464;2
 50.44800;11.58750; 1.343047e-003;50.00000;100.00000;2.82464;2
 50.44900;11.72083; 1.079159e-003;50.00000;100.00000;2.82465;2
 50.44900;11.85417; 8.083635e-004;50.00000;100.00000;2.82465;2
 50.45100;11.98750; 5.027800e-004;50.00000;100.00000;2.82465;2
 50.45200;12.12083; 2.909693e-004;50.00000;100.00000;2.82465;2
 50.45200;12.25417; 3.058991e-005;50.00000;100.00000;2.82465;2
 50.45400;12.38750;-1.847269e-004;50.00000;100.00000;2.82466;2
 50.45400;12.52083;-3.340108e-004;50.00000;100.00000;2.82466;2
 50.45500;12.65417;-5.215183e-004;50.00000;100.00000;2.82466;2
 50.45200;12.78750;-6.776421e-004;50.00000;100.00000;2.82465;2
 50.45300;12.92083;-8.200173e-004;50.00000;100.00000;2.82466;2
 50.45400;13.05417;-9.450336e-004;50.00000;100.00000;2.82466;2
 50.45500;13.18750;-1.070050e-003;50.00000;100.00000;2.82466;2
 50.45500;13.32083;-1.201975e-003;50.00000;100.00000;2.82466;2
 50.45400;13.45417;-1.340810e-003;50.00000;100.00000;2.82466;2
 50.45300;13.58750;-1.469229e-003;50.00000;100.00000;2.82466;2
 50.45100;13.72083;-1.611503e-003;50.00000;100.00000;2.82465;2
 50.44800;13.85417;-1.805819e-003;50.00000;100.00000;2.82464;2
 50.44400;13.98750;-2.045235e-003;50.00000;100.00000;2.82464;2
 50.44400;14.12083;-2.257011e-003;50.00000;100.00000;2.82464;2
 50.44100;14.25417;-2.427027e-003;50.00000;100.00000;2.82463;2
 50.44100;14.38750;-2.524237e-003;50.00000;100.00000;2.82463;2
 50.44000;14.52083;-2.551978e-003;50.00000;100.00000;2.82463;2
 50.44000;14.65417;-2.527675e-003;50.00000;100.00000;2.82463;2
 50.44000;14.78750;-2.517260e-003;50.00000;100.00000;2.82463;2
 50.44000;14.92083;-2.472127e-003;50.00000;100.00000;2.82463;2
 50.44100;15.05417;-2.423556e-003;50.00000;100.00000;2.82463;2
 50.44200;15.18750;-2.374984e-003;50.00000;100.00000;2.82463;2
 50.44100;15.32083;-2.333290e-003;50.00000;100.00000;2.82463;2
 50.44100;15.45417;-2.274270e-003;50.00000;100.00000;2.82463;2
 50.44300;15.58750;-2.229204e-003;50.00000;100.00000;2.82463;2
 50.44500;15.72083;-2.114703e-003;50.00000;100.00000;2.82464;2
 50.44600;15.85417;-2.031414e-003;50.00000;100.00000;2.82464;2
 50.44800;15.98750;-1.941216e-003;50.00000;100.00000;2.82464;2
 50.44900;16.12083;-1.830154e-003;50.00000;100.00000;2.82465;2
 50.45300;16.25417;-1.729609e-003;50.00000;100.00000;2.82466;2
 50.45200;16.38750;-1.674027e-003;50.00000;100.00000;2.82465;2
 50.45300;16.52083;-1.656703e-003;50.00000;100.00000;2.82466;2
 50.45400;16.65417;-1.698397e-003;50.00000;100.00000;2.82466;2
 50.45300;16.78750;-1.729609e-003;50.00000;100.00000;2.82466;2
 50.45200;16.92083;-1.774707e-003;50.00000;100.00000;2.82465;2
 50.45200;17.05417;-1.840670e-003;50.00000;100.00000;2.82465;2
 50.45100;17.18750;-1.920486e-003;50.00000;100.00000;2.82465;2
 50.44900;17.32083;-1.972495e-003;50.00000;100.00000;2.82465;2
 50.44900;17.45417;-2.073176e-003;50.00000;100.00000;2.82465;2
 50.44700;17.58750;-2.142544e-003;50.00000;100.00000;2.82464;2
 50.44600;17.72083;-2.243191e-003;50.00000;100.00000;2.82464;2
 50.44400;17.85417;-2.312559e-003;50.00000;100.00000;2.82464;2
 50.44300;17.98750;-2.361130e-003;50.00000;100.00000;2.82463;2
 50.44200;18.12083;-2.465250e-003;50.00000;100.00000;2.82463;2
 50.43900;18.25417;-2.538057e-003;50.00000;100.00000;2.82462;2
 50.43800;18.38750;-2.649121e-003;50.00000;100.00000;2.82462;2
 50.43500;18.52083;-2.725401e-003;50.00000;100.00000;2.82462;2
 50.43700;18.65583;-2.753241e-003;50.00000;100.00000;2.82462;3
 50.46800;18.78917;-1.726642e-003;50.00000;100.00000;2.82469;3
 50.57900;18.92250; 2.699100e-003;50.00000;100.00000;2.82494;3
 50.78900;19.05583; 1.182299e-002;50.00000;100.00000;2.82540;3
 51.08600;19.18917; 2.570721e-002;50.00000;100.00000;2.82606;3
 51.45900;19.32250; 4.364220e-002;50.00000;100.00000;2.82688;3
 51.88900;19.45583; 6.431907e-002;50.00000;100.00000;2.82782;3
 52.36700;19.58917; 8.657902e-002;50.00000;100.00000;2.82886;3
 52.87900;19.72250;       0.10989;50.00000;100.00000;2.82997;3
 53.41600;19.85583;       0.13374;50.00000;100.00000;2.83113;3
 53.97500;19.98917;       0.15743;50.00000;100.00000;2.83233;3
 54.55200;20.12250;       0.18042;50.00000;100.00000;2.83356;3
 55.14000;20.25583;       0.20245;50.00000;100.00000;2.83481;3
 55.74000;20.38917;       0.22342;50.00000;100.00000;2.83607;3
 56.35100;20.52250;       0.24306;50.00000;100.00000;2.83735;3
 56.96900;20.65583;       0.26140;50.00000;100.00000;2.83863;3
 57.59200;20.78917;       0.27844;50.00000;100.00000;2.83991;3
 58.21900;20.92250;       0.29420;50.00000;100.00000;2.84120;3
 58.85300;21.05583;       0.30871;50.00000;100.00000;2.84248;3
 59.49100;21.18917;       0.32203;50.00000;100.00000;2.84377;3
 60.13300;21.32250;       0.33418;50.00000;100.00000;2.84506;3
 60.77900;21.45583;       0.34534;50.00000;100.00000;2.84634;3
 61.42600;21.58917;       0.35550;50.00000;100.00000;2.84762;3
 62.07700;21.72250;       0.36470;50.00000;100.00000;2.84889;3
 62.72900;21.85583;       0.37312;50.00000;100.00000;2.85015;3
 63.38300;21.98917;       0.38078;50.00000;100.00000;2.85141;3
 64.04000;22.12250;       0.38778;50.00000;100.00000;2.85267;3
 64.69700;22.25583;       0.39411;50.00000;100.00000;2.85391;3
 65.35600;22.38917;       0.39993;50.00000;100.00000;2.85515;3
 66.01400;22.52250;       0.40524;50.00000;100.00000;2.85637;3
 66.67500;22.65583;       0.41013;50.00000;100.00000;2.85760;3
 67.33600;22.78917;       0.41447;50.00000;100.00000;2.85881;3
 67.99700;22.92250;       0.41849;50.00000;100.00000;2.86001;3
 68.66000;23.05583;       0.42209;50.00000;100.00000;2.86120;3
 69.32200;23.18917;       0.42534;50.00000;100.00000;2.86238;3
 69.98800;23.32250;       0.42827;50.00000;100.00000;2.86356;3
 70.65000;23.45583;       0.43091;50.00000;100.00000;2.86472;3
 71.31400;23.58917;       0.43327;50.00000;100.00000;2.86587;3
 71.98000;23.72250;       0.43541;50.00000;100.00000;2.86701;3
 72.64400;23.85583;       0.43730;50.00000;100.00000;2.86814;3
 73.31100;23.98917;       0.43905;50.00000;100.00000;2.86927;3
 73.97500;24.12250;       0.44064;50.00000;100.00000;2.87038;3
 74.64100;24.25583;       0.44205;50.00000;100.00000;2.87148;3
 75.30700;24.38917;       0.44328;50.00000;100.00000;2.87257;3
 75.97300;24.52250;       0.44442;50.00000;100.00000;2.87365;3
 76.64000;24.65583;       0.44547;50.00000;100.00000;2.87472;3
 77.30700;24.78917;       0.44636;50.00000;100.00000;2.87579;3
 77.97400;24.92250;       0.44715;50.00000;100.00000;2.87684;3
 78.63900;25.05583;       0.44782;50.00000;100.00000;2.87787;3
 79.30500;25.18917;       0.44844;50.00000;100.00000;2.87890;3
 79.97200;25.32250;       0.44896;50.00000;100.00000;2.87992;3
 80.63800;25.45583;       0.44937;50.00000;100.00000;2.88092;3
 81.30600;25.58917;       0.44980;50.00000;100.00000;2.88192;3
 81.97200;25.72250;       0.45014;50.00000;100.00000;2.88290;3
 82.63900;25.85583;       0.45041;50.00000;100.00000;2.88387;3
 83.30600;25.98917;       0.45064;50.00000;100.00000;2.88484;3
 83.97100;26.12250;       0.45084;50.00000;100.00000;2.88579;3
 84.64300;26.25583;       0.45101;50.00000;100.00000;2.88673;3
 85.30900;26.38917;       0.45112;50.00000;100.00000;2.88766;3
 85.97600;26.52250;       0.45117;50.00000;100.00000;2.88858;3
 86.64300;26.65583;       0.45119;50.00000;100.00000;2.88949;3
 87.31100;26.78917;       0.45118;50.00000;100.00000;2.89039;3
 87.97800;26.92250;       0.45115;50.00000;100.00000;2.89127;3
 88.64600;27.05583;       0.45114;50.00000;100.00000;2.89215;3
 89.31200;27.18917;       0.45109;50.00000;100.00000;2.89301;3
 89.98000;27.32250;       0.45101;50.00000;100.00000;2.89386;3
 90.64800;27.45583;       0.45092;50.00000;100.00000;2.89471;3
 91.31700;27.58917;       0.45086;50.00000;100.00000;2.89554;3
 91.98300;27.72250;       0.45074;50.00000;100.00000;2.89636;3
 92.65000;27.85583;       0.45066;50.00000;100.00000;2.89717;3
 93.32000;27.98917;       0.45053;50.00000;100.00000;2.89797;3
 93.98700;28.12250;       0.45047;50.00000;100.00000;2.89875;3
 94.65400;28.25583;       0.45031;50.00000;100.00000;2.89953;3
 95.32100;28.38917;       0.45015;50.00000;100.00000;2.90029;3
 95.98800;28.52250;       0.44999;50.00000;100.00000;2.90104;3
 96.65500;28.65583;       0.44979;50.00000;100.00000;2.90179;3
 97.32400;28.78917;       0.44962;50.00000;100.00000;2.90252;3
 97.99200;28.92250;       0.44947;50.00000;100.00000;2.90324;3
 98.65900;29.05583;       0.44929;50.00000;100.00000;2.90395;3
 99.32700;29.18917;       0.44913;50.00000;100.00000;2.90464;3
 99.99500;29.32250;       0.44899;50.00000;100.00000;2.90533;3
100.66300;29.45583;       0.44882;50.00000;100.00000;2.90601;3
101.33000;29.58917;       0.44859;50.00000;100.00000;2.90667;3
101.99900;29.72250;       0.44839;50.00000;100.00000;2.90732;3
102.66600;29.85583;       0.44821;50.00000;100.00000;2.90797;3
103.33400;29.98917;       0.44799;50.00000;100.00000;2.90860;3
104.00200;30.12250;       0.44782;50.00000;100.00000;2.90922;3
104.67100;30.25583;       0.44760;50.00000;100.00000;2.90982;3
105.33900;30.38917;       0.44741;50.00000;100.00000;2.91042;3
106.00600;30.52250;       0.44721;50.00000;100.00000;2.91100;3
106.67200;30.65583;       0.44694;50.00000;100.00000;2.91158;3
107.34000;30.78917;       0.44665;50.00000;100.00000;2.91214;3
108.00700;30.92250;       0.44641;50.00000;100.00000;2.91269;3
108.67400;31.05583;       0.44614;50.00000;100.00000;2.91323;3
109.34400;31.18917;       0.44592;50.00000;100.00000;2.91376;3
110.01000;31.32250;       0.44573;50.00000;100.00000;2.91428;3
110.67900;31.45583;       0.44550;50.00000;100.00000;2.91478;3
111.34700;31.58917;       0.44529;50.00000;100.00000;2.91528;3
112.01400;31.72250;       0.44511;50.00000;100.00000;2.91576;3
112.68300;31.85583;       0.44486;50.00000;100.00000;2.91624;3
113.35100;31.98917;       0.44460;50.00000;100.00000;2.91670;3
114.01800;32.12250;       0.44439;50.00000;100.00000;2.91715;3
114.68600;32.25583;       0.44417;50.00000;100.00000;2.91758;3
115.35300;32.38917;       0.44391;50.00000;100.00000;2.91801;3
116.02000;32.52250;       0.44366;50.00000;100.00000;2.91842;3
116.68900;32.65583;       0.44336;50.00000;100.00000;2.91883;3
117.35400;32.78917;       0.44302;50.00000;100.00000;2.91922;3
118.02000;32.92250;       0.44276;50.00000;100.00000;2.91960;3
118.69000;33.05583;       0.44254;50.00000;100.00000;2.91997;3
119.35900;33.18917;       0.44238;50.00000;100.00000;2.92033;3
120.02500;33.32250;       0.44218;50.00000;100.00000;2.92068;3
120.69400;33.45583;       0.44196;50.00000;100.00000;2.92101;3
121.36000;33.58917;       0.44171;50.00000;100.00000;2.92134;3
122.02700;33.72250;       0.44150;50.00000;100.00000;2.92165;3
122.69500;33.85583;       0.44127;50.00000;100.00000;2.92195;3
123.36200;33.98917;       0.44100;50.00000;100.00000;2.92224;3
124.03100;34.12250;       0.44082;50.00000;100.00000;2.92252;3
124.69800;34.25583;       0.44062;50.00000;100.00000;2.92279;3
125.36500;34.38917;       0.44038;50.00000;100.00000;2.92304;3
126.03100;34.52250;       0.44013;50.00000;100.00000;2.92329;3
126.70000;34.65583;       0.43991;50.00000;100.00000;2.92352;3
127.36800;34.78917;       0.43973;50.00000;100.00000;2.92374;3
128.03500;34.92250;       0.43951;50.00000;100.00000;2.92395;3
128.70300;35.05583;       0.43926;50.00000;100.00000;2.92415;3
129.37000;35.18917;       0.43906;50.00000;100.00000;2.92434;3
130.03900;35.32250;       0.43887;50.00000;100.00000;2.92451;3
130.70399;35.45583;       0.43864;50.00000;100.00000;2.92468;3
131.37199;35.58917;       0.43846;50.00000;100.00000;2.92483;3
132.04100;35.72250;       0.43826;50.00000;100.00000;2.92497;3
132.70900;35.85583;       0.43806;50.00000;100.00000;2.92510;3
133.37500;35.98917;       0.43785;50.00000;100.00000;2.92522;3
134.04300;36.12250;       0.43770;50.00000;100.00000;2.92533;3
134.71100;36.25583;       0.43747;50.00000;100.00000;2.92542;3
135.37900;36.38917;       0.43730;50.00000;100.00000;2.92551;3
136.04601;36.52250;       0.43712;50.00000;100.00000;2.92558;3
136.71400;36.65583;       0.43693;50.00000;100.00000;2.92564;3
137.38200;36.78917;       0.43674;50.00000;100.00000;2.92569;3
138.04700;36.92250;       0.43653;50.00000;100.00000;2.92573;3
138.71700;37.05583;       0.43643;50.00000;100.00000;2.92576;3
139.38600;37.18917;       0.43631;50.00000;100.00000;2.92577;3
140.05400;37.32250;       0.43618;50.00000;100.00000;2.92578;3
140.72200;37.45583;       0.43604;50.00000;100.00000;2.92577;3
141.39000;37.58917;       0.43589;50.00000;100.00000;2.92575;3
142.05600;37.72250;       0.43571;50.00000;100.00000;2.92572;3
142.72301;37.85583;       0.43553;50.00000;100.00000;2.92568;3
143.39000;37.98917;       0.43533;50.00000;100.00000;2.92563;3
144.05701;38.12250;       0.43518;50.00000;100.00000;2.92556;3
144.72301;38.25583;       0.43499;50.00000;100.00000;2.92549;3
145.38901;38.38917;       0.43479;50.00000;100.00000;2.92540;3
146.05600;38.52250;       0.43464;50.00000;100.00000;2.92530;3
146.72501;38.65583;       0.43455;50.00000;100.00000;2.92519;3
147.39000;38.78917;       0.43447;50.00000;100.00000;2.92507;3
148.05701;38.92250;       0.43435;50.00000;100.00000;2.92494;3
148.72400;39.05583;       0.43423;50.00000;100.00000;2.92479;3
149.39301;39.18917;       0.43413;50.00000;100.00000;2.92464;3
150.06000;39.32250;       0.43408;50.00000;100.00000;2.92447;3
150.72800;39.45583;       0.43405;50.00000;100.00000;2.92429;3
151.39500;39.58917;       0.43404;50.00000;100.00000;2.92410;3
152.06200;39.72250;       0.43403;50.00000;100.00000;2.92390;3
152.72900;39.85583;       0.43402;50.00000;100.00000;2.92369;3
153.39700;39.98917;       0.43398;50.00000;100.00000;2.92346;3
154.06300;40.12250;       0.43396;50.00000;100.00000;2.92323;3
154.73300;40.25583;       0.43389;50.00000;100.00000;2.92298;3
155.39900;40.38917;       0.43382;50.00000;100.00000;2.92272;3
156.06599;40.52250;       0.43374;50.00000;100.00000;2.92245;3
156.73399;40.65583;       0.43362;50.00000;100.00000;2.92217;3
157.40199;40.78917;       0.43355;50.00000;100.00000;2.92187;3
158.06900;40.92250;       0.43343;50.00000;100.00000;2.92157;3
158.73700;41.05583;       0.43332;50.00000;100.00000;2.92125;3
159.40401;41.18917;       0.43326;50.00000;100.00000;2.92093;3
160.07201;41.32250;       0.43316;50.00000;100.00000;2.92059;3
160.73900;41.45583;       0.43309;50.00000;100.00000;2.92024;3
161.40601;41.58917;       0.43298;50.00000;100.00000;2.91988;3
162.07300;41.72250;       0.43286;50.00000;100.00000;2.91951;3
162.74001;41.85583;       0.43281;50.00000;100.00000;2.91912;3
163.40800;41.98917;       0.43273;50.00000;100.00000;2.91873;3
164.07401;42.12250;       0.43267;50.00000;100.00000;2.91832;3
164.74200;42.25583;       0.43254;50.00000;100.00000;2.91790;3
165.40900;42.38917;       0.43241;50.00000;100.00000;2.91747;3
166.07600;42.52250;       0.43228;50.00000;100.00000;2.91703;3
166.74400;42.65583;       0.43221;50.00000;100.00000;2.91658;3
167.41100;42.78917;       0.43224;50.00000;100.00000;2.91612;3
168.07800;42.92250;       0.43248;50.00000;100.00000;2.91564;3
168.74500;43.05583;       0.43248;50.00000;100.00000;2.91516;3
169.41299;43.18917;       0.43242;50.00000;100.00000;2.91466;3
170.08000;43.32250;       0.43235;50.00000;100.00000;2.91415;3
170.74699;43.45583;       0.43234;50.00000;100.00000;2.91363;3
171.41299;43.58917;       0.43230;50.00000;100.00000;2.91310;3
172.08200;43.72250;       0.43243;50.00000;100.00000;2.91256;3
172.75000;43.85583;       0.43260;50.00000;100.00000;2.91200;3
173.41701;43.98917;       0.43264;50.00000;100.00000;2.91144;3
174.08400;44.12250;       0.43272;50.00000;100.00000;2.91086;3
174.75101;44.25583;       0.43304;50.00000;100.00000;2.91027;3
175.41800;44.38917;       0.43336;50.00000;100.00000;2.90968;3
176.08600;44.52250;       0.43370;50.00000;100.00000;2.90906;3
176.75200;44.65583;       0.43409;50.00000;100.00000;2.90844;3
177.42000;44.78917;       0.43450;50.00000;100.00000;2.90781;3
178.08600;44.92250;       0.43482;50.00000;100.00000;2.90717;3
178.75301;45.05583;       0.43510;50.00000;100.00000;2.90651;3
179.42101;45.18917;       0.43547;50.00000;100.00000;2.90585;3
180.08600;45.32250;       0.43654;50.00000;100.00000;2.90517;3
180.75500;45.45583;       0.43744;50.00000;100.00000;2.90448;3
181.42101;45.58917;       0.43808;50.00000;100.00000;2.90378;3
182.08701;45.72250;       0.43836;50.00000;100.00000;2.90307;3
182.75400;45.85583;       0.43843;50.00000;100.00000;2.90235;3
183.42101;45.98917;       0.43874;50.00000;100.00000;2.90162;3
184.08701;46.12250;       0.43909;50.00000;100.00000;2.90088;3
184.75500;46.25583;       0.43927;50.00000;100.00000;2.90012;3
185.42200;46.38917;       0.43930;50.00000;100.00000;2.89935;3
186.09000;46.52250;       0.43913;50.00000;100.00000;2.89857;3
186.75700;46.65583;       0.43885;50.00000;100.00000;2.89779;3
187.42300;46.78917;       0.43860;50.00000;100.00000;2.89699;3
188.09000;46.92250;       0.43848;50.00000;100.00000;2.89618;3
188.75700;47.05583;       0.43818;50.00000;100.00000;2.89535;3
189.42400;47.18917;       0.43765;50.00000;100.00000;2.89452;3
190.09200;47.32250;       0.43710;50.00000;100.00000;2.89368;3
190.75900;47.45583;       0.43659;50.00000;100.00000;2.89282;3
191.42599;47.58917;       0.43608;50.00000;100.00000;2.89195;3
192.09300;47.72250;       0.43561;50.00000;100.00000;2.89108;3
192.75999;47.85583;       0.43510;50.00000;100.00000;2.89019;3
193.42599;47.98917;       0.43466;50.00000;100.00000;2.88929;3
194.09399;48.12250;       0.43423;50.00000;100.00000;2.88838;3
194.76300;48.25583;       0.43384;50.00000;100.00000;2.88746;3
195.42700;48.38917;       0.43338;50.00000;100.00000;2.88653;3
196.09500;48.52250;       0.43302;50.00000;100.00000;2.88558;3
196.76500;48.65750;       0.43248;50.00000;100.00000;2.88463;4
197.33501;48.79083;       0.42721;50.00000;100.00000;2.88380;4
197.78300;48.92417;       0.41415;50.00000;100.00000;2.88315;4
198.13901;49.05750;       0.39479;50.00000;100.00000;2.88262;4
198.42500;49.19083;       0.37110;50.00000;100.00000;2.88220;4
198.65700;49.32417;       0.34486;50.00000;100.00000;2.88186;4
198.84700;49.45750;       0.31748;50.00000;100.00000;2.88158;4
199.00600;49.59083;       0.28998;50.00000;100.00000;2.88134;4
199.13901;49.72417;       0.26319;50.00000;100.00000;2.88114;4
199.25000;49.85750;       0.23748;50.00000;100.00000;2.88097;4
199.34500;49.99083;       0.21321;50.00000;100.00000;2.88083;4
199.42500;50.12417;       0.19046;50.00000;100.00000;2.88071;4
199.49400;50.25750;       0.16943;50.00000;100.00000;2.88061;4
199.55200;50.39083;       0.15017;50.00000;100.00000;2.88052;4
199.60201;50.52417;       0.13248;50.00000;100.00000;2.88044;4
199.64700;50.65750;       0.11640;50.00000;100.00000;2.88038;4
199.68401;50.79083;       0.10182;50.00000;100.00000;2.88032;4
199.71800;50.92417; 8.859799e-002;50.00000;100.00000;2.88027;4
199.74600;51.05750; 7.666812e-002;50.00000;100.00000;2.88023;4
199.77000;51.19083; 6.593978e-002;50.00000;100.00000;2.88019;4
199.79100;51.32417; 5.627011e-002;50.00000;100.00000;2.88016;4
199.81100;51.45750; 4.765573e-002;50.00000;100.00000;2.88013;4
199.82800;51.59083; 3.995031e-002;50.00000;100.00000;2.88010;4
199.84300;51.72417; 3.301430e-002;50.00000;100.00000;2.88008;4
199.85400;51.85750; 2.683075e-002;50.00000;100.00000;2.88006;4
199.86800;51.99083; 2.140978e-002;50.00000;100.00000;2.88004;4
199.87801;52.12417; 1.662896e-002;50.00000;100.00000;2.88003;4
199.88901;52.25750; 1.234179e-002;50.00000;100.00000;2.88001;4
199.89999;52.39083; 8.616395e-003;50.00000;100.00000;2.87999;4
199.90700;52.52417; 5.197538e-003;50.00000;100.00000;2.87998;4
199.91200;52.65750; 2.173707e-003;50.00000;100.00000;2.87998;4
199.92101;52.79083;-4.586975e-004;50.00000;100.00000;2.87996;4
199.92500;52.92417;-2.764062e-003;50.00000;100.00000;2.87996;4
199.92999;53.05750;-4.851548e-003;50.00000;100.00000;2.87995;4
199.93500;53.19083;-6.683665e-003;50.00000;100.00000;2.87994;4
199.94000;53.32417;-8.253599e-003;50.00000;100.00000;2.87993;4
199.94299;53.45750;-9.700879e-003;50.00000;100.00000;2.87993;4
199.94501;53.59083;-1.100171e-002;50.00000;100.00000;2.87993;4
199.94800;53.72417;-1.207784e-002;50.00000;100.00000;2.87992;4
199.95300;53.85750;-1.299742e-002;50.00000;100.00000;2.87991;4
199.95700;53.99083;-1.387270e-002;50.00000;100.00000;2.87991;4
199.95799;54.12417;-1.456739e-002;50.00000;100.00000;2.87991;4
199.96100;54.25750;-1.518725e-002;50.00000;100.00000;2.87990;4
199.96400;54.39083;-1.571517e-002;50.00000;100.00000;2.87990;4
199.96800;54.52417;-1.616822e-002;50.00000;100.00000;2.87989;4
199.96800;54.65750;-1.654619e-002;50.00000;100.00000;2.87989;4
199.97000;54.79083;-1.689360e-002;50.00000;100.00000;2.87989;4
199.97301;54.92417;-1.722744e-002;50.00000;100.00000;2.87988;4
199.97200;55.05750;-1.749640e-002;50.00000;100.00000;2.87988;4
199.97501;55.19083;-1.773149e-002;50.00000;100.00000;2.87988;4
199.97600;55.32417;-1.789838e-002;50.00000;100.00000;2.87988;4
199.98000;55.45750;-1.798369e-002;50.00000;100.00000;2.87987;4
199.98100;55.59083;-1.804502e-002;50.00000;100.00000;2.87987;4
199.98300;55.72417;-1.809959e-002;50.00000;100.00000;2.87987;4
199.98399;55.85750;-1.816774e-002;50.00000;100.00000;2.87987;4
199.98801;55.99083;-1.812024e-002;50.00000;100.00000;2.87986;4
199.99001;56.12417;-1.810671e-002;50.00000;100.00000;2.87986;4
199.99100;56.25750;-1.817145e-002;50.00000;100.00000;2.87986;4
199.99001;56.39083;-1.825654e-002;50.00000;100.00000;2.87986;4
199.99100;56.52417;-1.822594e-002;50.00000;100.00000;2.87986;4
199.99300;56.65750;-1.822262e-002;50.00000;100.00000;2.87985;4
199.99300;56.79083;-1.818516e-002;50.00000;100.00000;2.87985;4
199.99600;56.92417;-1.813762e-002;50.00000;100.00000;2.87985;4
199.99699;57.05750;-1.805594e-002;50.00000;100.00000;2.87985;4
199.99699;57.19083;-1.802870e-002;50.00000;100.00000;2.87985;4
199.99899;57.32417;-1.800836e-002;50.00000;100.00000;2.87984;4
199.99800;57.45750;-1.795042e-002;50.00000;100.00000;2.87984;4
199.99899;57.59083;-1.792663e-002;50.00000;100.00000;2.87984;4
200.00200;57.72417;-1.786887e-002;50.00000;100.00000;2.87984;4
200.00301;57.85750;-1.776336e-002;50.00000;100.00000;2.87984;4
200.00301;57.99083;-1.771909e-002;50.00000;100.00000;2.87984;4
200.00200;58.12417;-1.777693e-002;50.00000;100.00000;2.87984;4
200.00101;58.25750;-1.780073e-002;50.00000;100.00000;2.87984;4
200.00200;58.39083;-1.774288e-002;50.00000;100.00000;2.87984;4
200.00301;58.52417;-1.765099e-002;50.00000;100.00000;2.87984;4
200.00301;58.65750;-1.753521e-002;50.00000;100.00000;2.87984;4
200.00500;58.79083;-1.744336e-002;50.00000;100.00000;2.87983;4
200.00600;58.92417;-1.738551e-002;50.00000;100.00000;2.87983;4
200.00700;59.05750;-1.727999e-002;50.00000;100.00000;2.87983;4
200.00600;59.19083;-1.719823e-002;50.00000;100.00000;2.87983;4
200.00800;59.32417;-1.709275e-002;50.00000;100.00000;2.87983;4
200.00900;59.45750;-1.702809e-002;50.00000;100.00000;2.87983;4
200.00800;59.59083;-1.695314e-002;50.00000;100.00000;2.87983;4
200.00999;59.72417;-1.691236e-002;50.00000;100.00000;2.87983;4
200.01100;59.85750;-1.681025e-002;50.00000;100.00000;2.87983;4
200.01100;59.99083;-1.673533e-002;50.00000;100.00000;2.87983;4
200.01300;60.12417;-1.661964e-002;50.00000;100.00000;2.87982;4
200.01300;60.25750;-1.653451e-002;50.00000;100.00000;2.87982;4
200.01401;60.39083;-1.644942e-002;50.00000;100.00000;2.87982;4
200.01401;60.52417;-1.637110e-002;50.00000;100.00000;2.87982;4
200.01401;60.65750;-1.630640e-002;50.00000;100.00000;2.87982;4
200.01401;60.79083;-1.622468e-002;50.00000;100.00000;2.87982;4
200.01401;60.92417;-1.613614e-002;50.00000;100.00000;2.87982;4
200.01601;61.05750;-1.608856e-002;50.00000;100.00000;2.87982;4
200.01601;61.19083;-1.600002e-002;50.00000;100.00000;2.87982;4
200.01700;61.32417;-1.593877e-002;50.00000;100.00000;2.87982;4
200.01700;61.45750;-1.588769e-002;50.00000;100.00000;2.87982;4
200.01801;61.59083;-1.579239e-002;50.00000;100.00000;2.87981;4
200.01801;61.72417;-1.575152e-002;50.00000;100.00000;2.87981;4
200.01700;61.85750;-1.568338e-002;50.00000;100.00000;2.87982;4
200.01900;61.99083;-1.560174e-002;50.00000;100.00000;2.87981;4
200.01900;62.12417;-1.554044e-002;50.00000;100.00000;2.87981;4
200.02000;62.25750;-1.547579e-002;50.00000;100.00000;2.87981;4
200.01900;62.39083;-1.539402e-002;50.00000;100.00000;2.87981;4
200.02100;62.52417;-1.532600e-002;50.00000;100.00000;2.87981;4
200.02100;62.65750;-1.524087e-002;50.00000;100.00000;2.87981;4
200.02000;62.79083;-1.523061e-002;50.00000;100.00000;2.87981;4
200.02000;62.92417;-1.516591e-002;50.00000;100.00000;2.87981;4
200.02100;63.05750;-1.511828e-002;50.00000;100.00000;2.87981;4
200.02100;63.19083;-1.509444e-002;50.00000;100.00000;2.87981;4
200.02000;63.32417;-1.503992e-002;50.00000;100.00000;2.87981;4
200.02100;63.45750;-1.498548e-002;50.00000;100.00000;2.87981;4
200.02100;63.59083;-1.491397e-002;50.00000;100.00000;2.87981;4
200.02200;63.72417;-1.483569e-002;50.00000;100.00000;2.87981;4
200.02299;63.85750;-1.477784e-002;50.00000;100.00000;2.87981;4
200.02400;63.99083;-1.469956e-002;50.00000;100.00000;2.87981;4
200.02299;64.12417;-1.462120e-002;50.00000;100.00000;2.87981;4
200.02499;64.25750;-1.458042e-002;50.00000;100.00000;2.87980;4
200.02400;64.39083;-1.453951e-002;50.00000;100.00000;2.87981;4
200.02400;64.52417;-1.448163e-002;50.00000;100.00000;2.87981;4
200.02400;64.65750;-1.445438e-002;50.00000;100.00000;2.87981;4
200.02499;64.79083;-1.439313e-002;50.00000;100.00000;2.87980;4
200.02499;64.92417;-1.433524e-002;50.00000;100.00000;2.87980;4
200.02400;65.05750;-1.428753e-002;50.00000;100.00000;2.87981;4
200.02499;65.19083;-1.421606e-002;50.00000;100.00000;2.87980;4
200.02400;65.32417;-1.415132e-002;50.00000;100.00000;2.87981;4
200.02600;65.45750;-1.409692e-002;50.00000;100.00000;2.87980;4
200.02600;65.59083;-1.401179e-002;50.00000;100.00000;2.87980;4
200.02499;65.72417;-1.396067e-002;50.00000;100.00000;2.87980;4
200.02600;65.85750;-1.394709e-002;50.00000;100.00000;2.87980;4
200.02600;65.99083;-1.387898e-002;50.00000;100.00000;2.87980;4
200.02699;66.12417;-1.384497e-002;50.00000;100.00000;2.87980;4
200.02600;66.25750;-1.378023e-002;50.00000;100.00000;2.87980;4
200.02499;66.39083;-1.378019e-002;50.00000;100.00000;2.87980;4
200.02699;66.52417;-1.371898e-002;50.00000;100.00000;2.87980;4
200.02600;66.65750;-1.366105e-002;50.00000;100.00000;2.87980;4
200.02699;66.79083;-1.358958e-002;50.00000;100.00000;2.87980;4
200.02499;66.92417;-1.354523e-002;50.00000;100.00000;2.87980;4
200.02699;67.05750;-1.354872e-002;50.00000;100.00000;2.87980;4
200.02800;67.19083;-1.347384e-002;50.00000;100.00000;2.87980;4
200.02699;67.32417;-1.343634e-002;50.00000;100.00000;2.87980;4
200.02800;67.45750;-1.335125e-002;50.00000;100.00000;2.87980;4
200.02699;67.59083;-1.328311e-002;50.00000;100.00000;2.87980;4
200.02699;67.72417;-1.326267e-002;50.00000;100.00000;2.87980;4
200.02699;67.85750;-1.318435e-002;50.00000;100.00000;2.87980;4
200.02800;67.99083;-1.313332e-002;50.00000;100.00000;2.87980;4
200.02600;68.12417;-1.307535e-002;50.00000;100.00000;2.87980;4
200.02800;68.25750;-1.303797e-002;50.00000;100.00000;2.87980;4
200.02901;68.39083;-1.298353e-002;50.00000;100.00000;2.87980;4
200.02699;68.52417;-1.295280e-002;50.00000;100.00000;2.87980;4
200.02901;68.65750;-1.292564e-002;50.00000;100.00000;2.87980;4
200.02800;68.79083;-1.289495e-002;50.00000;100.00000;2.87980;4
200.02699;68.92417;-1.284724e-002;50.00000;100.00000;2.87980;4
200.02699;69.05750;-1.284042e-002;50.00000;100.00000;2.87980;4
200.02800;69.19083;-1.277917e-002;50.00000;100.00000;2.87980;4
200.02901;69.32417;-1.269068e-002;50.00000;100.00000;2.87980;4
200.02800;69.45750;-1.267701e-002;50.00000;100.00000;2.87980;4
200.02800;69.59083;-1.263615e-002;50.00000;100.00000;2.87980;4
200.02699;69.72417;-1.257482e-002;50.00000;100.00000;2.87980;4
200.02699;69.85750;-1.256801e-002;50.00000;100.00000;2.87980;4
200.02600;69.99083;-1.249986e-002;50.00000;100.00000;2.87980;4
200.02699;70.12417;-1.247606e-002;50.00000;100.00000;2.87980;4
200.02699;70.25750;-1.243180e-002;50.00000;100.00000;2.87980;4
200.02901;70.39083;-1.237739e-002;50.00000;100.00000;2.87980;4
200.02901;70.52417;-1.233313e-002;50.00000;100.00000;2.87980;4
200.02800;70.65750;-1.229222e-002;50.00000;100.00000;2.87980;4
200.02901;70.79083;-1.225140e-002;50.00000;100.00000;2.87980;4
200.02800;70.92417;-1.220028e-002;50.00000;100.00000;2.87980;4
200.02699;71.05750;-1.220024e-002;50.00000;100.00000;2.87980;4
200.02800;71.19083;-1.215261e-002;50.00000;100.00000;2.87980;4
200.02901;71.32417;-1.212881e-002;50.00000;100.00000;2.87980;4
200.02800;71.45750;-1.206748e-002;50.00000;100.00000;2.87980;4
200.02800;71.59083;-1.203002e-002;50.00000;100.00000;2.87980;4
200.02901;71.72417;-1.196536e-002;50.00000;100.00000;2.87980;4
200.03101;71.85750;-1.192117e-002;50.00000;100.00000;2.87979;4
200.02800;71.99083;-1.185295e-002;50.00000;100.00000;2.87980;4
200.03101;72.12417;-1.180199e-002;50.00000;100.00000;2.87979;4
200.03101;72.25750;-1.181901e-002;50.00000;100.00000;2.87979;4
200.03000;72.39083;-1.178492e-002;50.00000;100.00000;2.87980;4
200.02901;72.52417;-1.176445e-002;50.00000;100.00000;2.87980;4
200.02901;72.65750;-1.177467e-002;50.00000;100.00000;2.87980;4
200.02901;72.79083;-1.173380e-002;50.00000;100.00000;2.87980;4
200.02901;72.92417;-1.167932e-002;50.00000;100.00000;2.87980;4
200.03101;73.05750;-1.165897e-002;50.00000;100.00000;2.87979;4
200.02800;73.19083;-1.159415e-002;50.00000;100.00000;2.87980;4
200.02901;73.32417;-1.156013e-002;50.00000;100.00000;2.87980;4
200.03000;73.45750;-1.149888e-002;50.00000;100.00000;2.87980;4
200.02901;73.59083;-1.147160e-002;50.00000;100.00000;2.87980;4
200.03000;73.72417;-1.143078e-002;50.00000;100.00000;2.87980;4
200.02901;73.85750;-1.138647e-002;50.00000;100.00000;2.87980;4
200.02901;73.99083;-1.136604e-002;50.00000;100.00000;2.87980;4
200.03000;74.12417;-1.132862e-002;50.00000;100.00000;2.87980;4
200.03000;74.25750;-1.128094e-002;50.00000;100.00000;2.87980;4
200.03101;74.39083;-1.120947e-002;50.00000;100.00000;2.87979;4
200.03101;74.52417;-1.115158e-002;50.00000;100.00000;2.87979;4
200.03200;74.65750;-1.103585e-002;50.00000;100.00000;2.87979;4
200.03200;74.79083;-1.102563e-002;50.00000;100.00000;2.87979;4
200.03101;74.92417;-1.099835e-002;50.00000;100.00000;2.87979;4
200.03101;75.05750;-1.101537e-002;50.00000;100.00000;2.87979;4
200.03101;75.19083;-1.099494e-002;50.00000;100.00000;2.87979;4
200.03101;75.32417;-1.092003e-002;50.00000;100.00000;2.87979;4
200.03200;75.45750;-1.090985e-002;50.00000;100.00000;2.87979;4
200.03200;75.59083;-1.090645e-002;50.00000;100.00000;2.87979;4
200.03101;75.72417;-1.089619e-002;50.00000;100.00000;2.87979;4
200.03000;75.85750;-1.092339e-002;50.00000;100.00000;2.87980;4
200.03000;75.99083;-1.096426e-002;50.00000;100.00000;2.87980;4
200.03000;76.12417;-1.094723e-002;50.00000;100.00000;2.87980;4
200.03000;76.25750;-1.093361e-002;50.00000;100.00000;2.87980;4
200.02901;76.39083;-1.089611e-002;50.00000;100.00000;2.87980;4
200.03000;76.52417;-1.085869e-002;50.00000;100.00000;2.87980;4
200.02901;76.65750;-1.083141e-002;50.00000;100.00000;2.87980;4
200.02901;76.79083;-1.081439e-002;50.00000;100.00000;2.87980;4
200.02901;76.92417;-1.074628e-002;50.00000;100.00000;2.87980;4
200.02901;77.05750;-1.070882e-002;50.00000;100.00000;2.87980;4
200.02901;77.19083;-1.067818e-002;50.00000;100.00000;2.87980;4
200.02901;77.32417;-1.067477e-002;50.00000;100.00000;2.87980;4
200.02901;77.45750;-1.065093e-002;50.00000;100.00000;2.87980;4
200.03101;77.59083;-1.062377e-002;50.00000;100.00000;2.87979;4
200.02901;77.72417;-1.056580e-002;50.00000;100.00000;2.87980;4
200.02800;77.85750;-1.058279e-002;50.00000;100.00000;2.87980;4
200.02800;77.99083;-1.061344e-002;50.00000;100.00000;2.87980;4
200.02800;78.12417;-1.062025e-002;50.00000;100.00000;2.87980;4
200.02600;78.25750;-1.061336e-002;50.00000;100.00000;2.87980;4
200.02699;78.39083;-1.054529e-002;50.00000;100.00000;2.87980;4
200.02699;78.52417;-1.050783e-002;50.00000;100.00000;2.87980;4
200.02200;78.65917;-1.058595e-002;50.00000;100.00000;2.87981;5
199.91499;78.79250;-1.580501e-002;50.00000;100.00000;2.87997;5
199.65401;78.92583;-3.053569e-002;50.00000;100.00000;2.88037;5
199.25800;79.05917;-5.417267e-002;50.00000;100.00000;2.88096;5
198.75301;79.19250;-8.453317e-002;50.00000;100.00000;2.88172;5
198.16701;79.32583;      -0.11926;50.00000;100.00000;2.88258;5
197.51700;79.45917;      -0.15629;50.00000;100.00000;2.88354;5
196.81599;79.59250;      -0.19394;50.00000;100.00000;2.88455;5
196.07600;79.72583;      -0.23103;50.00000;100.00000;2.88561;5
195.30600;79.85917;      -0.26663;50.00000;100.00000;2.88670;5
194.51300;79.99250;      -0.30025;50.00000;100.00000;2.88780;5
193.70000;80.12583;      -0.33155;50.00000;100.00000;2.88892;5
192.87300;80.25917;      -0.36036;50.00000;100.00000;2.89004;5
192.03600;80.39250;      -0.38668;50.00000;100.00000;2.89115;5
191.19099;80.52583;      -0.41051;50.00000;100.00000;2.89226;5
190.33900;80.65917;      -0.43191;50.00000;100.00000;2.89336;5
189.48199;80.79250;      -0.45108;50.00000;100.00000;2.89445;5
188.62199;80.92583;      -0.46804;50.00000;100.00000;2.89552;5
187.75999;81.05917;      -0.48309;50.00000;100.00000;2.89658;5
186.89999;81.19250;      -0.49614;50.00000;100.00000;2.89761;5
186.04900;81.32583;      -0.50708;50.00000;100.00000;2.89862;5
185.21001;81.45917;      -0.51577;50.00000;100.00000;2.89960;5
184.38699;81.59250;      -0.52220;50.00000;100.00000;2.90054;5
183.58000;81.72583;      -0.52642;50.00000;100.00000;2.90144;5
182.79300;81.85917;      -0.52874;50.00000;100.00000;2.90231;5
182.02100;81.99250;      -0.52920;50.00000;100.00000;2.90314;5
181.26801;82.12583;      -0.52810;50.00000;100.00000;2.90394;5
180.53101;82.25917;      -0.52568;50.00000;100.00000;2.90471;5
179.81200;82.39250;      -0.52209;50.00000;100.00000;2.90545;5
179.10800;82.52583;      -0.51754;50.00000;100.00000;2.90616;5
178.41901;82.65917;      -0.51224;50.00000;100.00000;2.90684;5
177.74500;82.79250;      -0.50626;50.00000;100.00000;2.90750;5
177.08501;82.92583;      -0.49984;50.00000;100.00000;2.90813;5
176.43401;83.05917;      -0.49317;50.00000;100.00000;2.90874;5
175.79900;83.19250;      -0.48612;50.00000;100.00000;2.90933;5
175.17400;83.32583;      -0.47893;50.00000;100.00000;2.90990;5
174.56000;83.45917;      -0.47177;50.00000;100.00000;2.91044;5
173.95700;83.59250;      -0.46455;50.00000;100.00000;2.91097;5
173.36301;83.72583;      -0.45740;50.00000;100.00000;2.91148;5
172.77800;83.85917;      -0.45036;50.00000;100.00000;2.91198;5
172.20000;83.99250;      -0.44342;50.00000;100.00000;2.91246;5
171.63200;84.12583;      -0.43667;50.00000;100.00000;2.91292;5
171.07001;84.25917;      -0.43008;50.00000;100.00000;2.91337;5
170.51500;84.39250;      -0.42370;50.00000;100.00000;2.91381;5
169.96800;84.52583;      -0.41752;50.00000;100.00000;2.91424;5
169.42599;84.65917;      -0.41158;50.00000;100.00000;2.91465;5
168.89101;84.79250;      -0.40587;50.00000;100.00000;2.91505;5
168.35899;84.92583;      -0.40032;50.00000;100.00000;2.91544;5
167.83501;85.05917;      -0.39504;50.00000;100.00000;2.91582;5
167.31599;85.19250;      -0.38997;50.00000;100.00000;2.91618;5
166.80200;85.32583;      -0.38509;50.00000;100.00000;2.91654;5
166.28999;85.45917;      -0.38044;50.00000;100.00000;2.91689;5
165.78600;85.59250;      -0.37595;50.00000;100.00000;2.91722;5
165.28500;85.72583;      -0.37163;50.00000;100.00000;2.91755;5
164.78799;85.85917;      -0.36752;50.00000;100.00000;2.91787;5
164.29401;85.99250;      -0.36354;50.00000;100.00000;2.91818;5
163.80600;86.12583;      -0.35976;50.00000;100.00000;2.91848;5
163.31900;86.25917;      -0.35608;50.00000;100.00000;2.91878;5
162.83800;86.39250;      -0.35264;50.00000;100.00000;2.91906;5
162.36200;86.52583;      -0.34927;50.00000;100.00000;2.91934;5
161.88400;86.65917;      -0.34601;50.00000;100.00000;2.91961;5
161.41299;86.79250;      -0.34292;50.00000;100.00000;2.91987;5
160.94501;86.92583;      -0.33991;50.00000;100.00000;2.92013;5
160.47900;87.05917;      -0.33699;50.00000;100.00000;2.92038;5
160.01700;87.19250;      -0.33425;50.00000;100.00000;2.92062;5
159.55901;87.32583;      -0.33153;50.00000;100.00000;2.92085;5
159.10300;87.45917;      -0.32892;50.00000;100.00000;2.92108;5
158.64799;87.59250;      -0.32639;50.00000;100.00000;2.92130;5
158.19800;87.72583;      -0.32393;50.00000;100.00000;2.92151;5
157.75000;87.85917;      -0.32156;50.00000;100.00000;2.92172;5
157.30400;87.99250;      -0.31925;50.00000;100.00000;2.92192;5
156.86099;88.12583;      -0.31698;50.00000;100.00000;2.92211;5
156.42101;88.25917;      -0.31486;50.00000;100.00000;2.92230;5
155.98399;88.39250;      -0.31267;50.00000;100.00000;2.92248;5
155.54900;88.52583;      -0.31061;50.00000;100.00000;2.92266;5
155.11400;88.65917;      -0.30860;50.00000;100.00000;2.92283;5
154.68600;88.79250;      -0.30660;50.00000;100.00000;2.92299;5
154.25700;88.92583;      -0.30470;50.00000;100.00000;2.92315;5
153.83000;89.05917;      -0.30280;50.00000;100.00000;2.92331;5
153.40800;89.19250;      -0.30096;50.00000;100.00000;2.92346;5
152.98801;89.32583;      -0.29916;50.00000;100.00000;2.92360;5
152.57001;89.45917;      -0.29738;50.00000;100.00000;2.92374;5
152.15300;89.59250;      -0.29564;50.00000;100.00000;2.92387;5
151.73900;89.72583;      -0.29393;50.00000;100.00000;2.92400;5
151.32800;89.85917;      -0.29225;50.00000;100.00000;2.92412;5
150.91800;89.99250;      -0.29060;50.00000;100.00000;2.92424;5
150.50900;90.12583;      -0.28894;50.00000;100.00000;2.92435;5
150.10300;90.25917;      -0.28737;50.00000;100.00000;2.92446;5
149.69901;90.39250;      -0.28579;50.00000;100.00000;2.92456;5
149.30000;90.52583;      -0.28422;50.00000;100.00000;2.92466;5
148.89999;90.65917;      -0.28270;50.00000;100.00000;2.92475;5
148.50301;90.79250;      -0.28119;50.00000;100.00000;2.92484;5
148.10699;90.92583;      -0.27970;50.00000;100.00000;2.92493;5
147.71400;91.05917;      -0.27825;50.00000;100.00000;2.92501;5
147.32401;91.19250;      -0.27677;50.00000;100.00000;2.92508;5
146.93300;91.32583;      -0.27534;50.00000;100.00000;2.92515;5
146.54500;91.45917;      -0.27394;50.00000;100.00000;2.92522;5
146.16200;91.59250;      -0.27255;50.00000;100.00000;2.92528;5
145.77600;91.72583;      -0.27117;50.00000;100.00000;2.92534;5
145.39500;91.85917;      -0.26979;50.00000;100.00000;2.92540;5
145.01500;91.99250;      -0.26844;50.00000;100.00000;2.92545;5
144.63600;92.12583;      -0.26707;50.00000;100.00000;2.92550;5
144.26300;92.25917;      -0.26574;50.00000;100.00000;2.92554;5
143.88800;92.39250;      -0.26445;50.00000;100.00000;2.92558;5
143.51500;92.52583;      -0.26312;50.00000;100.00000;2.92562;5
143.14400;92.65917;      -0.26182;50.00000;100.00000;2.92565;5
142.77600;92.79250;      -0.26054;50.00000;100.00000;2.92568;5
142.40800;92.92583;      -0.25929;50.00000;100.00000;2.92570;5
142.04300;93.05917;      -0.25799;50.00000;100.00000;2.92572;5
141.67900;93.19250;      -0.25677;50.00000;100.00000;2.92574;5
141.31900;93.32583;      -0.25547;50.00000;100.00000;2.92575;5
140.96001;93.45917;      -0.25424;50.00000;100.00000;2.92577;5
140.60400;93.59250;      -0.25293;50.00000;100.00000;2.92577;5
140.24699;93.72583;      -0.25165;50.00000;100.00000;2.92578;5
139.89500;93.85917;      -0.25035;50.00000;100.00000;2.92578;5
139.54401;93.99250;      -0.24910;50.00000;100.00000;2.92578;5
139.19200;94.12583;      -0.24783;50.00000;100.00000;2.92577;5
138.84399;94.25917;      -0.24663;50.00000;100.00000;2.92576;5
138.49899;94.39250;      -0.24538;50.00000;100.00000;2.92575;5
138.15401;94.52583;      -0.24416;50.00000;100.00000;2.92574;5
137.80901;94.65917;      -0.24299;50.00000;100.00000;2.92572;5
137.46700;94.79250;      -0.24183;50.00000;100.00000;2.92570;5
137.12601;94.92583;      -0.24070;50.00000;100.00000;2.92568;5
136.78600;95.05917;      -0.23956;50.00000;100.00000;2.92565;5
136.45000;95.19250;      -0.23848;50.00000;100.00000;2.92562;5
136.11301;95.32583;      -0.23743;50.00000;100.00000;2.92559;5
135.77901;95.45917;      -0.23635;50.00000;100.00000;2.92555;5
135.44600;95.59250;      -0.23524;50.00000;100.00000;2.92552;5
135.11501;95.72583;      -0.23416;50.00000;100.00000;2.92548;5
134.78700;95.85917;      -0.23303;50.00000;100.00000;2.92543;5
134.46001;95.99250;      -0.23191;50.00000;100.00000;2.92539;5
134.13300;96.12583;      -0.23084;50.00000;100.00000;2.92534;5
133.80800;96.25917;      -0.22973;50.00000;100.00000;2.92529;5
133.48599;96.39250;      -0.22860;50.00000;100.00000;2.92524;5
133.16499;96.52583;      -0.22756;50.00000;100.00000;2.92518;5
132.84500;96.65917;      -0.22648;50.00000;100.00000;2.92513;5
132.52600;96.79250;      -0.22546;50.00000;100.00000;2.92507;5
132.20900;96.92583;      -0.22443;50.00000;100.00000;2.92501;5
131.89200;97.05917;      -0.22340;50.00000;100.00000;2.92494;5
131.57800;97.19250;      -0.22242;50.00000;100.00000;2.92488;5
131.26500;97.32583;      -0.22144;50.00000;100.00000;2.92481;5
130.95300;97.45917;      -0.22046;50.00000;100.00000;2.92474;5
130.64200;97.59250;      -0.21952;50.00000;100.00000;2.92466;5
130.33400;97.72583;      -0.21858;50.00000;100.00000;2.92459;5
130.02699;97.85917;      -0.21767;50.00000;100.00000;2.92451;5
129.71899;97.99250;      -0.21675;50.00000;100.00000;2.92443;5
129.41299;98.12583;      -0.21586;50.00000;100.00000;2.92435;5
129.10899;98.25917;      -0.21494;50.00000;100.00000;2.92427;5
128.80701;98.39250;      -0.21405;50.00000;100.00000;2.92418;5
128.50400;98.52583;      -0.21316;50.00000;100.00000;2.92409;5
128.20300;98.65917;      -0.21233;50.00000;100.00000;2.92400;5
127.90400;98.79250;      -0.21145;50.00000;100.00000;2.92391;5
127.60600;98.92583;      -0.21058;50.00000;100.00000;2.92382;5
127.31000;99.05917;      -0.20969;50.00000;100.00000;2.92372;5
127.01400;99.19250;      -0.20883;50.00000;100.00000;2.92363;5
126.72000;99.32583;      -0.20799;50.00000;100.00000;2.92353;5
126.42700;99.45917;      -0.20714;50.00000;100.00000;2.92343;5
126.13700;99.59250;      -0.20624;50.00000;100.00000;2.92332;5
125.84600;99.72583;      -0.20538;50.00000;100.00000;2.92322;5
125.55800;99.85917;      -0.20450;50.00000;100.00000;2.92311;5
125.27100;99.99250;      -0.20365;50.00000;100.00000;2.92301;5