File: examples/data/A_2.txt
#EXPORTTYPE:DATA ALL
#FILE:
#FORMAT:NETZSCH5
#FTYPE:ANSI
#IDENTITY:
#DECIMAL:POINT
#SEPARATOR:SEMICOLON
#MTYPE:DSC
#INSTRUMENT:NETZSCH DSC 200F3
#PROJECT:
#DATE/TIME:19.03.2025 15:09
#CORR. FILE:
#TEMPCAL:temp_cal_3Kmin.ngb-td5
#SENSITIVITY:sens_cal_3Kmin.ngb-ed5
#LABORATORY:
#OPERATOR:
#REMARK:CR 1355.7; tot 1431.2
#SAMPLE:
#SAMPLE MASS /mg:75.9
#MATERIAL:
#REFERENCE:Ref.
#REFERENCE MASS /mg:0
#TYPE OF CRUCIBLE:High pressure, steel
#SAMPLE CRUCIBLE MASS /mg:1355.7
#REFERENCE CRUCIBLE MASS /mg:1385.5
#M.RANGE /�V:5000
#TAU-R:---
#CORR. CODE:000
#EXO:-1
#RANGE:25�C....200�C/-7.0....7.0K/min
#SEGMENT:S1-5/5
#SEG. 1:25�C/7.0(K/min)/50�C
#SEG. 2:50�C/00:15/50�C
#SEG. 3:50�C/5.0(K/min)/200�C
#SEG. 4:200�C/00:30/200�C
#SEG. 5:200�C/7.0(K/min)/50�C

##Temp./�C;Time/min;DSC/(mW/mg);Gas Flow(purge2)/(ml/min);Gas Flow(protective)/(ml/min);Sensit./(uV/mW);Segment
 37.38300; 0.00000;-1.510214e-002;50.00000;100.00000;2.79369;1
 37.36000; 0.13333;-1.506924e-002;50.00000;100.00000;2.79364;1
 37.33700; 0.26667;-1.505792e-002;50.00000;100.00000;2.79358;1
 37.31500; 0.40000;-1.503223e-002;50.00000;100.00000;2.79352;1
 37.29300; 0.53333;-1.501734e-002;50.00000;100.00000;2.79347;1
 37.27000; 0.66667;-1.498083e-002;50.00000;100.00000;2.79341;1
 37.24800; 0.80000;-1.494794e-002;50.00000;100.00000;2.79335;1
 37.22400; 0.93333;-1.495099e-002;50.00000;100.00000;2.79329;1
 37.20100; 1.06667;-1.490008e-002;50.00000;100.00000;2.79324;1
 37.18000; 1.20000;-1.485642e-002;50.00000;100.00000;2.79318;1
 37.15700; 1.33333;-1.484150e-002;50.00000;100.00000;2.79312;1
 37.13600; 1.46667;-1.480503e-002;50.00000;100.00000;2.79307;1
 37.12200; 1.60000;-1.453478e-002;50.00000;100.00000;2.79304;1
 37.14100; 1.73333;-1.353474e-002;50.00000;100.00000;2.79308;1
 37.22600; 1.86667;-1.090623e-002;50.00000;100.00000;2.79330;1
 37.40500; 2.00000;-5.708266e-003;50.00000;100.00000;2.79375;1
 37.69000; 2.13333; 2.811519e-003;50.00000;100.00000;2.79447;1
 38.07900; 2.26667; 1.503301e-002;50.00000;100.00000;2.79544;1
 38.55700; 2.40000; 3.076662e-002;50.00000;100.00000;2.79663;1
 39.10600; 2.53333; 4.963206e-002;50.00000;100.00000;2.79800;1
 39.71700; 2.66667; 7.076410e-002;50.00000;100.00000;2.79951;1
 40.37600; 2.80000; 9.274724e-002;50.00000;100.00000;2.80112;1
 41.07300; 2.93333;       0.11475;50.00000;100.00000;2.80283;1
 41.80700; 3.06667;       0.13692;50.00000;100.00000;2.80461;1
 42.56800; 3.20000;       0.15886;50.00000;100.00000;2.80644;1
 43.35300; 3.33333;       0.18048;50.00000;100.00000;2.80832;1
 44.15600; 3.46667;       0.20153;50.00000;100.00000;2.81022;1
 44.90400; 3.58833;       0.22024;50.00000;100.00000;2.81198;2
 45.70900; 3.72167;       0.23891;50.00000;100.00000;2.81387;2
 46.40600; 3.85500;       0.25451;50.00000;100.00000;2.81548;2
 46.99200; 3.98833;       0.26733;50.00000;100.00000;2.81684;2
 47.48000; 4.12167;       0.27650;50.00000;100.00000;2.81795;2
 47.88900; 4.25500;       0.28144;50.00000;100.00000;2.81889;2
 48.23500; 4.38833;       0.28209;50.00000;100.00000;2.81968;2
 48.52900; 4.52167;       0.27887;50.00000;100.00000;2.82034;2
 48.77600; 4.65500;       0.27247;50.00000;100.00000;2.82090;2
 48.98800; 4.78833;       0.26350;50.00000;100.00000;2.82138;2
 49.17000; 4.92167;       0.25268;50.00000;100.00000;2.82179;2
 49.32900; 5.05500;       0.24064;50.00000;100.00000;2.82215;2
 49.46400; 5.18833;       0.22779;50.00000;100.00000;2.82245;2
 49.58200; 5.32167;       0.21455;50.00000;100.00000;2.82271;2
 49.68800; 5.45500;       0.20124;50.00000;100.00000;2.82295;2
 49.77800; 5.58833;       0.18805;50.00000;100.00000;2.82315;2
 49.85900; 5.72167;       0.17526;50.00000;100.00000;2.82333;2
 49.92700; 5.85500;       0.16280;50.00000;100.00000;2.82349;2
 49.98600; 5.98833;       0.15094;50.00000;100.00000;2.82362;2
 50.03900; 6.12167;       0.13961;50.00000;100.00000;2.82374;2
 50.08400; 6.25500;       0.12883;50.00000;100.00000;2.82384;2
 50.12300; 6.38833;       0.11868;50.00000;100.00000;2.82392;2
 50.15700; 6.52167;       0.10914;50.00000;100.00000;2.82400;2
 50.18900; 6.65500;       0.10024;50.00000;100.00000;2.82407;2
 50.21900; 6.78833; 9.197252e-002;50.00000;100.00000;2.82414;2
 50.24200; 6.92167; 8.425363e-002;50.00000;100.00000;2.82419;2
 50.26400; 7.05500; 7.711883e-002;50.00000;100.00000;2.82424;2
 50.28200; 7.18833; 7.048291e-002;50.00000;100.00000;2.82428;2
 50.29900; 7.32167; 6.437401e-002;50.00000;100.00000;2.82431;2
 50.31300; 7.45500; 5.869615e-002;50.00000;100.00000;2.82434;2
 50.32800; 7.58833; 5.351661e-002;50.00000;100.00000;2.82438;2
 50.34200; 7.72167; 4.874653e-002;50.00000;100.00000;2.82441;2
 50.35300; 7.85500; 4.440385e-002;50.00000;100.00000;2.82443;2
 50.36300; 7.98833; 4.041363e-002;50.00000;100.00000;2.82446;2
 50.37200; 8.12167; 3.673673e-002;50.00000;100.00000;2.82448;2
 50.37800; 8.25500; 3.332696e-002;50.00000;100.00000;2.82449;2
 50.38500; 8.38833; 3.018765e-002;50.00000;100.00000;2.82451;2
 50.39100; 8.52167; 2.730110e-002;50.00000;100.00000;2.82452;2
 50.39400; 8.65500; 2.467098e-002;50.00000;100.00000;2.82452;2
 50.39600; 8.78833; 2.228292e-002;50.00000;100.00000;2.82453;2
 50.40000; 8.92167; 2.007271e-002;50.00000;100.00000;2.82454;2
 50.40300; 9.05500; 1.804049e-002;50.00000;100.00000;2.82454;2
 50.40600; 9.18833; 1.623605e-002;50.00000;100.00000;2.82455;2
 50.40900; 9.32167; 1.454906e-002;50.00000;100.00000;2.82456;2
 50.40900; 9.45500; 1.304726e-002;50.00000;100.00000;2.82456;2
 50.41300; 9.58833; 1.163426e-002;50.00000;100.00000;2.82457;2
 50.41300; 9.72167; 1.036379e-002;50.00000;100.00000;2.82457;2
 50.41500; 9.85500; 9.210667e-003;50.00000;100.00000;2.82457;2
 50.41500; 9.98833; 8.135928e-003;50.00000;100.00000;2.82457;2
 50.41600;10.12167; 7.196381e-003;50.00000;100.00000;2.82457;2
 50.41500;10.25500; 6.313855e-003;50.00000;100.00000;2.82457;2
 50.41700;10.38833; 5.566440e-003;50.00000;100.00000;2.82458;2
 50.41800;10.52167; 4.822626e-003;50.00000;100.00000;2.82458;2
 50.41800;10.65500; 4.192731e-003;50.00000;100.00000;2.82458;2
 50.41800;10.78833; 3.623334e-003;50.00000;100.00000;2.82458;2
 50.42000;10.92167; 3.100124e-003;50.00000;100.00000;2.82458;2
 50.42100;11.05500; 2.626776e-003;50.00000;100.00000;2.82459;2
 50.42100;11.18833; 2.174819e-003;50.00000;100.00000;2.82459;2
 50.41900;11.32167; 1.797670e-003;50.00000;100.00000;2.82458;2
 50.42000;11.45500; 1.434642e-003;50.00000;100.00000;2.82458;2
 50.41800;11.58833; 1.071726e-003;50.00000;100.00000;2.82458;2
 50.41700;11.72167; 7.408010e-004;50.00000;100.00000;2.82458;2
 50.41900;11.85500; 4.738237e-004;50.00000;100.00000;2.82458;2
 50.41800;11.98833; 2.033966e-004;50.00000;100.00000;2.82458;2
 50.42000;12.12167; 4.772831e-007;50.00000;100.00000;2.82458;2
 50.41800;12.25500;-1.880635e-004;50.00000;100.00000;2.82458;2
 50.41900;12.38833;-3.375657e-004;50.00000;100.00000;2.82458;2
 50.42100;12.52167;-4.372812e-004;50.00000;100.00000;2.82459;2
 50.42100;12.65500;-5.547189e-004;50.00000;100.00000;2.82459;2
 50.42100;12.78833;-6.614805e-004;50.00000;100.00000;2.82459;2
 50.42100;12.92167;-7.646833e-004;50.00000;100.00000;2.82459;2
 50.42000;13.05500;-8.536161e-004;50.00000;100.00000;2.82458;2
 50.42000;13.18833;-9.532603e-004;50.00000;100.00000;2.82458;2
 50.42000;13.32167;-1.027993e-003;50.00000;100.00000;2.82458;2
 50.41900;13.45500;-1.145396e-003;50.00000;100.00000;2.82458;2
 50.42000;13.58833;-1.234399e-003;50.00000;100.00000;2.82458;2
 50.42000;13.72167;-1.291339e-003;50.00000;100.00000;2.82458;2
 50.42000;13.85500;-1.344720e-003;50.00000;100.00000;2.82458;2
 50.42000;13.98833;-1.401659e-003;50.00000;100.00000;2.82458;2
 50.42000;14.12167;-1.426570e-003;50.00000;100.00000;2.82458;2
 50.42100;14.25500;-1.479986e-003;50.00000;100.00000;2.82459;2
 50.42100;14.38833;-1.504897e-003;50.00000;100.00000;2.82459;2
 50.42200;14.52167;-1.540519e-003;50.00000;100.00000;2.82459;2
 50.42000;14.65500;-1.568919e-003;50.00000;100.00000;2.82458;2
 50.42100;14.78833;-1.593865e-003;50.00000;100.00000;2.82459;2
 50.42000;14.92167;-1.615183e-003;50.00000;100.00000;2.82458;2
 50.42000;15.05500;-1.650770e-003;50.00000;100.00000;2.82458;2
 50.42100;15.18833;-1.689951e-003;50.00000;100.00000;2.82459;2
 50.42200;15.32167;-1.700661e-003;50.00000;100.00000;2.82459;2
 50.42000;15.45500;-1.714827e-003;50.00000;100.00000;2.82458;2
 50.42000;15.58833;-1.721944e-003;50.00000;100.00000;2.82458;2
 50.42100;15.72167;-1.732655e-003;50.00000;100.00000;2.82459;2
 50.42100;15.85500;-1.736214e-003;50.00000;100.00000;2.82459;2
 50.42300;15.98833;-1.750518e-003;50.00000;100.00000;2.82459;2
 50.42200;16.12167;-1.750483e-003;50.00000;100.00000;2.82459;2
 50.42200;16.25500;-1.757601e-003;50.00000;100.00000;2.82459;2
 50.42200;16.38833;-1.750483e-003;50.00000;100.00000;2.82459;2
 50.42200;16.52167;-1.775394e-003;50.00000;100.00000;2.82459;2
 50.42200;16.65500;-1.775394e-003;50.00000;100.00000;2.82459;2
 50.42200;16.78833;-1.786070e-003;50.00000;100.00000;2.82459;2
 50.42100;16.92167;-1.786036e-003;50.00000;100.00000;2.82459;2
 50.42200;17.05500;-1.796747e-003;50.00000;100.00000;2.82459;2
 50.42200;17.18833;-1.800305e-003;50.00000;100.00000;2.82459;2
 50.42100;17.32167;-1.775360e-003;50.00000;100.00000;2.82459;2
 50.42300;17.45500;-1.768311e-003;50.00000;100.00000;2.82459;2
 50.42400;17.58833;-1.786139e-003;50.00000;100.00000;2.82459;2
 50.42300;17.72167;-1.761194e-003;50.00000;100.00000;2.82459;2
 50.42500;17.85500;-1.743469e-003;50.00000;100.00000;2.82459;2
 50.42600;17.98833;-1.707917e-003;50.00000;100.00000;2.82460;2
 50.42800;18.12167;-1.683075e-003;50.00000;100.00000;2.82460;2
 50.42800;18.25500;-1.636812e-003;50.00000;100.00000;2.82460;2
 50.42800;18.38833;-1.658164e-003;50.00000;100.00000;2.82460;2
 50.42900;18.52167;-1.640405e-003;50.00000;100.00000;2.82460;2
 50.42900;18.65667;-1.629729e-003;50.00000;100.00000;2.82460;3
 50.45800;18.79000;-8.834243e-004;50.00000;100.00000;2.82467;3
 50.56100;18.92333; 1.625128e-003;50.00000;100.00000;2.82490;3
 50.75000;19.05667; 6.634601e-003;50.00000;100.00000;2.82531;3
 51.02800;19.19000; 1.459803e-002;50.00000;100.00000;2.82593;3
 51.37400;19.32333; 2.529256e-002;50.00000;100.00000;2.82669;3
 51.78100;19.45667; 3.810332e-002;50.00000;100.00000;2.82758;3
 52.23300;19.59000; 5.233838e-002;50.00000;100.00000;2.82857;3
 52.72200;19.72333; 6.770072e-002;50.00000;100.00000;2.82963;3
 53.23900;19.85667; 8.383367e-002;50.00000;100.00000;2.83075;3
 53.77700;19.99000;       0.10003;50.00000;100.00000;2.83191;3
 54.33400;20.12333;       0.11560;50.00000;100.00000;2.83310;3
 54.90600;20.25667;       0.13063;50.00000;100.00000;2.83431;3
 55.49400;20.39000;       0.14582;50.00000;100.00000;2.83555;3
 56.09000;20.52333;       0.16099;50.00000;100.00000;2.83680;3
 56.69800;20.65667;       0.17602;50.00000;100.00000;2.83807;3
 57.31000;20.79000;       0.19050;50.00000;100.00000;2.83933;3
 57.93100;20.92333;       0.20426;50.00000;100.00000;2.84061;3
 58.55700;21.05667;       0.21723;50.00000;100.00000;2.84188;3
 59.19000;21.19000;       0.22929;50.00000;100.00000;2.84317;3
 59.82300;21.32333;       0.24055;50.00000;100.00000;2.84444;3
 60.46300;21.45667;       0.25097;50.00000;100.00000;2.84571;3
 61.10600;21.59000;       0.26063;50.00000;100.00000;2.84699;3
 61.75300;21.72333;       0.26953;50.00000;100.00000;2.84826;3
 62.40000;21.85667;       0.27764;50.00000;100.00000;2.84952;3
 63.04800;21.99000;       0.28528;50.00000;100.00000;2.85077;3
 63.70300;22.12333;       0.29216;50.00000;100.00000;2.85203;3
 64.35800;22.25667;       0.29848;50.00000;100.00000;2.85327;3
 65.01500;22.39000;       0.30431;50.00000;100.00000;2.85451;3
 65.67000;22.52333;       0.30961;50.00000;100.00000;2.85574;3
 66.33000;22.65667;       0.31442;50.00000;100.00000;2.85696;3
 66.99000;22.79000;       0.31881;50.00000;100.00000;2.85817;3
 67.65000;22.92333;       0.32282;50.00000;100.00000;2.85938;3
 68.31200;23.05667;       0.32652;50.00000;100.00000;2.86057;3
 68.97400;23.19000;       0.32977;50.00000;100.00000;2.86176;3
 69.63800;23.32333;       0.33285;50.00000;100.00000;2.86294;3
 70.30200;23.45667;       0.33555;50.00000;100.00000;2.86411;3
 70.96400;23.59000;       0.33803;50.00000;100.00000;2.86526;3
 71.63000;23.72333;       0.34028;50.00000;100.00000;2.86641;3
 72.29300;23.85667;       0.34227;50.00000;100.00000;2.86755;3
 72.95800;23.99000;       0.34409;50.00000;100.00000;2.86867;3
 73.62500;24.12333;       0.34573;50.00000;100.00000;2.86980;3
 74.28900;24.25667;       0.34718;50.00000;100.00000;2.87090;3
 74.95500;24.39000;       0.34846;50.00000;100.00000;2.87200;3
 75.62300;24.52333;       0.34966;50.00000;100.00000;2.87309;3
 76.29000;24.65667;       0.35074;50.00000;100.00000;2.87416;3
 76.95700;24.79000;       0.35168;50.00000;100.00000;2.87523;3
 77.62400;24.92333;       0.35260;50.00000;100.00000;2.87629;3
 78.29000;25.05667;       0.35332;50.00000;100.00000;2.87733;3
 78.95900;25.19000;       0.35397;50.00000;100.00000;2.87837;3
 79.62500;25.32333;       0.35454;50.00000;100.00000;2.87939;3
 80.29300;25.45667;       0.35499;50.00000;100.00000;2.88040;3
 80.96100;25.59000;       0.35546;50.00000;100.00000;2.88140;3
 81.62700;25.72333;       0.35580;50.00000;100.00000;2.88239;3
 82.29500;25.85667;       0.35611;50.00000;100.00000;2.88337;3
 82.96200;25.99000;       0.35639;50.00000;100.00000;2.88434;3
 83.63000;26.12333;       0.35661;50.00000;100.00000;2.88530;3
 84.29800;26.25667;       0.35678;50.00000;100.00000;2.88625;3
 84.96500;26.39000;       0.35690;50.00000;100.00000;2.88718;3
 85.63200;26.52333;       0.35702;50.00000;100.00000;2.88811;3
 86.30000;26.65667;       0.35710;50.00000;100.00000;2.88902;3
 86.97100;26.79000;       0.35723;50.00000;100.00000;2.88993;3
 87.63900;26.92333;       0.35730;50.00000;100.00000;2.89082;3
 88.30700;27.05667;       0.35734;50.00000;100.00000;2.89170;3
 88.97300;27.19000;       0.35733;50.00000;100.00000;2.89257;3
 89.64200;27.32333;       0.35734;50.00000;100.00000;2.89343;3
 90.30900;27.45667;       0.35734;50.00000;100.00000;2.89428;3
 90.97900;27.59000;       0.35729;50.00000;100.00000;2.89512;3
 91.64600;27.72333;       0.35725;50.00000;100.00000;2.89595;3
 92.31300;27.85667;       0.35716;50.00000;100.00000;2.89676;3
 92.98200;27.99000;       0.35710;50.00000;100.00000;2.89756;3
 93.65100;28.12333;       0.35704;50.00000;100.00000;2.89836;3
 94.32100;28.25667;       0.35696;50.00000;100.00000;2.89914;3
 94.98900;28.39000;       0.35688;50.00000;100.00000;2.89991;3
 95.65500;28.52333;       0.35684;50.00000;100.00000;2.90067;3
 96.32500;28.65667;       0.35677;50.00000;100.00000;2.90142;3
 96.99200;28.79000;       0.35664;50.00000;100.00000;2.90216;3
 97.66100;28.92333;       0.35653;50.00000;100.00000;2.90288;3
 98.32900;29.05667;       0.35643;50.00000;100.00000;2.90360;3
 98.99700;29.19000;       0.35636;50.00000;100.00000;2.90430;3
 99.66400;29.32333;       0.35621;50.00000;100.00000;2.90499;3
100.33300;29.45667;       0.35609;50.00000;100.00000;2.90567;3
101.00200;29.59000;       0.35595;50.00000;100.00000;2.90635;3
101.67000;29.72333;       0.35579;50.00000;100.00000;2.90700;3
102.33700;29.85667;       0.35566;50.00000;100.00000;2.90765;3
103.00300;29.99000;       0.35549;50.00000;100.00000;2.90828;3
103.67200;30.12333;       0.35532;50.00000;100.00000;2.90891;3
104.34000;30.25667;       0.35518;50.00000;100.00000;2.90952;3
105.00900;30.39000;       0.35502;50.00000;100.00000;2.91013;3
105.67600;30.52333;       0.35484;50.00000;100.00000;2.91072;3
106.34400;30.65667;       0.35468;50.00000;100.00000;2.91130;3
107.01100;30.79000;       0.35450;50.00000;100.00000;2.91186;3
107.68100;30.92333;       0.35435;50.00000;100.00000;2.91242;3
108.34800;31.05667;       0.35418;50.00000;100.00000;2.91297;3
109.01600;31.19000;       0.35402;50.00000;100.00000;2.91350;3
109.68600;31.32333;       0.35387;50.00000;100.00000;2.91403;3
110.35400;31.45667;       0.35375;50.00000;100.00000;2.91454;3
111.02100;31.59000;       0.35360;50.00000;100.00000;2.91504;3
111.68800;31.72333;       0.35337;50.00000;100.00000;2.91553;3
112.35500;31.85667;       0.35323;50.00000;100.00000;2.91600;3
113.02300;31.99000;       0.35301;50.00000;100.00000;2.91647;3
113.69300;32.12333;       0.35286;50.00000;100.00000;2.91693;3
114.36200;32.25667;       0.35270;50.00000;100.00000;2.91737;3
115.02900;32.39000;       0.35253;50.00000;100.00000;2.91780;3
115.69800;32.52333;       0.35239;50.00000;100.00000;2.91823;3
116.36700;32.65667;       0.35221;50.00000;100.00000;2.91864;3
117.03300;32.79000;       0.35205;50.00000;100.00000;2.91903;3
117.70400;32.92333;       0.35191;50.00000;100.00000;2.91942;3
118.37200;33.05667;       0.35174;50.00000;100.00000;2.91980;3
119.03900;33.19000;       0.35155;50.00000;100.00000;2.92016;3
119.70700;33.32333;       0.35140;50.00000;100.00000;2.92051;3
120.37600;33.45667;       0.35122;50.00000;100.00000;2.92085;3
121.04400;33.59000;       0.35106;50.00000;100.00000;2.92118;3
121.71200;33.72333;       0.35090;50.00000;100.00000;2.92150;3
122.38000;33.85667;       0.35070;50.00000;100.00000;2.92181;3
123.04800;33.99000;       0.35051;50.00000;100.00000;2.92211;3
123.71800;34.12333;       0.35037;50.00000;100.00000;2.92239;3
124.38600;34.25667;       0.35018;50.00000;100.00000;2.92266;3
125.05400;34.39000;       0.35001;50.00000;100.00000;2.92292;3
125.72100;34.52333;       0.34983;50.00000;100.00000;2.92317;3
126.38900;34.65667;       0.34965;50.00000;100.00000;2.92341;3
127.05700;34.79000;       0.34950;50.00000;100.00000;2.92364;3
127.72600;34.92333;       0.34934;50.00000;100.00000;2.92386;3
128.39400;35.05667;       0.34919;50.00000;100.00000;2.92406;3
129.06100;35.19000;       0.34902;50.00000;100.00000;2.92425;3
129.73000;35.32333;       0.34886;50.00000;100.00000;2.92443;3
130.39700;35.45667;       0.34867;50.00000;100.00000;2.92460;3
131.06599;35.59000;       0.34850;50.00000;100.00000;2.92476;3
131.73399;35.72333;       0.34833;50.00000;100.00000;2.92491;3
132.40300;35.85667;       0.34820;50.00000;100.00000;2.92504;3
133.07100;35.99000;       0.34807;50.00000;100.00000;2.92517;3
133.73900;36.12333;       0.34792;50.00000;100.00000;2.92528;3
134.40601;36.25667;       0.34775;50.00000;100.00000;2.92538;3
135.07401;36.39000;       0.34759;50.00000;100.00000;2.92547;3
135.74200;36.52333;       0.34744;50.00000;100.00000;2.92555;3
136.41000;36.65667;       0.34730;50.00000;100.00000;2.92562;3
137.07800;36.79000;       0.34715;50.00000;100.00000;2.92567;3
137.74500;36.92333;       0.34701;50.00000;100.00000;2.92572;3
138.41299;37.05667;       0.34685;50.00000;100.00000;2.92575;3
139.08099;37.19000;       0.34670;50.00000;100.00000;2.92577;3
139.75000;37.32333;       0.34656;50.00000;100.00000;2.92578;3
140.41701;37.45667;       0.34648;50.00000;100.00000;2.92578;3
141.08600;37.59000;       0.34639;50.00000;100.00000;2.92576;3
141.75400;37.72333;       0.34630;50.00000;100.00000;2.92574;3
142.42200;37.85667;       0.34623;50.00000;100.00000;2.92570;3
143.08900;37.99000;       0.34614;50.00000;100.00000;2.92565;3
143.75900;38.12333;       0.34601;50.00000;100.00000;2.92559;3
144.42500;38.25667;       0.34589;50.00000;100.00000;2.92552;3
145.09399;38.39000;       0.34578;50.00000;100.00000;2.92544;3
145.76100;38.52333;       0.34566;50.00000;100.00000;2.92535;3
146.42900;38.65667;       0.34554;50.00000;100.00000;2.92524;3
147.09801;38.79000;       0.34543;50.00000;100.00000;2.92512;3
147.76601;38.92333;       0.34538;50.00000;100.00000;2.92500;3
148.43500;39.05667;       0.34538;50.00000;100.00000;2.92486;3
149.10201;39.19000;       0.34536;50.00000;100.00000;2.92471;3
149.76900;39.32333;       0.34530;50.00000;100.00000;2.92454;3
150.43900;39.45667;       0.34521;50.00000;100.00000;2.92437;3
151.10699;39.59000;       0.34510;50.00000;100.00000;2.92418;3
151.77499;39.72333;       0.34499;50.00000;100.00000;2.92399;3
152.44299;39.85667;       0.34492;50.00000;100.00000;2.92378;3
153.11099;39.99000;       0.34488;50.00000;100.00000;2.92356;3
153.77699;40.12333;       0.34492;50.00000;100.00000;2.92333;3
154.44600;40.25667;       0.34512;50.00000;100.00000;2.92309;3
155.11501;40.39000;       0.34531;50.00000;100.00000;2.92283;3
155.78200;40.52333;       0.34545;50.00000;100.00000;2.92257;3
156.45200;40.65667;       0.34562;50.00000;100.00000;2.92229;3
157.11900;40.79000;       0.34584;50.00000;100.00000;2.92200;3
157.78700;40.92333;       0.34599;50.00000;100.00000;2.92170;3
158.45399;41.05667;       0.34597;50.00000;100.00000;2.92139;3
159.12000;41.19000;       0.34587;50.00000;100.00000;2.92107;3
159.78799;41.32333;       0.34572;50.00000;100.00000;2.92073;3
160.45700;41.45667;       0.34562;50.00000;100.00000;2.92039;3
161.12199;41.59000;       0.34553;50.00000;100.00000;2.92003;3
161.78900;41.72333;       0.34540;50.00000;100.00000;2.91967;3
162.45700;41.85667;       0.34515;50.00000;100.00000;2.91929;3
163.12300;41.99000;       0.34492;50.00000;100.00000;2.91890;3
163.78999;42.12333;       0.34472;50.00000;100.00000;2.91849;3
164.45799;42.25667;       0.34446;50.00000;100.00000;2.91808;3
165.12500;42.39000;       0.34424;50.00000;100.00000;2.91766;3
165.79201;42.52333;       0.34397;50.00000;100.00000;2.91722;3
166.46100;42.65667;       0.34379;50.00000;100.00000;2.91677;3
167.13000;42.79000;       0.34365;50.00000;100.00000;2.91631;3
167.79700;42.92333;       0.34341;50.00000;100.00000;2.91584;3
168.46700;43.05667;       0.34320;50.00000;100.00000;2.91536;3
169.13400;43.19000;       0.34299;50.00000;100.00000;2.91487;3
169.80099;43.32333;       0.34284;50.00000;100.00000;2.91436;3
170.46899;43.45667;       0.34263;50.00000;100.00000;2.91385;3
171.13600;43.59000;       0.34243;50.00000;100.00000;2.91332;3
171.80499;43.72333;       0.34223;50.00000;100.00000;2.91278;3
172.47301;43.85667;       0.34209;50.00000;100.00000;2.91223;3
173.13901;43.99000;       0.34193;50.00000;100.00000;2.91167;3
173.80701;44.12333;       0.34176;50.00000;100.00000;2.91110;3
174.47600;44.25667;       0.34160;50.00000;100.00000;2.91052;3
175.14400;44.39000;       0.34144;50.00000;100.00000;2.90992;3
175.81000;44.52333;       0.34126;50.00000;100.00000;2.90932;3
176.47900;44.65667;       0.34107;50.00000;100.00000;2.90870;3
177.14700;44.79000;       0.34091;50.00000;100.00000;2.90807;3
177.81400;44.92333;       0.34076;50.00000;100.00000;2.90743;3
178.48199;45.05667;       0.34063;50.00000;100.00000;2.90678;3
179.14900;45.19000;       0.34041;50.00000;100.00000;2.90612;3
179.81599;45.32333;       0.34023;50.00000;100.00000;2.90545;3
180.48399;45.45667;       0.34008;50.00000;100.00000;2.90476;3
181.15199;45.59000;       0.33991;50.00000;100.00000;2.90407;3
181.81900;45.72333;       0.33978;50.00000;100.00000;2.90336;3
182.48700;45.85667;       0.33966;50.00000;100.00000;2.90264;3
183.15500;45.99000;       0.33947;50.00000;100.00000;2.90191;3
183.82201;46.12333;       0.33936;50.00000;100.00000;2.90117;3
184.49001;46.25667;       0.33918;50.00000;100.00000;2.90042;3
185.15800;46.39000;       0.33908;50.00000;100.00000;2.89966;3
185.82500;46.52333;       0.33894;50.00000;100.00000;2.89888;3
186.49300;46.65667;       0.33883;50.00000;100.00000;2.89810;3
187.16200;46.79000;       0.33873;50.00000;100.00000;2.89730;3
187.82899;46.92333;       0.33859;50.00000;100.00000;2.89649;3
188.49699;47.05667;       0.33847;50.00000;100.00000;2.89568;3
189.16400;47.19000;       0.33991;50.00000;100.00000;2.89485;3
189.83099;47.32333;       0.35168;50.00000;100.00000;2.89401;3
190.49800;47.45667;       0.35212;50.00000;100.00000;2.89316;3
191.16499;47.59000;       0.35180;50.00000;100.00000;2.89230;3
191.83099;47.72333;       0.35138;50.00000;100.00000;2.89142;3
192.49899;47.85667;       0.35091;50.00000;100.00000;2.89054;3
193.16701;47.99000;       0.35055;50.00000;100.00000;2.88964;3
193.83400;48.12333;       0.35020;50.00000;100.00000;2.88874;3
194.50200;48.25667;       0.34990;50.00000;100.00000;2.88782;3
195.16800;48.39000;       0.34965;50.00000;100.00000;2.88689;3
195.83600;48.52333;       0.34949;50.00000;100.00000;2.88595;3
196.50800;48.65833;       0.34897;50.00000;100.00000;2.88499;4
197.08099;48.79167;       0.34495;50.00000;100.00000;2.88417;4
197.53900;48.92500;       0.33627;50.00000;100.00000;2.88350;4
197.91100;49.05833;       0.32350;50.00000;100.00000;2.88296;4
198.21800;49.19167;       0.30714;50.00000;100.00000;2.88251;4
198.47000;49.32500;       0.28828;50.00000;100.00000;2.88214;4
198.68401;49.45833;       0.26795;50.00000;100.00000;2.88182;4
198.86301;49.59167;       0.24703;50.00000;100.00000;2.88155;4
199.01500;49.72500;       0.22617;50.00000;100.00000;2.88133;4
199.14500;49.85833;       0.20583;50.00000;100.00000;2.88113;4
199.25500;49.99167;       0.18625;50.00000;100.00000;2.88097;4
199.34801;50.12500;       0.16780;50.00000;100.00000;2.88083;4
199.42999;50.25833;       0.15048;50.00000;100.00000;2.88070;4
199.49899;50.39167;       0.13439;50.00000;100.00000;2.88060;4
199.56000;50.52500;       0.11948;50.00000;100.00000;2.88051;4
199.61099;50.65833;       0.10579;50.00000;100.00000;2.88043;4
199.65500;50.79167; 9.326492e-002;50.00000;100.00000;2.88036;4
199.69299;50.92500; 8.174536e-002;50.00000;100.00000;2.88031;4
199.72900;51.05833; 7.137005e-002;50.00000;100.00000;2.88025;4
199.75800;51.19167; 6.197854e-002;50.00000;100.00000;2.88021;4
199.78300;51.32500; 5.347325e-002;50.00000;100.00000;2.88017;4
199.80600;51.45833; 4.581934e-002;50.00000;100.00000;2.88014;4
199.82700;51.59167; 3.898895e-002;50.00000;100.00000;2.88010;4
199.84599;51.72500; 3.281110e-002;50.00000;100.00000;2.88008;4
199.86099;51.85833; 2.728587e-002;50.00000;100.00000;2.88005;4
199.87601;51.99167; 2.239926e-002;50.00000;100.00000;2.88003;4
199.88800;52.12500; 1.793149e-002;50.00000;100.00000;2.88001;4
199.89999;52.25833; 1.399068e-002;50.00000;100.00000;2.87999;4
199.91000;52.39167; 1.046174e-002;50.00000;100.00000;2.87998;4
199.92101;52.52500; 7.355054e-003;50.00000;100.00000;2.87996;4
199.92700;52.65833; 4.545172e-003;50.00000;100.00000;2.87995;4
199.93401;52.79167; 2.098231e-003;50.00000;100.00000;2.87994;4
199.94099;52.92500;-1.427987e-004;50.00000;100.00000;2.87993;4
199.94600;53.05833;-2.066151e-003;50.00000;100.00000;2.87992;4
199.95100;53.19167;-3.860371e-003;50.00000;100.00000;2.87992;4
199.95599;53.32500;-5.382352e-003;50.00000;100.00000;2.87991;4
199.96100;53.45833;-6.715862e-003;50.00000;100.00000;2.87990;4
199.96500;53.59167;-7.895763e-003;50.00000;100.00000;2.87990;4
199.97000;53.72500;-8.901189e-003;50.00000;100.00000;2.87989;4
199.97301;53.85833;-9.857676e-003;50.00000;100.00000;2.87988;4
199.97600;53.99167;-1.063616e-002;50.00000;100.00000;2.87988;4
199.97900;54.12500;-1.135181e-002;50.00000;100.00000;2.87987;4
199.98100;54.25833;-1.193130e-002;50.00000;100.00000;2.87987;4
199.98399;54.39167;-1.249338e-002;50.00000;100.00000;2.87987;4
199.98599;54.52500;-1.295769e-002;50.00000;100.00000;2.87986;4
199.98900;54.65833;-1.336619e-002;50.00000;100.00000;2.87986;4
199.99200;54.79167;-1.367347e-002;50.00000;100.00000;2.87985;4
199.99300;54.92500;-1.399813e-002;50.00000;100.00000;2.87985;4
199.99500;55.05833;-1.425650e-002;50.00000;100.00000;2.87985;4
199.99699;55.19167;-1.442413e-002;50.00000;100.00000;2.87985;4
199.99899;55.32500;-1.462317e-002;50.00000;100.00000;2.87984;4
200.00000;55.45833;-1.479773e-002;50.00000;100.00000;2.87984;4
200.00301;55.59167;-1.485371e-002;50.00000;100.00000;2.87984;4
200.00500;55.72500;-1.489917e-002;50.00000;100.00000;2.87983;4
200.00500;55.85833;-1.501087e-002;50.00000;100.00000;2.87983;4
200.00700;55.99167;-1.513312e-002;50.00000;100.00000;2.87983;4
200.00800;56.12500;-1.515062e-002;50.00000;100.00000;2.87983;4
200.00900;56.25833;-1.520651e-002;50.00000;100.00000;2.87983;4
200.00999;56.39167;-1.520306e-002;50.00000;100.00000;2.87983;4
200.01100;56.52500;-1.521008e-002;50.00000;100.00000;2.87983;4
200.00999;56.65833;-1.526589e-002;50.00000;100.00000;2.87983;4
200.01199;56.79167;-1.520315e-002;50.00000;100.00000;2.87982;4
200.01601;56.92500;-1.516492e-002;50.00000;100.00000;2.87982;4
200.01700;57.05833;-1.509516e-002;50.00000;100.00000;2.87982;4
200.01801;57.19167;-1.504633e-002;50.00000;100.00000;2.87981;4
200.01900;57.32500;-1.498355e-002;50.00000;100.00000;2.87981;4
200.01900;57.45833;-1.495911e-002;50.00000;100.00000;2.87981;4
200.02100;57.59167;-1.492779e-002;50.00000;100.00000;2.87981;4
200.02200;57.72500;-1.486849e-002;50.00000;100.00000;2.87981;4
200.02200;57.85833;-1.485802e-002;50.00000;100.00000;2.87981;4
200.02200;57.99167;-1.482661e-002;50.00000;100.00000;2.87981;4
200.02299;58.12500;-1.475335e-002;50.00000;100.00000;2.87981;4
200.02200;58.25833;-1.466953e-002;50.00000;100.00000;2.87981;4
200.02499;58.39167;-1.458589e-002;50.00000;100.00000;2.87980;4
200.02600;58.52500;-1.451613e-002;50.00000;100.00000;2.87980;4
200.02600;58.65833;-1.444632e-002;50.00000;100.00000;2.87980;4
200.02901;58.79167;-1.436267e-002;50.00000;100.00000;2.87980;4
200.02699;58.92500;-1.431721e-002;50.00000;100.00000;2.87980;4
200.02699;59.05833;-1.427532e-002;50.00000;100.00000;2.87980;4
200.03000;59.19167;-1.420564e-002;50.00000;100.00000;2.87980;4
200.02901;59.32500;-1.410787e-002;50.00000;100.00000;2.87980;4
200.03000;59.45833;-1.403461e-002;50.00000;100.00000;2.87980;4
200.03101;59.59167;-1.392295e-002;50.00000;100.00000;2.87979;4
200.03200;59.72500;-1.386366e-002;50.00000;100.00000;2.87979;4
200.03101;59.85833;-1.380777e-002;50.00000;100.00000;2.87979;4
200.03200;59.99167;-1.376592e-002;50.00000;100.00000;2.87979;4
200.03300;60.12500;-1.371710e-002;50.00000;100.00000;2.87979;4
200.03300;60.25833;-1.362286e-002;50.00000;100.00000;2.87979;4
200.03500;60.39167;-1.350776e-002;50.00000;100.00000;2.87979;4
200.03600;60.52500;-1.338563e-002;50.00000;100.00000;2.87979;4
200.03799;60.65833;-1.325657e-002;50.00000;100.00000;2.87978;4
200.03700;60.79167;-1.320766e-002;50.00000;100.00000;2.87979;4
200.03600;60.92500;-1.315177e-002;50.00000;100.00000;2.87979;4
200.03799;61.05833;-1.308902e-002;50.00000;100.00000;2.87978;4
200.03799;61.19167;-1.307157e-002;50.00000;100.00000;2.87978;4
200.03700;61.32500;-1.299125e-002;50.00000;100.00000;2.87979;4
200.03700;61.45833;-1.294936e-002;50.00000;100.00000;2.87979;4
200.03799;61.59167;-1.290402e-002;50.00000;100.00000;2.87978;4
200.03799;61.72500;-1.284120e-002;50.00000;100.00000;2.87978;4
200.03799;61.85833;-1.274695e-002;50.00000;100.00000;2.87978;4
200.03900;61.99167;-1.270860e-002;50.00000;100.00000;2.87978;4
200.03999;62.12500;-1.264581e-002;50.00000;100.00000;2.87978;4
200.03900;62.25833;-1.257247e-002;50.00000;100.00000;2.87978;4
200.04100;62.39167;-1.252019e-002;50.00000;100.00000;2.87978;4
200.03999;62.52500;-1.247478e-002;50.00000;100.00000;2.87978;4
200.03999;62.65833;-1.238402e-002;50.00000;100.00000;2.87978;4
200.04201;62.79167;-1.234222e-002;50.00000;100.00000;2.87978;4
200.03999;62.92500;-1.230025e-002;50.00000;100.00000;2.87978;4
200.04201;63.05833;-1.226194e-002;50.00000;100.00000;2.87978;4
200.03999;63.19167;-1.220950e-002;50.00000;100.00000;2.87978;4
200.03999;63.32500;-1.218157e-002;50.00000;100.00000;2.87978;4
200.03900;63.45833;-1.214314e-002;50.00000;100.00000;2.87978;4
200.03900;63.59167;-1.206984e-002;50.00000;100.00000;2.87978;4
200.03999;63.72500;-1.200356e-002;50.00000;100.00000;2.87978;4
200.03900;63.85833;-1.197908e-002;50.00000;100.00000;2.87978;4
200.03999;63.99167;-1.188488e-002;50.00000;100.00000;2.87978;4
200.03700;64.12500;-1.189174e-002;50.00000;100.00000;2.87979;4
200.03799;64.25833;-1.186734e-002;50.00000;100.00000;2.87978;4
200.03999;64.39167;-1.178365e-002;50.00000;100.00000;2.87978;4
200.03799;64.52500;-1.169282e-002;50.00000;100.00000;2.87978;4
200.03900;64.65833;-1.161607e-002;50.00000;100.00000;2.87978;4
200.03799;64.79167;-1.154273e-002;50.00000;100.00000;2.87978;4
200.03799;64.92500;-1.148688e-002;50.00000;100.00000;2.87978;4
200.03900;65.05833;-1.139966e-002;50.00000;100.00000;2.87978;4
200.03999;65.19167;-1.134036e-002;50.00000;100.00000;2.87978;4
200.03999;65.32500;-1.124961e-002;50.00000;100.00000;2.87978;4
200.03999;65.45833;-1.117282e-002;50.00000;100.00000;2.87978;4
200.03999;65.59167;-1.112395e-002;50.00000;100.00000;2.87978;4
200.04201;65.72500;-1.102281e-002;50.00000;100.00000;2.87978;4
200.04100;65.85833;-1.098786e-002;50.00000;100.00000;2.87978;4
200.04201;65.99167;-1.090064e-002;50.00000;100.00000;2.87978;4
200.04300;66.12500;-1.082040e-002;50.00000;100.00000;2.87978;4
200.04201;66.25833;-1.075404e-002;50.00000;100.00000;2.87978;4
200.04201;66.39167;-1.070517e-002;50.00000;100.00000;2.87978;4
200.04300;66.52500;-1.064587e-002;50.00000;100.00000;2.87978;4
200.04300;66.65833;-1.057955e-002;50.00000;100.00000;2.87978;4
200.04401;66.79167;-1.050629e-002;50.00000;100.00000;2.87977;4
200.04500;66.92500;-1.046445e-002;50.00000;100.00000;2.87977;4
200.04401;67.05833;-1.039809e-002;50.00000;100.00000;2.87977;4
200.04500;67.19167;-1.035973e-002;50.00000;100.00000;2.87977;4
200.04500;67.32500;-1.031086e-002;50.00000;100.00000;2.87977;4
200.04601;67.45833;-1.025855e-002;50.00000;100.00000;2.87977;4
200.04500;67.59167;-1.022709e-002;50.00000;100.00000;2.87977;4
200.04500;67.72500;-1.019568e-002;50.00000;100.00000;2.87977;4
200.04500;67.85833;-1.014332e-002;50.00000;100.00000;2.87977;4
200.04500;67.99167;-1.011888e-002;50.00000;100.00000;2.87977;4
200.04500;68.12500;-1.007700e-002;50.00000;100.00000;2.87977;4
200.04401;68.25833;-1.001762e-002;50.00000;100.00000;2.87977;4
200.04700;68.39167;-9.968874e-003;50.00000;100.00000;2.87977;4
200.04601;68.52500;-9.906003e-003;50.00000;100.00000;2.87977;4
200.04601;68.65833;-9.853645e-003;50.00000;100.00000;2.87977;4
200.04700;68.79167;-9.829253e-003;50.00000;100.00000;2.87977;4
200.04700;68.92500;-9.797838e-003;50.00000;100.00000;2.87977;4
200.04601;69.05833;-9.776853e-003;50.00000;100.00000;2.87977;4
200.04601;69.19167;-9.762891e-003;50.00000;100.00000;2.87977;4
200.04601;69.32500;-9.721005e-003;50.00000;100.00000;2.87977;4
200.04700;69.45833;-9.689632e-003;50.00000;100.00000;2.87977;4
200.04700;69.59167;-9.598879e-003;50.00000;100.00000;2.87977;4
200.04800;69.72500;-9.570994e-003;50.00000;100.00000;2.87977;4
200.04800;69.85833;-9.518636e-003;50.00000;100.00000;2.87977;4
200.04800;69.99167;-9.476750e-003;50.00000;100.00000;2.87977;4
200.04800;70.12500;-9.438354e-003;50.00000;100.00000;2.87977;4
200.04601;70.25833;-9.406858e-003;50.00000;100.00000;2.87977;4
200.04700;70.39167;-9.340580e-003;50.00000;100.00000;2.87977;4
200.04700;70.52500;-9.305675e-003;50.00000;100.00000;2.87977;4
200.04800;70.65833;-9.228923e-003;50.00000;100.00000;2.87977;4
200.04800;70.79167;-9.194018e-003;50.00000;100.00000;2.87977;4
200.04800;70.92500;-9.110245e-003;50.00000;100.00000;2.87977;4
200.04900;71.05833;-9.082360e-003;50.00000;100.00000;2.87977;4
200.05000;71.19167;-9.009100e-003;50.00000;100.00000;2.87977;4
200.04900;71.32500;-8.995097e-003;50.00000;100.00000;2.87977;4
200.04800;71.45833;-8.981096e-003;50.00000;100.00000;2.87977;4
200.05000;71.59167;-8.935798e-003;50.00000;100.00000;2.87977;4
200.05099;71.72500;-8.873008e-003;50.00000;100.00000;2.87976;4
200.04900;71.85833;-8.845004e-003;50.00000;100.00000;2.87977;4
200.04900;71.99167;-8.806608e-003;50.00000;100.00000;2.87977;4
200.05099;72.12500;-8.747349e-003;50.00000;100.00000;2.87976;4
200.05099;72.25833;-8.733387e-003;50.00000;100.00000;2.87976;4
200.04900;72.39167;-8.754250e-003;50.00000;100.00000;2.87977;4
200.04900;72.52500;-8.736798e-003;50.00000;100.00000;2.87977;4
200.04900;72.65833;-8.656516e-003;50.00000;100.00000;2.87977;4
200.05000;72.79167;-8.590236e-003;50.00000;100.00000;2.87977;4
200.05000;72.92500;-8.523916e-003;50.00000;100.00000;2.87977;4
200.05200;73.05833;-8.478619e-003;50.00000;100.00000;2.87976;4
200.05000;73.19167;-8.468067e-003;50.00000;100.00000;2.87977;4
200.05099;73.32500;-8.433202e-003;50.00000;100.00000;2.87976;4
200.05000;73.45833;-8.426181e-003;50.00000;100.00000;2.87977;4
200.05099;73.59167;-8.408768e-003;50.00000;100.00000;2.87976;4
200.04900;73.72500;-8.384255e-003;50.00000;100.00000;2.87977;4
200.04900;73.85833;-8.384255e-003;50.00000;100.00000;2.87977;4
200.05000;73.99167;-8.331937e-003;50.00000;100.00000;2.87977;4
200.04800;74.12500;-8.331858e-003;50.00000;100.00000;2.87977;4
200.04900;74.25833;-8.300482e-003;50.00000;100.00000;2.87977;4
200.04800;74.39167;-8.293462e-003;50.00000;100.00000;2.87977;4
200.04700;74.52500;-8.310875e-003;50.00000;100.00000;2.87977;4
200.04700;74.65833;-8.321347e-003;50.00000;100.00000;2.87977;4
200.04700;74.79167;-8.275970e-003;50.00000;100.00000;2.87977;4
200.04900;74.92500;-8.206238e-003;50.00000;100.00000;2.87977;4
200.04800;75.05833;-8.157331e-003;50.00000;100.00000;2.87977;4
200.04700;75.19167;-8.111916e-003;50.00000;100.00000;2.87977;4
200.04900;75.32500;-8.017749e-003;50.00000;100.00000;2.87977;4
200.04900;75.45833;-7.982844e-003;50.00000;100.00000;2.87977;4
200.05000;75.59167;-7.944488e-003;50.00000;100.00000;2.87977;4
200.04900;75.72500;-7.916524e-003;50.00000;100.00000;2.87977;4
200.04900;75.85833;-7.888600e-003;50.00000;100.00000;2.87977;4
200.04800;75.99167;-7.906014e-003;50.00000;100.00000;2.87977;4
200.04800;76.12500;-7.906014e-003;50.00000;100.00000;2.87977;4
200.04601;76.25833;-7.881501e-003;50.00000;100.00000;2.87977;4
200.04601;76.39167;-7.926878e-003;50.00000;100.00000;2.87977;4
200.04601;76.52500;-7.846596e-003;50.00000;100.00000;2.87977;4
200.04601;76.65833;-7.860558e-003;50.00000;100.00000;2.87977;4
200.04500;76.79167;-7.804670e-003;50.00000;100.00000;2.87977;4
200.04700;76.92500;-7.717486e-003;50.00000;100.00000;2.87977;4
200.04601;77.05833;-7.672070e-003;50.00000;100.00000;2.87977;4
200.04700;77.19167;-7.588337e-003;50.00000;100.00000;2.87977;4
200.04700;77.32500;-7.525507e-003;50.00000;100.00000;2.87977;4
200.04700;77.45833;-7.494093e-003;50.00000;100.00000;2.87977;4
200.04800;77.59167;-7.508094e-003;50.00000;100.00000;2.87977;4
200.04601;77.72500;-7.490563e-003;50.00000;100.00000;2.87977;4
200.04601;77.85833;-7.455657e-003;50.00000;100.00000;2.87977;4
200.04500;77.99167;-7.431185e-003;50.00000;100.00000;2.87977;4
200.04500;78.12500;-7.424203e-003;50.00000;100.00000;2.87977;4
200.04601;78.25833;-7.420752e-003;50.00000;100.00000;2.87977;4
200.04601;78.39167;-7.427733e-003;50.00000;100.00000;2.87977;4
200.04401;78.52500;-7.403222e-003;50.00000;100.00000;2.87977;4
200.03900;78.66000;-7.486798e-003;50.00000;100.00000;2.87978;5
199.93300;78.79333;-1.155235e-002;50.00000;100.00000;2.87994;5
199.68500;78.92667;-2.157197e-002;50.00000;100.00000;2.88032;5
199.30800;79.06000;-3.734991e-002;50.00000;100.00000;2.88089;5
198.83099;79.19333;-5.816652e-002;50.00000;100.00000;2.88160;5
198.27400;79.32667;-8.272971e-002;50.00000;100.00000;2.88243;5
197.65401;79.46000;      -0.10964;50.00000;100.00000;2.88334;5
196.98199;79.59333;      -0.13768;50.00000;100.00000;2.88431;5
196.26900;79.72667;      -0.16593;50.00000;100.00000;2.88534;5
195.52600;79.86000;      -0.19353;50.00000;100.00000;2.88639;5
194.75301;79.99333;      -0.22003;50.00000;100.00000;2.88747;5
193.96100;80.12667;      -0.24505;50.00000;100.00000;2.88856;5
193.15199;80.26000;      -0.26854;50.00000;100.00000;2.88966;5
192.32800;80.39333;      -0.29012;50.00000;100.00000;2.89077;5
191.49600;80.52667;      -0.30996;50.00000;100.00000;2.89186;5
190.65700;80.66000;      -0.32797;50.00000;100.00000;2.89295;5
189.80701;80.79333;      -0.34424;50.00000;100.00000;2.89404;5
188.95599;80.92667;      -0.35885;50.00000;100.00000;2.89511;5
188.10201;81.06000;      -0.37184;50.00000;100.00000;2.89616;5
187.25000;81.19333;      -0.38322;50.00000;100.00000;2.89720;5
186.40500;81.32667;      -0.39288;50.00000;100.00000;2.89820;5
185.57300;81.46000;      -0.40076;50.00000;100.00000;2.89918;5
184.75600;81.59333;      -0.40686;50.00000;100.00000;2.90012;5
183.95399;81.72667;      -0.41130;50.00000;100.00000;2.90102;5
183.16800;81.86000;      -0.41411;50.00000;100.00000;2.90190;5
182.40100;81.99333;      -0.41544;50.00000;100.00000;2.90273;5
181.64900;82.12667;      -0.41555;50.00000;100.00000;2.90354;5
180.91200;82.26000;      -0.41446;50.00000;100.00000;2.90432;5
180.19299;82.39333;      -0.41245;50.00000;100.00000;2.90506;5
179.48801;82.52667;      -0.40956;50.00000;100.00000;2.90578;5
178.79700;82.66000;      -0.40604;50.00000;100.00000;2.90647;5
178.12199;82.79333;      -0.40194;50.00000;100.00000;2.90713;5
177.46001;82.92667;      -0.39735;50.00000;100.00000;2.90777;5
176.81100;83.06000;      -0.39241;50.00000;100.00000;2.90839;5
176.17300;83.19333;      -0.38722;50.00000;100.00000;2.90898;5
175.54800;83.32667;      -0.38187;50.00000;100.00000;2.90956;5
174.93300;83.46000;      -0.37640;50.00000;100.00000;2.91011;5
174.32700;83.59333;      -0.37087;50.00000;100.00000;2.91065;5
173.73100;83.72667;      -0.36533;50.00000;100.00000;2.91117;5
173.14700;83.86000;      -0.35979;50.00000;100.00000;2.91167;5
172.56900;83.99333;      -0.35434;50.00000;100.00000;2.91215;5
172.00301;84.12667;      -0.34896;50.00000;100.00000;2.91262;5
171.44200;84.26000;      -0.34369;50.00000;100.00000;2.91308;5
170.88800;84.39333;      -0.33856;50.00000;100.00000;2.91352;5
170.34200;84.52667;      -0.33357;50.00000;100.00000;2.91395;5
169.80200;84.66000;      -0.32875;50.00000;100.00000;2.91436;5
169.26801;84.79333;      -0.32404;50.00000;100.00000;2.91477;5
168.74001;84.92667;      -0.31953;50.00000;100.00000;2.91516;5
168.21700;85.06000;      -0.31515;50.00000;100.00000;2.91554;5
167.70000;85.19333;      -0.31099;50.00000;100.00000;2.91591;5
167.18800;85.32667;      -0.30702;50.00000;100.00000;2.91627;5
166.68100;85.46000;      -0.30316;50.00000;100.00000;2.91662;5
166.17700;85.59333;      -0.29949;50.00000;100.00000;2.91696;5
165.67799;85.72667;      -0.29597;50.00000;100.00000;2.91730;5
165.18300;85.86000;      -0.29261;50.00000;100.00000;2.91762;5
164.69299;85.99333;      -0.28936;50.00000;100.00000;2.91793;5
164.20500;86.12667;      -0.28628;50.00000;100.00000;2.91824;5
163.72200;86.26000;      -0.28333;50.00000;100.00000;2.91854;5
163.24100;86.39333;      -0.28049;50.00000;100.00000;2.91883;5
162.76300;86.52667;      -0.27782;50.00000;100.00000;2.91911;5
162.28799;86.66000;      -0.27526;50.00000;100.00000;2.91938;5
161.81700;86.79333;      -0.27282;50.00000;100.00000;2.91965;5
161.34801;86.92667;      -0.27046;50.00000;100.00000;2.91991;5
160.88200;87.06000;      -0.26826;50.00000;100.00000;2.92016;5
160.42000;87.19333;      -0.26610;50.00000;100.00000;2.92041;5
159.95900;87.32667;      -0.26398;50.00000;100.00000;2.92065;5
159.50200;87.46000;      -0.26197;50.00000;100.00000;2.92088;5
159.04900;87.59333;      -0.25999;50.00000;100.00000;2.92110;5
158.59599;87.72667;      -0.25810;50.00000;100.00000;2.92132;5
158.14799;87.86000;      -0.25623;50.00000;100.00000;2.92153;5
157.70200;87.99333;      -0.25443;50.00000;100.00000;2.92174;5
157.25900;88.12667;      -0.25266;50.00000;100.00000;2.92194;5
156.81700;88.26000;      -0.25091;50.00000;100.00000;2.92213;5
156.37900;88.39333;      -0.24925;50.00000;100.00000;2.92232;5
155.94299;88.52667;      -0.24759;50.00000;100.00000;2.92250;5
155.50999;88.66000;      -0.24601;50.00000;100.00000;2.92267;5
155.07899;88.79333;      -0.24438;50.00000;100.00000;2.92284;5
154.65100;88.92667;      -0.24284;50.00000;100.00000;2.92301;5
154.22600;89.06000;      -0.24131;50.00000;100.00000;2.92317;5
153.80299;89.19333;      -0.23982;50.00000;100.00000;2.92332;5
153.38200;89.32667;      -0.23837;50.00000;100.00000;2.92347;5
152.96300;89.46000;      -0.23690;50.00000;100.00000;2.92361;5
152.54800;89.59333;      -0.23551;50.00000;100.00000;2.92374;5
152.13300;89.72667;      -0.23409;50.00000;100.00000;2.92388;5
151.72099;89.86000;      -0.23273;50.00000;100.00000;2.92400;5
151.31100;89.99333;      -0.23141;50.00000;100.00000;2.92412;5
150.90401;90.12667;      -0.23010;50.00000;100.00000;2.92424;5
150.49899;90.26000;      -0.22877;50.00000;100.00000;2.92435;5
150.09500;90.39333;      -0.22751;50.00000;100.00000;2.92446;5
149.69299;90.52667;      -0.22622;50.00000;100.00000;2.92456;5
149.29401;90.66000;      -0.22496;50.00000;100.00000;2.92466;5
148.89700;90.79333;      -0.22375;50.00000;100.00000;2.92475;5
148.50200;90.92667;      -0.22253;50.00000;100.00000;2.92484;5
148.10800;91.06000;      -0.22134;50.00000;100.00000;2.92493;5
147.71700;91.19333;      -0.22016;50.00000;100.00000;2.92501;5
147.33000;91.32667;      -0.21899;50.00000;100.00000;2.92508;5
146.94200;91.46000;      -0.21782;50.00000;100.00000;2.92515;5
146.55701;91.59333;      -0.21671;50.00000;100.00000;2.92522;5
146.17500;91.72667;      -0.21561;50.00000;100.00000;2.92528;5
145.79201;91.86000;      -0.21447;50.00000;100.00000;2.92534;5
145.41299;91.99333;      -0.21341;50.00000;100.00000;2.92540;5
145.03500;92.12667;      -0.21228;50.00000;100.00000;2.92545;5
144.65900;92.26000;      -0.21123;50.00000;100.00000;2.92549;5
144.28600;92.39333;      -0.21018;50.00000;100.00000;2.92554;5
143.91299;92.52667;      -0.20911;50.00000;100.00000;2.92558;5
143.54201;92.66000;      -0.20811;50.00000;100.00000;2.92561;5
143.17500;92.79333;      -0.20707;50.00000;100.00000;2.92565;5
142.80701;92.92667;      -0.20606;50.00000;100.00000;2.92567;5
142.44000;93.06000;      -0.20506;50.00000;100.00000;2.92570;5
142.07700;93.19333;      -0.20407;50.00000;100.00000;2.92572;5
141.71500;93.32667;      -0.20307;50.00000;100.00000;2.92574;5
141.35500;93.46000;      -0.20214;50.00000;100.00000;2.92575;5
140.99699;93.59333;      -0.20122;50.00000;100.00000;2.92576;5
140.63800;93.72667;      -0.20023;50.00000;100.00000;2.92577;5
140.28400;93.86000;      -0.19928;50.00000;100.00000;2.92578;5
139.93201;93.99333;      -0.19844;50.00000;100.00000;2.92578;5
139.57899;94.12667;      -0.19743;50.00000;100.00000;2.92578;5
139.22900;94.26000;      -0.19653;50.00000;100.00000;2.92577;5
138.87900;94.39333;      -0.19566;50.00000;100.00000;2.92576;5
138.53400;94.52667;      -0.19475;50.00000;100.00000;2.92575;5
138.18600;94.66000;      -0.19388;50.00000;100.00000;2.92574;5
137.84200;94.79333;      -0.19299;50.00000;100.00000;2.92572;5
137.50000;94.92667;      -0.19210;50.00000;100.00000;2.92570;5
137.15900;95.06000;      -0.19125;50.00000;100.00000;2.92568;5
136.82001;95.19333;      -0.19037;50.00000;100.00000;2.92565;5
136.48199;95.32667;      -0.18949;50.00000;100.00000;2.92562;5
136.14600;95.46000;      -0.18863;50.00000;100.00000;2.92559;5
135.81200;95.59333;      -0.18778;50.00000;100.00000;2.92556;5
135.47800;95.72667;      -0.18697;50.00000;100.00000;2.92552;5
135.14700;95.86000;      -0.18609;50.00000;100.00000;2.92548;5
134.81799;95.99333;      -0.18524;50.00000;100.00000;2.92544;5
134.49001;96.12667;      -0.18444;50.00000;100.00000;2.92539;5
134.16299;96.26000;      -0.18360;50.00000;100.00000;2.92535;5
133.83701;96.39333;      -0.18279;50.00000;100.00000;2.92530;5
133.51300;96.52667;      -0.18191;50.00000;100.00000;2.92524;5
133.19200;96.66000;      -0.18108;50.00000;100.00000;2.92519;5
132.87000;96.79333;      -0.18025;50.00000;100.00000;2.92513;5
132.55099;96.92667;      -0.17939;50.00000;100.00000;2.92507;5
132.23500;97.06000;      -0.17858;50.00000;100.00000;2.92501;5
131.91901;97.19333;      -0.17774;50.00000;100.00000;2.92495;5
131.60600;97.32667;      -0.17690;50.00000;100.00000;2.92488;5
131.29300;97.46000;      -0.17602;50.00000;100.00000;2.92481;5
130.98300;97.59333;      -0.17518;50.00000;100.00000;2.92474;5
130.67400;97.72667;      -0.17434;50.00000;100.00000;2.92467;5
130.36501;97.86000;      -0.17350;50.00000;100.00000;2.92460;5
130.05901;97.99333;      -0.17266;50.00000;100.00000;2.92452;5
129.75500;98.12667;      -0.17188;50.00000;100.00000;2.92444;5
129.45000;98.26000;      -0.17111;50.00000;100.00000;2.92436;5
129.14799;98.39333;      -0.17030;50.00000;100.00000;2.92428;5
128.84700;98.52667;      -0.16957;50.00000;100.00000;2.92419;5
128.54401;98.66000;      -0.16890;50.00000;100.00000;2.92410;5
128.24400;98.79333;      -0.16818;50.00000;100.00000;2.92401;5
127.94600;98.92667;      -0.16751;50.00000;100.00000;2.92392;5
127.65000;99.06000;      -0.16681;50.00000;100.00000;2.92383;5
127.35400;99.19333;      -0.16613;50.00000;100.00000;2.92374;5
127.05900;99.32667;      -0.16547;50.00000;100.00000;2.92364;5
126.76500;99.46000;      -0.16477;50.00000;100.00000;2.92354;5
126.47300;99.59333;      -0.16412;50.00000;100.00000;2.92344;5
126.18200;99.72667;      -0.16342;50.00000;100.00000;2.92334;5
125.89300;99.86000;      -0.16275;50.00000;100.00000;2.92324;5
125.60500;99.99333;      -0.16207;50.00000;100.00000;2.92313;5