File: examples/data/A_3.txt
#EXPORTTYPE:DATA ALL
#FILE:
#FORMAT:NETZSCH5
#FTYPE:ANSI
#IDENTITY:
#DECIMAL:POINT
#SEPARATOR:SEMICOLON
#MTYPE:DSC
#INSTRUMENT:NETZSCH DSC 200F3
#PROJECT:dsc_data_analysis
#DATE/TIME:19.03.2025 21:19
#CORR. FILE:
#TEMPCAL:temp_cal_3Kmin.ngb-td5
#SENSITIVITY:sens_cal_3Kmin.ngb-ed5
#LABORATORY:
#OPERATOR:
#REMARK:CR 1369.2; tot 1443.2
#SAMPLE:
#SAMPLE MASS /mg:74.8
#MATERIAL:
#REFERENCE:Ref.
#REFERENCE MASS /mg:0
#TYPE OF CRUCIBLE:High pressure, steel
#SAMPLE CRUCIBLE MASS /mg:1369.2
#REFERENCE CRUCIBLE MASS /mg:1385.5
#M.RANGE /�V:5000
#TAU-R:---
#CORR. CODE:000
#EXO:-1
#RANGE:25�C....200�C/-7.0....7.0K/min
#SEGMENT:S1-5/5
#SEG. 1:25�C/7.0(K/min)/50�C
#SEG. 2:50�C/00:15/50�C
#SEG. 3:50�C/5.0(K/min)/200�C
#SEG. 4:200�C/00:30/200�C
#SEG. 5:200�C/7.0(K/min)/50�C

##Temp./C;Time/min;DSC/(mW/mg);Gas Flow(purge2)/(ml/min);Gas Flow(protective)/(ml/min);Sensit./(uV/mW);Segment
 26.29600; 0.00000;-2.676422e-003;50.00000;100.00000;2.76444;1
 26.29500; 0.13333;-2.650560e-003;50.00000;100.00000;2.76444;1
 26.31400; 0.26667;-1.817379e-003;50.00000;100.00000;2.76449;1
 26.39800; 0.40000; 1.274916e-003;50.00000;100.00000;2.76472;1
 26.58900; 0.53333; 8.408570e-003;50.00000;100.00000;2.76525;1
 26.90600; 0.66667; 2.017529e-002;50.00000;100.00000;2.76612;1
 27.33200; 0.80000; 3.651227e-002;50.00000;100.00000;2.76729;1
 27.85100; 0.93333; 5.676906e-002;50.00000;100.00000;2.76871;1
 28.44500; 1.06667; 8.010427e-002;50.00000;100.00000;2.77032;1
 29.09600; 1.20000;       0.10561;50.00000;100.00000;2.77208;1
 29.79200; 1.33333;       0.13238;50.00000;100.00000;2.77396;1
 30.52400; 1.46667;       0.15966;50.00000;100.00000;2.77592;1
 31.28600; 1.60000;       0.18677;50.00000;100.00000;2.77794;1
 32.07300; 1.73333;       0.21335;50.00000;100.00000;2.78002;1
 32.88000; 1.86667;       0.23896;50.00000;100.00000;2.78214;1
 33.70200; 2.00000;       0.26342;50.00000;100.00000;2.78428;1
 34.54000; 2.13333;       0.28657;50.00000;100.00000;2.78645;1
 35.39000; 2.26667;       0.30836;50.00000;100.00000;2.78864;1
 36.24900; 2.40000;       0.32868;50.00000;100.00000;2.79083;1
 37.12100; 2.53333;       0.34765;50.00000;100.00000;2.79303;1
 38.00000; 2.66667;       0.36519;50.00000;100.00000;2.79524;1
 38.88700; 2.80000;       0.38140;50.00000;100.00000;2.79745;1
 39.77700; 2.93333;       0.39636;50.00000;100.00000;2.79965;1
 40.67200; 3.06667;       0.41014;50.00000;100.00000;2.80185;1
 41.57400; 3.20000;       0.42280;50.00000;100.00000;2.80404;1
 42.48000; 3.33333;       0.43438;50.00000;100.00000;2.80623;1
 43.39000; 3.46667;       0.44502;50.00000;100.00000;2.80840;1
 44.22200; 3.58833;       0.45389;50.00000;100.00000;2.81038;2
 45.10700; 3.72167;       0.46154;50.00000;100.00000;2.81246;2
 45.86700; 3.85500;       0.46379;50.00000;100.00000;2.81423;2
 46.50900; 3.98833;       0.46090;50.00000;100.00000;2.81572;2
 47.04800; 4.12167;       0.45306;50.00000;100.00000;2.81696;2
 47.50300; 4.25500;       0.44085;50.00000;100.00000;2.81801;2
 47.89000; 4.38833;       0.42507;50.00000;100.00000;2.81889;2
 48.21900; 4.52167;       0.40664;50.00000;100.00000;2.81964;2
 48.50200; 4.65500;       0.38628;50.00000;100.00000;2.82028;2
 48.74500; 4.78833;       0.36479;50.00000;100.00000;2.82083;2
 48.95500; 4.92167;       0.34283;50.00000;100.00000;2.82130;2
 49.13800; 5.05500;       0.32080;50.00000;100.00000;2.82172;2
 49.29800; 5.18833;       0.29911;50.00000;100.00000;2.82208;2
 49.43400; 5.32167;       0.27807;50.00000;100.00000;2.82238;2
 49.55500; 5.45500;       0.25778;50.00000;100.00000;2.82265;2
 49.66100; 5.58833;       0.23837;50.00000;100.00000;2.82289;2
 49.75300; 5.72167;       0.21996;50.00000;100.00000;2.82310;2
 49.83200; 5.85500;       0.20259;50.00000;100.00000;2.82327;2
 49.90400; 5.98833;       0.18630;50.00000;100.00000;2.82343;2
 49.96600; 6.12167;       0.17111;50.00000;100.00000;2.82357;2
 50.02200; 6.25500;       0.15698;50.00000;100.00000;2.82370;2
 50.07100; 6.38833;       0.14384;50.00000;100.00000;2.82381;2
 50.11500; 6.52167;       0.13169;50.00000;100.00000;2.82390;2
 50.15300; 6.65500;       0.12041;50.00000;100.00000;2.82399;2
 50.18800; 6.78833;       0.10997;50.00000;100.00000;2.82407;2
 50.21500; 6.92167;       0.10034;50.00000;100.00000;2.82413;2
 50.24000; 7.05500; 9.149528e-002;50.00000;100.00000;2.82418;2
 50.26500; 7.18833; 8.335948e-002;50.00000;100.00000;2.82424;2
 50.28400; 7.32167; 7.584936e-002;50.00000;100.00000;2.82428;2
 50.30200; 7.45500; 6.900404e-002;50.00000;100.00000;2.82432;2
 50.31700; 7.58833; 6.267920e-002;50.00000;100.00000;2.82435;2
 50.33100; 7.72167; 5.692519e-002;50.00000;100.00000;2.82438;2
 50.34600; 7.85500; 5.166957e-002;50.00000;100.00000;2.82442;2
 50.35500; 7.98833; 4.683343e-002;50.00000;100.00000;2.82444;2
 50.36600; 8.12167; 4.249556e-002;50.00000;100.00000;2.82446;2
 50.37600; 8.25500; 3.853700e-002;50.00000;100.00000;2.82449;2
 50.38400; 8.38833; 3.491448e-002;50.00000;100.00000;2.82450;2
 50.39000; 8.52167; 3.157018e-002;50.00000;100.00000;2.82452;2
 50.39500; 8.65500; 2.856541e-002;50.00000;100.00000;2.82453;2
 50.40100; 8.78833; 2.579173e-002;50.00000;100.00000;2.82454;2
 50.40600; 8.92167; 2.327812e-002;50.00000;100.00000;2.82455;2
 50.40900; 9.05500; 2.099575e-002;50.00000;100.00000;2.82456;2
 50.41300; 9.18833; 1.885056e-002;50.00000;100.00000;2.82457;2
 50.41400; 9.32167; 1.691858e-002;50.00000;100.00000;2.82457;2
 50.41400; 9.45500; 1.517082e-002;50.00000;100.00000;2.82457;2
 50.42000; 9.58833; 1.359611e-002;50.00000;100.00000;2.82458;2
 50.42400; 9.72167; 1.224178e-002;50.00000;100.00000;2.82459;2
 50.42600; 9.85500; 1.105727e-002;50.00000;100.00000;2.82460;2
 50.42900; 9.98833; 9.948546e-003;50.00000;100.00000;2.82460;2
 50.43100;10.12167; 8.894039e-003;50.00000;100.00000;2.82461;2
 50.43300;10.25500; 7.980364e-003;50.00000;100.00000;2.82461;2
 50.43300;10.38833; 7.149830e-003;50.00000;100.00000;2.82461;2
 50.43600;10.52167; 6.322782e-003;50.00000;100.00000;2.82462;2
 50.43400;10.65500; 5.593439e-003;50.00000;100.00000;2.82461;2
 50.43500;10.78833; 4.910917e-003;50.00000;100.00000;2.82462;2
 50.43700;10.92167; 4.325853e-003;50.00000;100.00000;2.82462;2
 50.43600;11.05500; 3.784241e-003;50.00000;100.00000;2.82462;2
 50.43600;11.18833; 3.285921e-003;50.00000;100.00000;2.82462;2
 50.43800;11.32167; 2.816413e-003;50.00000;100.00000;2.82462;2
 50.43700;11.45500; 2.430073e-003;50.00000;100.00000;2.82462;2
 50.43800;11.58833; 2.094212e-003;50.00000;100.00000;2.82462;2
 50.44000;11.72167; 1.769145e-003;50.00000;100.00000;2.82463;2
 50.44000;11.85500; 1.505542e-003;50.00000;100.00000;2.82463;2
 50.43900;11.98833; 1.256421e-003;50.00000;100.00000;2.82462;2
 50.44000;12.12167; 1.057778e-003;50.00000;100.00000;2.82463;2
 50.44100;12.25500; 9.060793e-004;50.00000;100.00000;2.82463;2
 50.44300;12.38833; 7.074004e-004;50.00000;100.00000;2.82463;2
 50.44300;12.52167; 5.485168e-004;50.00000;100.00000;2.82463;2
 50.44400;12.65500; 4.076514e-004;50.00000;100.00000;2.82464;2
 50.44400;12.78833; 2.559898e-004;50.00000;100.00000;2.82464;2
 50.44400;12.92167; 1.368272e-004;50.00000;100.00000;2.82464;2
 50.44400;13.05500; 2.127557e-005;50.00000;100.00000;2.82464;2
 50.44300;13.18833;-1.050727e-004;50.00000;100.00000;2.82463;2
 50.44300;13.32167;-2.350684e-004;50.00000;100.00000;2.82463;2
 50.44300;13.45500;-3.397871e-004;50.00000;100.00000;2.82463;2
 50.44400;13.58833;-4.048211e-004;50.00000;100.00000;2.82464;2
 50.44400;13.72167;-4.950958e-004;50.00000;100.00000;2.82464;2
 50.44400;13.85500;-5.673156e-004;50.00000;100.00000;2.82464;2
 50.44300;13.98833;-6.214445e-004;50.00000;100.00000;2.82463;2
 50.44400;14.12167;-6.467574e-004;50.00000;100.00000;2.82464;2
 50.44400;14.25500;-6.720343e-004;50.00000;100.00000;2.82464;2
 50.44400;14.38833;-6.973112e-004;50.00000;100.00000;2.82464;2
 50.44500;14.52167;-7.551229e-004;50.00000;100.00000;2.82464;2
 50.44600;14.65500;-7.912685e-004;50.00000;100.00000;2.82464;2
 50.44600;14.78833;-8.273783e-004;50.00000;100.00000;2.82464;2
 50.44700;14.92167;-7.985263e-004;50.00000;100.00000;2.82464;2
 50.44900;15.05500;-7.949869e-004;50.00000;100.00000;2.82465;2
 50.44900;15.18833;-7.588772e-004;50.00000;100.00000;2.82465;2
 50.45000;15.32167;-7.661350e-004;50.00000;100.00000;2.82465;2
 50.45000;15.45500;-7.661350e-004;50.00000;100.00000;2.82465;2
 50.45000;15.58833;-7.589131e-004;50.00000;100.00000;2.82465;2
 50.45200;15.72167;-7.734286e-004;50.00000;100.00000;2.82465;2
 50.45300;15.85500;-7.842974e-004;50.00000;100.00000;2.82466;2
 50.45300;15.98833;-7.879083e-004;50.00000;100.00000;2.82466;2
 50.45200;16.12167;-8.456480e-004;50.00000;100.00000;2.82465;2
 50.45100;16.25500;-9.178316e-004;50.00000;100.00000;2.82465;2
 50.45000;16.38833;-1.040569e-003;50.00000;100.00000;2.82465;2
 50.44700;16.52167;-1.141569e-003;50.00000;100.00000;2.82464;2
 50.44600;16.65500;-1.210143e-003;50.00000;100.00000;2.82464;2
 50.44600;16.78833;-1.278751e-003;50.00000;100.00000;2.82464;2
 50.44300;16.92167;-1.343643e-003;50.00000;100.00000;2.82463;2
 50.44400;17.05500;-1.350900e-003;50.00000;100.00000;2.82464;2
 50.44400;17.18833;-1.405065e-003;50.00000;100.00000;2.82464;2
 50.44200;17.32167;-1.444715e-003;50.00000;100.00000;2.82463;2
 50.44200;17.45500;-1.480825e-003;50.00000;100.00000;2.82463;2
 50.44100;17.58833;-1.484401e-003;50.00000;100.00000;2.82463;2
 50.44100;17.72167;-1.495234e-003;50.00000;100.00000;2.82463;2
 50.44300;17.85500;-1.451972e-003;50.00000;100.00000;2.82463;2
 50.44100;17.98833;-1.462735e-003;50.00000;100.00000;2.82463;2
 50.44100;18.12167;-1.469957e-003;50.00000;100.00000;2.82463;2
 50.44000;18.25500;-1.498810e-003;50.00000;100.00000;2.82463;2
 50.43800;18.38833;-1.556515e-003;50.00000;100.00000;2.82462;2
 50.43800;18.52167;-1.570959e-003;50.00000;100.00000;2.82462;2
 50.43700;18.65667;-1.560091e-003;50.00000;100.00000;2.82462;3
 50.46900;18.79000;-3.768369e-004;50.00000;100.00000;2.82469;3
 50.57800;18.92333; 3.630610e-003;50.00000;100.00000;2.82493;3
 50.77200;19.05667; 1.112469e-002;50.00000;100.00000;2.82536;3
 51.05400;19.19000; 2.207691e-002;50.00000;100.00000;2.82599;3
 51.40300;19.32333; 3.613772e-002;50.00000;100.00000;2.82675;3
 51.81100;19.45667; 5.250588e-002;50.00000;100.00000;2.82765;3
 52.26300;19.59000; 7.054018e-002;50.00000;100.00000;2.82864;3
 52.74900;19.72333; 8.952093e-002;50.00000;100.00000;2.82969;3
 53.26600;19.85667;       0.10884;50.00000;100.00000;2.83081;3
 53.80200;19.99000;       0.12806;50.00000;100.00000;2.83196;3
 54.36000;20.12333;       0.14681;50.00000;100.00000;2.83315;3
 54.92900;20.25667;       0.16478;50.00000;100.00000;2.83436;3
 55.51400;20.39000;       0.18197;50.00000;100.00000;2.83559;3
 56.10900;20.52333;       0.19819;50.00000;100.00000;2.83684;3
 56.71300;20.65667;       0.21343;50.00000;100.00000;2.83810;3
 57.32400;20.79000;       0.22762;50.00000;100.00000;2.83936;3
 57.94400;20.92333;       0.24089;50.00000;100.00000;2.84063;3
 58.57100;21.05667;       0.25321;50.00000;100.00000;2.84191;3
 59.20100;21.19000;       0.26470;50.00000;100.00000;2.84319;3
 59.83700;21.32333;       0.27537;50.00000;100.00000;2.84447;3
 60.47500;21.45667;       0.28525;50.00000;100.00000;2.84574;3
 61.11700;21.59000;       0.29439;50.00000;100.00000;2.84701;3
 61.76200;21.72333;       0.30281;50.00000;100.00000;2.84827;3
 62.41100;21.85667;       0.31053;50.00000;100.00000;2.84954;3
 63.06300;21.99000;       0.31758;50.00000;100.00000;2.85080;3
 63.71500;22.12333;       0.32405;50.00000;100.00000;2.85205;3
 64.37000;22.25667;       0.32996;50.00000;100.00000;2.85329;3
 65.02400;22.39000;       0.33533;50.00000;100.00000;2.85453;3
 65.68100;22.52333;       0.34021;50.00000;100.00000;2.85576;3
 66.34100;22.65667;       0.34466;50.00000;100.00000;2.85698;3
 67.00100;22.79000;       0.34874;50.00000;100.00000;2.85819;3
 67.66300;22.92333;       0.35241;50.00000;100.00000;2.85940;3
 68.32300;23.05667;       0.35576;50.00000;100.00000;2.86059;3
 68.98600;23.19000;       0.35874;50.00000;100.00000;2.86178;3
 69.65000;23.32333;       0.36146;50.00000;100.00000;2.86296;3
 70.31300;23.45667;       0.36391;50.00000;100.00000;2.86413;3
 70.97700;23.59000;       0.36607;50.00000;100.00000;2.86528;3
 71.64000;23.72333;       0.36802;50.00000;100.00000;2.86643;3
 72.30400;23.85667;       0.36984;50.00000;100.00000;2.86757;3
 72.97100;23.99000;       0.37142;50.00000;100.00000;2.86870;3
 73.63600;24.12333;       0.37286;50.00000;100.00000;2.86981;3
 74.30200;24.25667;       0.37414;50.00000;100.00000;2.87092;3
 74.96700;24.39000;       0.37534;50.00000;100.00000;2.87202;3
 75.63400;24.52333;       0.37638;50.00000;100.00000;2.87310;3
 76.30100;24.65667;       0.37729;50.00000;100.00000;2.87418;3
 76.96700;24.79000;       0.37815;50.00000;100.00000;2.87525;3
 77.63500;24.92333;       0.37893;50.00000;100.00000;2.87630;3
 78.30100;25.05667;       0.37953;50.00000;100.00000;2.87735;3
 78.96700;25.19000;       0.38014;50.00000;100.00000;2.87838;3
 79.63500;25.32333;       0.38066;50.00000;100.00000;2.87940;3
 80.30300;25.45667;       0.38113;50.00000;100.00000;2.88042;3
 80.97000;25.59000;       0.38154;50.00000;100.00000;2.88142;3
 81.63800;25.72333;       0.38188;50.00000;100.00000;2.88241;3
 82.30400;25.85667;       0.38220;50.00000;100.00000;2.88339;3
 82.97500;25.99000;       0.38243;50.00000;100.00000;2.88436;3
 83.64200;26.12333;       0.38265;50.00000;100.00000;2.88532;3
 84.30800;26.25667;       0.38279;50.00000;100.00000;2.88626;3
 84.97600;26.39000;       0.38293;50.00000;100.00000;2.88720;3
 85.64300;26.52333;       0.38305;50.00000;100.00000;2.88812;3
 86.31200;26.65667;       0.38316;50.00000;100.00000;2.88904;3
 86.97800;26.79000;       0.38319;50.00000;100.00000;2.88994;3
 87.64700;26.92333;       0.38329;50.00000;100.00000;2.89083;3
 88.31700;27.05667;       0.38330;50.00000;100.00000;2.89172;3
 88.98200;27.19000;       0.38332;50.00000;100.00000;2.89258;3
 89.65200;27.32333;       0.38333;50.00000;100.00000;2.89345;3
 90.32000;27.45667;       0.38332;50.00000;100.00000;2.89429;3
 90.98700;27.59000;       0.38329;50.00000;100.00000;2.89513;3
 91.65500;27.72333;       0.38325;50.00000;100.00000;2.89596;3
 92.32200;27.85667;       0.38316;50.00000;100.00000;2.89677;3
 92.98900;27.99000;       0.38309;50.00000;100.00000;2.89757;3
 93.65900;28.12333;       0.38303;50.00000;100.00000;2.89837;3
 94.32700;28.25667;       0.38290;50.00000;100.00000;2.89915;3
 94.99600;28.39000;       0.38286;50.00000;100.00000;2.89992;3
 95.66500;28.52333;       0.38278;50.00000;100.00000;2.90068;3
 96.33300;28.65667;       0.38273;50.00000;100.00000;2.90143;3
 97.00100;28.79000;       0.38267;50.00000;100.00000;2.90217;3
 97.67200;28.92333;       0.38261;50.00000;100.00000;2.90290;3
 98.33800;29.05667;       0.38245;50.00000;100.00000;2.90361;3
 99.00600;29.19000;       0.38235;50.00000;100.00000;2.90431;3
 99.67300;29.32333;       0.38217;50.00000;100.00000;2.90500;3
100.34000;29.45667;       0.38202;50.00000;100.00000;2.90568;3
101.00800;29.59000;       0.38185;50.00000;100.00000;2.90635;3
101.67700;29.72333;       0.38170;50.00000;100.00000;2.90701;3
102.34500;29.85667;       0.38161;50.00000;100.00000;2.90766;3
103.01400;29.99000;       0.38143;50.00000;100.00000;2.90830;3
103.68200;30.12333;       0.38131;50.00000;100.00000;2.90892;3
104.35100;30.25667;       0.38114;50.00000;100.00000;2.90953;3
105.02000;30.39000;       0.38099;50.00000;100.00000;2.91014;3
105.68800;30.52333;       0.38083;50.00000;100.00000;2.91073;3
106.35500;30.65667;       0.38066;50.00000;100.00000;2.91131;3
107.02300;30.79000;       0.38051;50.00000;100.00000;2.91187;3
107.69200;30.92333;       0.38035;50.00000;100.00000;2.91243;3
108.35900;31.05667;       0.38019;50.00000;100.00000;2.91298;3
109.02800;31.19000;       0.38003;50.00000;100.00000;2.91351;3
109.69600;31.32333;       0.37989;50.00000;100.00000;2.91404;3
110.36500;31.45667;       0.37973;50.00000;100.00000;2.91455;3
111.03200;31.59000;       0.37960;50.00000;100.00000;2.91505;3
111.70000;31.72333;       0.37937;50.00000;100.00000;2.91554;3
112.36600;31.85667;       0.37919;50.00000;100.00000;2.91601;3
113.03500;31.99000;       0.37898;50.00000;100.00000;2.91648;3
113.70300;32.12333;       0.37882;50.00000;100.00000;2.91693;3
114.37200;32.25667;       0.37863;50.00000;100.00000;2.91738;3
115.03900;32.39000;       0.37845;50.00000;100.00000;2.91781;3
115.70600;32.52333;       0.37832;50.00000;100.00000;2.91823;3
116.37600;32.65667;       0.37816;50.00000;100.00000;2.91864;3
117.04500;32.79000;       0.37799;50.00000;100.00000;2.91904;3
117.71100;32.92333;       0.37778;50.00000;100.00000;2.91943;3
118.37900;33.05667;       0.37762;50.00000;100.00000;2.91980;3
119.04700;33.19000;       0.37743;50.00000;100.00000;2.92016;3
119.71500;33.32333;       0.37727;50.00000;100.00000;2.92052;3
120.38400;33.45667;       0.37711;50.00000;100.00000;2.92086;3
121.05200;33.59000;       0.37697;50.00000;100.00000;2.92119;3
121.71900;33.72333;       0.37680;50.00000;100.00000;2.92151;3
122.38600;33.85667;       0.37662;50.00000;100.00000;2.92181;3
123.05600;33.99000;       0.37641;50.00000;100.00000;2.92211;3
123.72400;34.12333;       0.37625;50.00000;100.00000;2.92239;3
124.38900;34.25667;       0.37605;50.00000;100.00000;2.92266;3
125.05700;34.39000;       0.37587;50.00000;100.00000;2.92293;3
125.72600;34.52333;       0.37572;50.00000;100.00000;2.92318;3
126.39400;34.65667;       0.37558;50.00000;100.00000;2.92341;3
127.06300;34.79000;       0.37545;50.00000;100.00000;2.92364;3
127.73200;34.92333;       0.37529;50.00000;100.00000;2.92386;3
128.39999;35.05667;       0.37515;50.00000;100.00000;2.92406;3
129.06700;35.19000;       0.37500;50.00000;100.00000;2.92425;3
129.73599;35.32333;       0.37482;50.00000;100.00000;2.92444;3
130.40300;35.45667;       0.37464;50.00000;100.00000;2.92460;3
131.07100;35.59000;       0.37446;50.00000;100.00000;2.92476;3
131.73801;35.72333;       0.37430;50.00000;100.00000;2.92491;3
132.40800;35.85667;       0.37418;50.00000;100.00000;2.92505;3
133.07600;35.99000;       0.37403;50.00000;100.00000;2.92517;3
133.74300;36.12333;       0.37389;50.00000;100.00000;2.92528;3
134.41200;36.25667;       0.37376;50.00000;100.00000;2.92538;3
135.07899;36.39000;       0.37356;50.00000;100.00000;2.92547;3
135.74600;36.52333;       0.37341;50.00000;100.00000;2.92555;3
136.41600;36.65667;       0.37322;50.00000;100.00000;2.92562;3
137.08400;36.79000;       0.37312;50.00000;100.00000;2.92567;3
137.75200;36.92333;       0.37298;50.00000;100.00000;2.92572;3
138.42000;37.05667;       0.37283;50.00000;100.00000;2.92575;3
139.08701;37.19000;       0.37269;50.00000;100.00000;2.92577;3
139.75500;37.32333;       0.37254;50.00000;100.00000;2.92578;3
140.42200;37.45667;       0.37239;50.00000;100.00000;2.92578;3
141.09200;37.59000;       0.37229;50.00000;100.00000;2.92576;3
141.75900;37.72333;       0.37216;50.00000;100.00000;2.92574;3
142.42700;37.85667;       0.37204;50.00000;100.00000;2.92570;3
143.09599;37.99000;       0.37192;50.00000;100.00000;2.92565;3
143.76401;38.12333;       0.37182;50.00000;100.00000;2.92559;3
144.43100;38.25667;       0.37171;50.00000;100.00000;2.92552;3
145.09900;38.39000;       0.37161;50.00000;100.00000;2.92544;3
145.76801;38.52333;       0.37151;50.00000;100.00000;2.92535;3
146.43500;38.65667;       0.37139;50.00000;100.00000;2.92524;3
147.10300;38.79000;       0.37126;50.00000;100.00000;2.92512;3
147.77000;38.92333;       0.37116;50.00000;100.00000;2.92500;3
148.43900;39.05667;       0.37109;50.00000;100.00000;2.92486;3
149.10500;39.19000;       0.37100;50.00000;100.00000;2.92470;3
149.77299;39.32333;       0.37090;50.00000;100.00000;2.92454;3
150.44000;39.45667;       0.37078;50.00000;100.00000;2.92437;3
151.10800;39.59000;       0.37069;50.00000;100.00000;2.92418;3
151.77499;39.72333;       0.37057;50.00000;100.00000;2.92399;3
152.44200;39.85667;       0.37048;50.00000;100.00000;2.92378;3
153.11099;39.99000;       0.37046;50.00000;100.00000;2.92356;3
153.77800;40.12333;       0.37039;50.00000;100.00000;2.92333;3
154.44600;40.25667;       0.37032;50.00000;100.00000;2.92309;3
155.11400;40.39000;       0.37029;50.00000;100.00000;2.92283;3
155.78300;40.52333;       0.37023;50.00000;100.00000;2.92256;3
156.45200;40.65667;       0.37020;50.00000;100.00000;2.92229;3
157.12000;40.79000;       0.37016;50.00000;100.00000;2.92200;3
157.78799;40.92333;       0.37008;50.00000;100.00000;2.92170;3
158.45599;41.05667;       0.37002;50.00000;100.00000;2.92139;3
159.12199;41.19000;       0.36989;50.00000;100.00000;2.92107;3
159.78799;41.32333;       0.36976;50.00000;100.00000;2.92073;3
160.45500;41.45667;       0.36972;50.00000;100.00000;2.92039;3
161.12399;41.59000;       0.36967;50.00000;100.00000;2.92003;3
161.78999;41.72333;       0.36955;50.00000;100.00000;2.91966;3
162.46001;41.85667;       0.36945;50.00000;100.00000;2.91928;3
163.12601;41.99000;       0.36935;50.00000;100.00000;2.91889;3
163.79500;42.12333;       0.36927;50.00000;100.00000;2.91849;3
164.46201;42.25667;       0.36923;50.00000;100.00000;2.91808;3
165.13000;42.39000;       0.36910;50.00000;100.00000;2.91765;3
165.79800;42.52333;       0.36895;50.00000;100.00000;2.91722;3
166.46400;42.65667;       0.36886;50.00000;100.00000;2.91677;3
167.13200;42.79000;       0.36872;50.00000;100.00000;2.91631;3
167.80000;42.92333;       0.36857;50.00000;100.00000;2.91584;3
168.46700;43.05667;       0.36846;50.00000;100.00000;2.91536;3
169.13499;43.19000;       0.36836;50.00000;100.00000;2.91487;3
169.80400;43.32333;       0.36823;50.00000;100.00000;2.91436;3
170.47099;43.45667;       0.36812;50.00000;100.00000;2.91385;3
171.14000;43.59000;       0.36800;50.00000;100.00000;2.91332;3
171.80701;43.72333;       0.36787;50.00000;100.00000;2.91278;3
172.47501;43.85667;       0.36776;50.00000;100.00000;2.91223;3
173.14200;43.99000;       0.36766;50.00000;100.00000;2.91167;3
173.80800;44.12333;       0.36753;50.00000;100.00000;2.91110;3
174.47800;44.25667;       0.36744;50.00000;100.00000;2.91052;3
175.14500;44.39000;       0.36727;50.00000;100.00000;2.90992;3
175.81300;44.52333;       0.36715;50.00000;100.00000;2.90932;3
176.48000;44.65667;       0.36702;50.00000;100.00000;2.90870;3
177.14799;44.79000;       0.36690;50.00000;100.00000;2.90807;3
177.81400;44.92333;       0.36681;50.00000;100.00000;2.90743;3
178.48300;45.05667;       0.36674;50.00000;100.00000;2.90678;3
179.14900;45.19000;       0.36660;50.00000;100.00000;2.90612;3
179.81900;45.32333;       0.36653;50.00000;100.00000;2.90544;3
180.48599;45.45667;       0.36644;50.00000;100.00000;2.90476;3
181.15199;45.59000;       0.36635;50.00000;100.00000;2.90407;3
181.82100;45.72333;       0.36627;50.00000;100.00000;2.90336;3
182.48900;45.85667;       0.36620;50.00000;100.00000;2.90264;3
183.15700;45.99000;       0.36613;50.00000;100.00000;2.90191;3
183.82300;46.12333;       0.36606;50.00000;100.00000;2.90117;3
184.49300;46.25667;       0.36598;50.00000;100.00000;2.90042;3
185.15900;46.39000;       0.36589;50.00000;100.00000;2.89966;3
185.82800;46.52333;       0.36586;50.00000;100.00000;2.89888;3
186.49400;46.65667;       0.36580;50.00000;100.00000;2.89810;3
187.16200;46.79000;       0.36576;50.00000;100.00000;2.89730;3
187.82800;46.92333;       0.36568;50.00000;100.00000;2.89650;3
188.49699;47.05667;       0.36561;50.00000;100.00000;2.89568;3
189.16400;47.19000;       0.36551;50.00000;100.00000;2.89485;3
189.83099;47.32333;       0.36542;50.00000;100.00000;2.89401;3
190.49899;47.45667;       0.36534;50.00000;100.00000;2.89316;3
191.16600;47.59000;       0.36525;50.00000;100.00000;2.89229;3
191.83299;47.72333;       0.36513;50.00000;100.00000;2.89142;3
192.49899;47.85667;       0.36506;50.00000;100.00000;2.89054;3
193.16800;47.99000;       0.36493;50.00000;100.00000;2.88964;3
193.83600;48.12333;       0.36486;50.00000;100.00000;2.88873;3
194.50301;48.25667;       0.36479;50.00000;100.00000;2.88782;3
195.17000;48.39000;       0.36468;50.00000;100.00000;2.88689;3
195.83800;48.52333;       0.36458;50.00000;100.00000;2.88595;3
196.50900;48.65833;       0.36430;50.00000;100.00000;2.88499;4
197.08200;48.79167;       0.36008;50.00000;100.00000;2.88417;4
197.54201;48.92500;       0.35044;50.00000;100.00000;2.88350;4
197.91499;49.05833;       0.33623;50.00000;100.00000;2.88295;4
198.22099;49.19167;       0.31850;50.00000;100.00000;2.88250;4
198.47600;49.32500;       0.29842;50.00000;100.00000;2.88213;4
198.68900;49.45833;       0.27699;50.00000;100.00000;2.88181;4
198.87000;49.59167;       0.25511;50.00000;100.00000;2.88154;4
199.02100;49.72500;       0.23340;50.00000;100.00000;2.88132;4
199.14999;49.85833;       0.21233;50.00000;100.00000;2.88112;4
199.25800;49.99167;       0.19215;50.00000;100.00000;2.88096;4
199.35201;50.12500;       0.17304;50.00000;100.00000;2.88082;4
199.43500;50.25833;       0.15521;50.00000;100.00000;2.88070;4
199.50301;50.39167;       0.13866;50.00000;100.00000;2.88059;4
199.56400;50.52500;       0.12338;50.00000;100.00000;2.88050;4
199.61700;50.65833;       0.10932;50.00000;100.00000;2.88042;4
199.66000;50.79167; 9.651333e-002;50.00000;100.00000;2.88036;4
199.70000;50.92500; 8.480315e-002;50.00000;100.00000;2.88030;4
199.73300;51.05833; 7.421858e-002;50.00000;100.00000;2.88025;4
199.76199;51.19167; 6.460753e-002;50.00000;100.00000;2.88020;4
199.78999;51.32500; 5.594881e-002;50.00000;100.00000;2.88016;4
199.81100;51.45833; 4.811153e-002;50.00000;100.00000;2.88013;4
199.83200;51.59167; 4.106736e-002;50.00000;100.00000;2.88010;4
199.84900;51.72500; 3.477390e-002;50.00000;100.00000;2.88007;4
199.86400;51.85833; 2.912492e-002;50.00000;100.00000;2.88005;4
199.87900;51.99167; 2.404251e-002;50.00000;100.00000;2.88003;4
199.89200;52.12500; 1.954442e-002;50.00000;100.00000;2.88001;4
199.90199;52.25833; 1.550676e-002;50.00000;100.00000;2.87999;4
199.91200;52.39167; 1.190821e-002;50.00000;100.00000;2.87998;4
199.91901;52.52500; 8.752428e-003;50.00000;100.00000;2.87996;4
199.92900;52.65833; 5.932975e-003;50.00000;100.00000;2.87995;4
199.93600;52.79167; 3.432344e-003;50.00000;100.00000;2.87994;4
199.94200;52.92500; 1.186729e-003;50.00000;100.00000;2.87993;4
199.94800;53.05833;-7.578582e-004;50.00000;100.00000;2.87992;4
199.95399;53.19167;-2.518291e-003;50.00000;100.00000;2.87991;4
199.96100;53.32500;-4.073354e-003;50.00000;100.00000;2.87990;4
199.96300;53.45833;-5.454692e-003;50.00000;100.00000;2.87990;4
199.96800;53.59167;-6.662607e-003;50.00000;100.00000;2.87989;4
199.97200;53.72500;-7.718195e-003;50.00000;100.00000;2.87988;4
199.97701;53.85833;-8.642784e-003;50.00000;100.00000;2.87988;4
199.97900;53.99167;-9.429127e-003;50.00000;100.00000;2.87987;4
199.98100;54.12500;-1.017297e-002;50.00000;100.00000;2.87987;4
199.98300;54.25833;-1.079286e-002;50.00000;100.00000;2.87987;4
199.98700;54.39167;-1.131012e-002;50.00000;100.00000;2.87986;4
199.99100;54.52500;-1.176717e-002;50.00000;100.00000;2.87986;4
199.99300;54.65833;-1.218164e-002;50.00000;100.00000;2.87985;4
199.99500;54.79167;-1.248277e-002;50.00000;100.00000;2.87985;4
199.99699;54.92500;-1.274849e-002;50.00000;100.00000;2.87985;4
200.00000;55.05833;-1.302133e-002;50.00000;100.00000;2.87984;4
200.00101;55.19167;-1.321617e-002;50.00000;100.00000;2.87984;4
200.00301;55.32500;-1.345002e-002;50.00000;100.00000;2.87984;4
200.00400;55.45833;-1.366611e-002;50.00000;100.00000;2.87984;4
200.00400;55.59167;-1.380778e-002;50.00000;100.00000;2.87984;4
200.00700;55.72500;-1.395666e-002;50.00000;100.00000;2.87983;4
200.00700;55.85833;-1.407708e-002;50.00000;100.00000;2.87983;4
200.00999;55.99167;-1.413742e-002;50.00000;100.00000;2.87983;4
200.00999;56.12500;-1.414451e-002;50.00000;100.00000;2.87983;4
200.01199;56.25833;-1.411272e-002;50.00000;100.00000;2.87982;4
200.01700;56.39167;-1.411293e-002;50.00000;100.00000;2.87982;4
200.01601;56.52500;-1.407747e-002;50.00000;100.00000;2.87982;4
200.01801;56.65833;-1.413777e-002;50.00000;100.00000;2.87981;4
200.01500;56.79167;-1.414472e-002;50.00000;100.00000;2.87982;4
200.01700;56.92500;-1.419439e-002;50.00000;100.00000;2.87982;4
200.01801;57.05833;-1.415548e-002;50.00000;100.00000;2.87981;4
200.01900;57.19167;-1.407760e-002;50.00000;100.00000;2.87981;4
200.02100;57.32500;-1.401748e-002;50.00000;100.00000;2.87981;4
200.02200;57.45833;-1.399273e-002;50.00000;100.00000;2.87981;4
200.02400;57.59167;-1.391843e-002;50.00000;100.00000;2.87981;4
200.02600;57.72500;-1.378393e-002;50.00000;100.00000;2.87980;4
200.02699;57.85833;-1.366001e-002;50.00000;100.00000;2.87980;4
200.02901;57.99167;-1.359989e-002;50.00000;100.00000;2.87980;4
200.02901;58.12500;-1.355738e-002;50.00000;100.00000;2.87980;4
200.02699;58.25833;-1.359980e-002;50.00000;100.00000;2.87980;4
200.02800;58.39167;-1.361755e-002;50.00000;100.00000;2.87980;4
200.02699;58.52500;-1.362105e-002;50.00000;100.00000;2.87980;4
200.02800;58.65833;-1.354672e-002;50.00000;100.00000;2.87980;4
200.02699;58.79167;-1.352896e-002;50.00000;100.00000;2.87980;4
200.02800;58.92500;-1.346171e-002;50.00000;100.00000;2.87980;4
200.02901;59.05833;-1.335550e-002;50.00000;100.00000;2.87980;4
200.03000;59.19167;-1.330596e-002;50.00000;100.00000;2.87980;4
200.03101;59.32500;-1.318204e-002;50.00000;100.00000;2.87979;4
200.03300;59.45833;-1.301920e-002;50.00000;100.00000;2.87979;4
200.03400;59.59167;-1.293070e-002;50.00000;100.00000;2.87979;4
200.03400;59.72500;-1.281382e-002;50.00000;100.00000;2.87979;4
200.03400;59.85833;-1.276423e-002;50.00000;100.00000;2.87979;4
200.03500;59.99167;-1.276427e-002;50.00000;100.00000;2.87979;4
200.03400;60.12500;-1.270402e-002;50.00000;100.00000;2.87979;4
200.03400;60.25833;-1.270402e-002;50.00000;100.00000;2.87979;4
200.03300;60.39167;-1.267918e-002;50.00000;100.00000;2.87979;4
200.03400;60.52500;-1.260131e-002;50.00000;100.00000;2.87979;4
200.03600;60.65833;-1.249159e-002;50.00000;100.00000;2.87979;4
200.03600;60.79167;-1.241367e-002;50.00000;100.00000;2.87979;4
200.03700;60.92500;-1.231454e-002;50.00000;100.00000;2.87979;4
200.03600;61.05833;-1.226492e-002;50.00000;100.00000;2.87979;4
200.03700;61.19167;-1.217641e-002;50.00000;100.00000;2.87979;4
200.03700;61.32500;-1.211974e-002;50.00000;100.00000;2.87979;4
200.03700;61.45833;-1.206307e-002;50.00000;100.00000;2.87979;4
200.03900;61.59167;-1.198170e-002;50.00000;100.00000;2.87978;4
200.03900;61.72500;-1.191794e-002;50.00000;100.00000;2.87978;4
200.03900;61.85833;-1.185065e-002;50.00000;100.00000;2.87978;4
200.03999;61.99167;-1.174798e-002;50.00000;100.00000;2.87978;4
200.03900;62.12500;-1.168772e-002;50.00000;100.00000;2.87978;4
200.03999;62.25833;-1.160630e-002;50.00000;100.00000;2.87978;4
200.03999;62.39167;-1.164526e-002;50.00000;100.00000;2.87978;4
200.03900;62.52500;-1.162043e-002;50.00000;100.00000;2.87978;4
200.03900;62.65833;-1.154251e-002;50.00000;100.00000;2.87978;4
200.03799;62.79167;-1.150350e-002;50.00000;100.00000;2.87978;4
200.04100;62.92500;-1.137966e-002;50.00000;100.00000;2.87978;4
200.04100;63.05833;-1.130883e-002;50.00000;100.00000;2.87978;4
200.04201;63.19167;-1.121324e-002;50.00000;100.00000;2.87978;4
200.04201;63.32500;-1.110699e-002;50.00000;100.00000;2.87978;4
200.04300;63.45833;-1.106453e-002;50.00000;100.00000;2.87978;4
200.04201;63.59167;-1.099011e-002;50.00000;100.00000;2.87978;4
200.04201;63.72500;-1.094052e-002;50.00000;100.00000;2.87978;4
200.04201;63.85833;-1.089448e-002;50.00000;100.00000;2.87978;4
200.04300;63.99167;-1.084493e-002;50.00000;100.00000;2.87978;4
200.04201;64.12500;-1.083426e-002;50.00000;100.00000;2.87978;4
200.04300;64.25833;-1.076701e-002;50.00000;100.00000;2.87978;4
200.04201;64.39167;-1.068196e-002;50.00000;100.00000;2.87978;4
200.04201;64.52500;-1.063946e-002;50.00000;100.00000;2.87978;4
200.04300;64.65833;-1.055096e-002;50.00000;100.00000;2.87978;4
200.04500;64.79167;-1.045895e-002;50.00000;100.00000;2.87977;4
200.04500;64.92500;-1.041645e-002;50.00000;100.00000;2.87977;4
200.04300;65.05833;-1.038449e-002;50.00000;100.00000;2.87978;4
200.04201;65.19167;-1.031715e-002;50.00000;100.00000;2.87978;4
200.04401;65.32500;-1.027474e-002;50.00000;100.00000;2.87977;4
200.04401;65.45833;-1.024286e-002;50.00000;100.00000;2.87977;4
200.04500;65.59167;-1.018977e-002;50.00000;100.00000;2.87977;4
200.04500;65.72500;-1.011539e-002;50.00000;100.00000;2.87977;4
200.04500;65.85833;-1.005518e-002;50.00000;100.00000;2.87977;4
200.04601;65.99167;-9.956049e-003;50.00000;100.00000;2.87977;4
200.04601;66.12500;-9.878128e-003;50.00000;100.00000;2.87977;4
200.04900;66.25833;-9.849916e-003;50.00000;100.00000;2.87977;4
200.04700;66.39167;-9.856920e-003;50.00000;100.00000;2.87977;4
200.04700;66.52500;-9.846294e-003;50.00000;100.00000;2.87977;4
200.04601;66.65833;-9.849794e-003;50.00000;100.00000;2.87977;4
200.04500;66.79167;-9.828502e-003;50.00000;100.00000;2.87977;4
200.04601;66.92500;-9.732913e-003;50.00000;100.00000;2.87977;4
200.04601;67.05833;-9.704578e-003;50.00000;100.00000;2.87977;4
200.04601;67.19167;-9.598322e-003;50.00000;100.00000;2.87977;4
200.04601;67.32500;-9.545194e-003;50.00000;100.00000;2.87977;4
200.04601;67.45833;-9.516860e-003;50.00000;100.00000;2.87977;4
200.04500;67.59167;-9.502652e-003;50.00000;100.00000;2.87977;4
200.04401;67.72500;-9.488445e-003;50.00000;100.00000;2.87977;4
200.04401;67.85833;-9.438859e-003;50.00000;100.00000;2.87977;4
200.04601;67.99167;-9.361018e-003;50.00000;100.00000;2.87977;4
200.04401;68.12500;-9.332604e-003;50.00000;100.00000;2.87977;4
200.04601;68.25833;-9.254763e-003;50.00000;100.00000;2.87977;4
200.04601;68.39167;-9.152049e-003;50.00000;100.00000;2.87977;4
200.04601;68.52500;-9.077670e-003;50.00000;100.00000;2.87977;4
200.04800;68.65833;-9.031708e-003;50.00000;100.00000;2.87977;4
200.04700;68.79167;-8.971456e-003;50.00000;100.00000;2.87977;4
200.04700;68.92500;-8.928954e-003;50.00000;100.00000;2.87977;4
200.04700;69.05833;-8.911244e-003;50.00000;100.00000;2.87977;4
200.04601;69.19167;-8.918287e-003;50.00000;100.00000;2.87977;4
200.04700;69.32500;-8.882909e-003;50.00000;100.00000;2.87977;4
200.04700;69.45833;-8.836865e-003;50.00000;100.00000;2.87977;4
200.04601;69.59167;-8.815573e-003;50.00000;100.00000;2.87977;4
200.04800;69.72500;-8.748359e-003;50.00000;100.00000;2.87977;4
200.04800;69.85833;-8.663354e-003;50.00000;100.00000;2.87977;4
200.04700;69.99167;-8.642063e-003;50.00000;100.00000;2.87977;4
200.04601;70.12500;-8.595978e-003;50.00000;100.00000;2.87977;4
200.04401;70.25833;-8.613608e-003;50.00000;100.00000;2.87977;4
200.04500;70.39167;-8.599480e-003;50.00000;100.00000;2.87977;4
200.04300;70.52500;-8.578148e-003;50.00000;100.00000;2.87978;4
200.04500;70.65833;-8.535726e-003;50.00000;100.00000;2.87977;4
200.04601;70.79167;-8.489723e-003;50.00000;100.00000;2.87977;4
200.04700;70.92500;-8.436636e-003;50.00000;100.00000;2.87977;4
200.04601;71.05833;-8.379925e-003;50.00000;100.00000;2.87977;4
200.04700;71.19167;-8.294962e-003;50.00000;100.00000;2.87977;4
200.04601;71.32500;-8.284295e-003;50.00000;100.00000;2.87977;4
200.04601;71.45833;-8.213458e-003;50.00000;100.00000;2.87977;4
200.04700;71.59167;-8.185164e-003;50.00000;100.00000;2.87977;4
200.04700;71.72500;-8.121410e-003;50.00000;100.00000;2.87977;4
200.04700;71.85833;-8.100159e-003;50.00000;100.00000;2.87977;4
200.04800;71.99167;-8.050613e-003;50.00000;100.00000;2.87977;4
200.04601;72.12500;-8.029282e-003;50.00000;100.00000;2.87977;4
200.04601;72.25833;-8.057617e-003;50.00000;100.00000;2.87977;4
200.04401;72.39167;-8.064621e-003;50.00000;100.00000;2.87977;4
200.04601;72.52500;-8.032824e-003;50.00000;100.00000;2.87977;4
200.04800;72.65833;-7.926649e-003;50.00000;100.00000;2.87977;4
200.04700;72.79167;-7.877023e-003;50.00000;100.00000;2.87977;4
200.04700;72.92500;-7.869939e-003;50.00000;100.00000;2.87977;4
200.04601;73.05833;-7.841564e-003;50.00000;100.00000;2.87977;4
200.04700;73.19167;-7.770767e-003;50.00000;100.00000;2.87977;4
200.04700;73.32500;-7.731807e-003;50.00000;100.00000;2.87977;4
200.04700;73.45833;-7.632635e-003;50.00000;100.00000;2.87977;4
200.04900;73.59167;-7.572502e-003;50.00000;100.00000;2.87977;4
200.04900;73.72500;-7.522916e-003;50.00000;100.00000;2.87977;4
200.04800;73.85833;-7.491000e-003;50.00000;100.00000;2.87977;4
200.04900;73.99167;-7.455620e-003;50.00000;100.00000;2.87977;4
200.04800;74.12500;-7.448498e-003;50.00000;100.00000;2.87977;4
200.04700;74.25833;-7.455542e-003;50.00000;100.00000;2.87977;4
200.04800;74.39167;-7.476833e-003;50.00000;100.00000;2.87977;4
200.04700;74.52500;-7.455542e-003;50.00000;100.00000;2.87977;4
200.04601;74.65833;-7.469669e-003;50.00000;100.00000;2.87977;4
200.04700;74.79167;-7.434291e-003;50.00000;100.00000;2.87977;4
200.04601;74.92500;-7.409457e-003;50.00000;100.00000;2.87977;4
200.04700;75.05833;-7.363454e-003;50.00000;100.00000;2.87977;4
200.04700;75.19167;-7.313868e-003;50.00000;100.00000;2.87977;4
200.04700;75.32500;-7.221780e-003;50.00000;100.00000;2.87977;4
200.04700;75.45833;-7.207612e-003;50.00000;100.00000;2.87977;4
200.04601;75.59167;-7.196946e-003;50.00000;100.00000;2.87977;4
200.04700;75.72500;-7.211154e-003;50.00000;100.00000;2.87977;4
200.04601;75.85833;-7.140277e-003;50.00000;100.00000;2.87977;4
200.04601;75.99167;-7.179237e-003;50.00000;100.00000;2.87977;4
200.04601;76.12500;-7.111942e-003;50.00000;100.00000;2.87977;4
200.04601;76.25833;-7.080065e-003;50.00000;100.00000;2.87977;4
200.04500;76.39167;-7.076484e-003;50.00000;100.00000;2.87977;4
200.04700;76.52500;-7.005727e-003;50.00000;100.00000;2.87977;4
200.04800;76.65833;-6.910135e-003;50.00000;100.00000;2.87977;4
200.04800;76.79167;-6.895968e-003;50.00000;100.00000;2.87977;4
200.04900;76.92500;-6.871214e-003;50.00000;100.00000;2.87977;4
200.04900;77.05833;-6.832254e-003;50.00000;100.00000;2.87977;4
200.04900;77.19167;-6.761416e-003;50.00000;100.00000;2.87977;4
200.04900;77.32500;-6.725998e-003;50.00000;100.00000;2.87977;4
200.04900;77.45833;-6.676412e-003;50.00000;100.00000;2.87977;4
200.05000;77.59167;-6.648116e-003;50.00000;100.00000;2.87977;4
200.05000;77.72500;-6.626865e-003;50.00000;100.00000;2.87977;4
200.04900;77.85833;-6.605575e-003;50.00000;100.00000;2.87977;4
200.05000;77.99167;-6.609156e-003;50.00000;100.00000;2.87977;4
200.04900;78.12500;-6.612658e-003;50.00000;100.00000;2.87977;4
200.04800;78.25833;-6.623245e-003;50.00000;100.00000;2.87977;4
200.04800;78.39167;-6.623245e-003;50.00000;100.00000;2.87977;4
200.04601;78.52500;-6.591290e-003;50.00000;100.00000;2.87977;4
200.04300;78.66000;-6.757639e-003;50.00000;100.00000;2.87978;5
199.93800;78.79333;-1.147099e-002;50.00000;100.00000;2.87994;5
199.68900;78.92667;-2.303319e-002;50.00000;100.00000;2.88031;5
199.31200;79.06000;-4.113187e-002;50.00000;100.00000;2.88088;5
198.83900;79.19333;-6.445929e-002;50.00000;100.00000;2.88159;5
198.28200;79.32667;-9.153727e-002;50.00000;100.00000;2.88241;5
197.66000;79.46000;      -0.12099;50.00000;100.00000;2.88333;5
196.98599;79.59333;      -0.15147;50.00000;100.00000;2.88431;5
196.27100;79.72667;      -0.18181;50.00000;100.00000;2.88533;5
195.52499;79.86000;      -0.21136;50.00000;100.00000;2.88639;5
194.75200;79.99333;      -0.23962;50.00000;100.00000;2.88747;5
193.96001;80.12667;      -0.26624;50.00000;100.00000;2.88856;5
193.15100;80.26000;      -0.29099;50.00000;100.00000;2.88966;5
192.32899;80.39333;      -0.31378;50.00000;100.00000;2.89076;5
191.49400;80.52667;      -0.33460;50.00000;100.00000;2.89187;5
190.65401;80.66000;      -0.35348;50.00000;100.00000;2.89296;5
189.80701;80.79333;      -0.37057;50.00000;100.00000;2.89404;5
188.95399;80.92667;      -0.38587;50.00000;100.00000;2.89511;5
188.09900;81.06000;      -0.39947;50.00000;100.00000;2.89617;5
187.24400;81.19333;      -0.41148;50.00000;100.00000;2.89720;5
186.39600;81.32667;      -0.42167;50.00000;100.00000;2.89821;5
185.55901;81.46000;      -0.42997;50.00000;100.00000;2.89919;5
184.73700;81.59333;      -0.43642;50.00000;100.00000;2.90014;5
183.92900;81.72667;      -0.44105;50.00000;100.00000;2.90105;5
183.13699;81.86000;      -0.44398;50.00000;100.00000;2.90193;5
182.36301;81.99333;      -0.44536;50.00000;100.00000;2.90278;5
181.60400;82.12667;      -0.44543;50.00000;100.00000;2.90359;5
180.86301;82.26000;      -0.44426;50.00000;100.00000;2.90437;5
180.13699;82.39333;      -0.44199;50.00000;100.00000;2.90512;5
179.42700;82.52667;      -0.43891;50.00000;100.00000;2.90584;5
178.73100;82.66000;      -0.43506;50.00000;100.00000;2.90654;5
178.05099;82.79333;      -0.43062;50.00000;100.00000;2.90720;5
177.38100;82.92667;      -0.42569;50.00000;100.00000;2.90785;5
176.72600;83.06000;      -0.42043;50.00000;100.00000;2.90847;5
176.08400;83.19333;      -0.41485;50.00000;100.00000;2.90907;5
175.45200;83.32667;      -0.40912;50.00000;100.00000;2.90964;5
174.83299;83.46000;      -0.40330;50.00000;100.00000;2.91020;5
174.22200;83.59333;      -0.39741;50.00000;100.00000;2.91074;5
173.62199;83.72667;      -0.39155;50.00000;100.00000;2.91126;5
173.03000;83.86000;      -0.38567;50.00000;100.00000;2.91177;5
172.44701;83.99333;      -0.37987;50.00000;100.00000;2.91225;5
171.87000;84.12667;      -0.37419;50.00000;100.00000;2.91273;5
171.30400;84.26000;      -0.36865;50.00000;100.00000;2.91319;5
170.74500;84.39333;      -0.36325;50.00000;100.00000;2.91363;5
170.19000;84.52667;      -0.35798;50.00000;100.00000;2.91407;5
169.64500;84.66000;      -0.35321;50.00000;100.00000;2.91448;5
169.10400;84.79333;      -0.34825;50.00000;100.00000;2.91489;5
168.57001;84.92667;      -0.34350;50.00000;100.00000;2.91528;5
168.03999;85.06000;      -0.33893;50.00000;100.00000;2.91567;5
167.51601;85.19333;      -0.33449;50.00000;100.00000;2.91604;5
166.99699;85.32667;      -0.33024;50.00000;100.00000;2.91641;5
166.48399;85.46000;      -0.32621;50.00000;100.00000;2.91676;5
165.97600;85.59333;      -0.32227;50.00000;100.00000;2.91710;5
165.47000;85.72667;      -0.31852;50.00000;100.00000;2.91743;5
164.96899;85.86000;      -0.31489;50.00000;100.00000;2.91776;5
164.47301;85.99333;      -0.31142;50.00000;100.00000;2.91807;5
163.98100;86.12667;      -0.30808;50.00000;100.00000;2.91838;5
163.49200;86.26000;      -0.30493;50.00000;100.00000;2.91868;5
163.00800;86.39333;      -0.30182;50.00000;100.00000;2.91896;5
162.52699;86.52667;      -0.29886;50.00000;100.00000;2.91925;5
162.04700;86.66000;      -0.29603;50.00000;100.00000;2.91952;5
161.57500;86.79333;      -0.29327;50.00000;100.00000;2.91978;5
161.10300;86.92667;      -0.29066;50.00000;100.00000;2.92004;5
160.63400;87.06000;      -0.28811;50.00000;100.00000;2.92029;5
160.17000;87.19333;      -0.28564;50.00000;100.00000;2.92054;5
159.70900;87.32667;      -0.28327;50.00000;100.00000;2.92077;5
159.24899;87.46000;      -0.28099;50.00000;100.00000;2.92100;5
158.79300;87.59333;      -0.27878;50.00000;100.00000;2.92123;5
158.33900;87.72667;      -0.27663;50.00000;100.00000;2.92144;5
157.89000;87.86000;      -0.27454;50.00000;100.00000;2.92165;5
157.44299;87.99333;      -0.27252;50.00000;100.00000;2.92186;5
156.99699;88.12667;      -0.27054;50.00000;100.00000;2.92205;5
156.55400;88.26000;      -0.26865;50.00000;100.00000;2.92224;5
156.11501;88.39333;      -0.26680;50.00000;100.00000;2.92243;5
155.67700;88.52667;      -0.26498;50.00000;100.00000;2.92261;5
155.24300;88.66000;      -0.26321;50.00000;100.00000;2.92278;5
154.81000;88.79333;      -0.26147;50.00000;100.00000;2.92295;5
154.38100;88.92667;      -0.25979;50.00000;100.00000;2.92311;5
153.95399;89.06000;      -0.25817;50.00000;100.00000;2.92326;5
153.52901;89.19333;      -0.25651;50.00000;100.00000;2.92341;5
153.10699;89.32667;      -0.25495;50.00000;100.00000;2.92356;5
152.68700;89.46000;      -0.25341;50.00000;100.00000;2.92370;5
152.26900;89.59333;      -0.25190;50.00000;100.00000;2.92383;5
151.85300;89.72667;      -0.25035;50.00000;100.00000;2.92396;5
151.43900;89.86000;      -0.24890;50.00000;100.00000;2.92409;5
151.02800;89.99333;      -0.24743;50.00000;100.00000;2.92421;5
150.61900;90.12667;      -0.24604;50.00000;100.00000;2.92432;5
150.21100;90.26000;      -0.24464;50.00000;100.00000;2.92443;5
149.80701;90.39333;      -0.24328;50.00000;100.00000;2.92453;5
149.40401;90.52667;      -0.24194;50.00000;100.00000;2.92463;5
149.00200;90.66000;      -0.24060;50.00000;100.00000;2.92473;5
148.60400;90.79333;      -0.23934;50.00000;100.00000;2.92482;5
148.20700;90.92667;      -0.23801;50.00000;100.00000;2.92491;5
147.81200;91.06000;      -0.23676;50.00000;100.00000;2.92499;5
147.41901;91.19333;      -0.23552;50.00000;100.00000;2.92506;5
147.02901;91.32667;      -0.23425;50.00000;100.00000;2.92514;5
146.63901;91.46000;      -0.23307;50.00000;100.00000;2.92521;5
146.25101;91.59333;      -0.23184;50.00000;100.00000;2.92527;5
145.86700;91.72667;      -0.23065;50.00000;100.00000;2.92533;5
145.48399;91.86000;      -0.22950;50.00000;100.00000;2.92539;5
145.10300;91.99333;      -0.22830;50.00000;100.00000;2.92544;5
144.72301;92.12667;      -0.22715;50.00000;100.00000;2.92549;5
144.34599;92.26000;      -0.22599;50.00000;100.00000;2.92553;5
143.96899;92.39333;      -0.22489;50.00000;100.00000;2.92557;5
143.59399;92.52667;      -0.22377;50.00000;100.00000;2.92561;5
143.22200;92.66000;      -0.22269;50.00000;100.00000;2.92564;5
142.85400;92.79333;      -0.22156;50.00000;100.00000;2.92567;5
142.48399;92.92667;      -0.22047;50.00000;100.00000;2.92570;5
142.11800;93.06000;      -0.21942;50.00000;100.00000;2.92572;5
141.75301;93.19333;      -0.21834;50.00000;100.00000;2.92574;5
141.38901;93.32667;      -0.21728;50.00000;100.00000;2.92575;5
141.02800;93.46000;      -0.21623;50.00000;100.00000;2.92576;5
140.66800;93.59333;      -0.21520;50.00000;100.00000;2.92577;5
140.31200;93.72667;      -0.21417;50.00000;100.00000;2.92578;5
139.95599;93.86000;      -0.21310;50.00000;100.00000;2.92578;5
139.60001;93.99333;      -0.21207;50.00000;100.00000;2.92578;5
139.24899;94.12667;      -0.21100;50.00000;100.00000;2.92577;5
138.89900;94.26000;      -0.20996;50.00000;100.00000;2.92576;5
138.54900;94.39333;      -0.20892;50.00000;100.00000;2.92575;5
138.20200;94.52667;      -0.20790;50.00000;100.00000;2.92574;5
137.85600;94.66000;      -0.20690;50.00000;100.00000;2.92572;5
137.51199;94.79333;      -0.20595;50.00000;100.00000;2.92570;5
137.16901;94.92667;      -0.20500;50.00000;100.00000;2.92568;5
136.82800;95.06000;      -0.20406;50.00000;100.00000;2.92565;5
136.48801;95.19333;      -0.20306;50.00000;100.00000;2.92562;5
136.14999;95.32667;      -0.20215;50.00000;100.00000;2.92559;5
135.81400;95.46000;      -0.20135;50.00000;100.00000;2.92556;5
135.47701;95.59333;      -0.20044;50.00000;100.00000;2.92552;5
135.14600;95.72667;      -0.19951;50.00000;100.00000;2.92548;5
134.81200;95.86000;      -0.19860;50.00000;100.00000;2.92544;5
134.48199;95.99333;      -0.19768;50.00000;100.00000;2.92539;5
134.15300;96.12667;      -0.19675;50.00000;100.00000;2.92534;5
133.82700;96.26000;      -0.19586;50.00000;100.00000;2.92529;5
133.50200;96.39333;      -0.19492;50.00000;100.00000;2.92524;5
133.17799;96.52667;      -0.19400;50.00000;100.00000;2.92519;5
132.85699;96.66000;      -0.19310;50.00000;100.00000;2.92513;5
132.53600;96.79333;      -0.19215;50.00000;100.00000;2.92507;5
132.21700;96.92667;      -0.19127;50.00000;100.00000;2.92501;5
131.89799;97.06000;      -0.19042;50.00000;100.00000;2.92494;5
131.58099;97.19333;      -0.18959;50.00000;100.00000;2.92488;5
131.26500;97.32667;      -0.18875;50.00000;100.00000;2.92481;5
130.95200;97.46000;      -0.18792;50.00000;100.00000;2.92474;5
130.63901;97.59333;      -0.18710;50.00000;100.00000;2.92466;5
130.32700;97.72667;      -0.18627;50.00000;100.00000;2.92459;5
130.01801;97.86000;      -0.18544;50.00000;100.00000;2.92451;5
129.71100;97.99333;      -0.18463;50.00000;100.00000;2.92443;5
129.40500;98.12667;      -0.18378;50.00000;100.00000;2.92435;5
129.09700;98.26000;      -0.18300;50.00000;100.00000;2.92426;5
128.79401;98.39333;      -0.18223;50.00000;100.00000;2.92418;5
128.48900;98.52667;      -0.18145;50.00000;100.00000;2.92409;5
128.18700;98.66000;      -0.18070;50.00000;100.00000;2.92400;5
127.88800;98.79333;      -0.17991;50.00000;100.00000;2.92391;5
127.58700;98.92667;      -0.17912;50.00000;100.00000;2.92381;5
127.29000;99.06000;      -0.17838;50.00000;100.00000;2.92372;5
126.99300;99.19333;      -0.17763;50.00000;100.00000;2.92362;5
126.69700;99.32667;      -0.17688;50.00000;100.00000;2.92352;5
126.40500;99.46000;      -0.17607;50.00000;100.00000;2.92342;5
126.11100;99.59333;      -0.17534;50.00000;100.00000;2.92331;5
125.82200;99.72667;      -0.17457;50.00000;100.00000;2.92321;5
125.53200;99.86000;      -0.17381;50.00000;100.00000;2.92310;5
125.27800;99.97667;      -0.17317;50.00000;100.00000;2.92301;5