File: examples/data/B_1.txt
#EXPORTTYPE:DATA ALL
#FILE:
#FORMAT:NETZSCH5
#FTYPE:ANSI
#IDENTITY:
#DECIMAL:POINT
#SEPARATOR:SEMICOLON
#MTYPE:DSC
#INSTRUMENT:NETZSCH DSC 200F3
#DATE/TIME:14.04.2025 17:29
#TEMPCAL:temp_cal_5Kmin.ngb-td5
#SENSITIVITY:sens_cal_5Kmin.ngb-ed5
#REMARK:tot 1432.0
#SAMPLE:Sbr-87-200c-30m_HR5_2ar
#SAMPLE MASS /mg:76
#MATERIAL:
#REFERENCE:Ref.
#REFERENCE MASS /mg:0
#TYPE OF CRUCIBLE:High pressure, steel
#SAMPLE CRUCIBLE MASS /mg:0
#REFERENCE CRUCIBLE MASS /mg:1385.5
#M.RANGE /�V:5000
#TAU-R:---
#CORR. CODE:000
#EXO:-1
#RANGE:25�C....200�C/-7.0....7.0K/min
#SEGMENT:S1-9/9
#SEG. 1:25�C/7.0(K/min)/50�C
#SEG. 2:50�C/00:15/50�C
#SEG. 3:50�C/5.0(K/min)/200�C
#SEG. 4:200�C/00:30/200�C
#SEG. 5:200�C/7.0(K/min)/50�C
#SEG. 6:50�C/04:00/50�C
#SEG. 7:50�C/5.0(K/min)/200�C
#SEG. 8:200�C/00:30/200�C
#SEG. 9:200�C/7.0(K/min)/50�C

##Temp./C;Time/min;DSC/(mW/mg);Gas Flow(purge2)/(ml/min);Gas Flow(protective)/(ml/min);Sensit./(uV/mW);Segment
 33.47400;  0.00000;       0.20789;50.00000;100.00000;3.05528;1
 33.50300;  0.35000;       0.15933;50.00000;100.00000;3.05532;1
 33.53000;  0.70000;       0.12270;50.00000;100.00000;3.05536;1
 33.54900;  1.05000; 9.456662e-002;50.00000;100.00000;3.05538;1
 33.66200;  1.40000; 6.950032e-002;50.00000;100.00000;3.05554;1
 34.29900;  1.75000; 4.422821e-002;50.00000;100.00000;3.05640;1
 35.58500;  2.10000; 3.934849e-002;50.00000;100.00000;3.05812;1
 37.30300;  2.45000; 6.268402e-002;50.00000;100.00000;3.06034;1
 39.27300;  2.80000;       0.10269;50.00000;100.00000;3.06280;1
 41.40000;  3.15000;       0.14779;50.00000;100.00000;3.06534;1
 43.63000;  3.50000;       0.19149;50.00000;100.00000;3.06788;1
 45.68400;  3.83667;       0.23507;50.00000;100.00000;3.07011;2
 47.12600;  4.18667;       0.27685;50.00000;100.00000;3.07162;2
 48.04200;  4.53667;       0.28458;50.00000;100.00000;3.07254;2
 48.64200;  4.88667;       0.26561;50.00000;100.00000;3.07314;2
 49.04200;  5.23667;       0.23390;50.00000;100.00000;3.07353;2
 49.32200;  5.58667;       0.19880;50.00000;100.00000;3.07380;2
 49.51800;  5.93667;       0.16516;50.00000;100.00000;3.07399;2
 49.65600;  6.28667;       0.13516;50.00000;100.00000;3.07412;2
 49.75600;  6.63667;       0.10938;50.00000;100.00000;3.07422;2
 49.82900;  6.98667; 8.775056e-002;50.00000;100.00000;3.07429;2
 49.88000;  7.33667; 6.986335e-002;50.00000;100.00000;3.07434;2
 49.91800;  7.68667; 5.533079e-002;50.00000;100.00000;3.07437;2
 49.94400;  8.03667; 4.354846e-002;50.00000;100.00000;3.07440;2
 49.96400;  8.38667; 3.409142e-002;50.00000;100.00000;3.07442;2
 49.98000;  8.73667; 2.648930e-002;50.00000;100.00000;3.07443;2
 49.99000;  9.08667; 2.055275e-002;50.00000;100.00000;3.07444;2
 50.00000;  9.43667; 1.577211e-002;50.00000;100.00000;3.07445;2
 50.00500;  9.78667; 1.204634e-002;50.00000;100.00000;3.07445;2
 50.00900; 10.13667; 9.107526e-003;50.00000;100.00000;3.07446;2
 50.01200; 10.48667; 6.756487e-003;50.00000;100.00000;3.07446;2
 50.01400; 10.83667; 4.980158e-003;50.00000;100.00000;3.07446;2
 50.01500; 11.18667; 3.540179e-003;50.00000;100.00000;3.07446;2
 50.01500; 11.53667; 2.407161e-003;50.00000;100.00000;3.07446;2
 50.01700; 11.88667; 1.509170e-003;50.00000;100.00000;3.07447;2
 50.01600; 12.23667; 8.561675e-004;50.00000;100.00000;3.07447;2
 50.01700; 12.58667; 3.402362e-004;50.00000;100.00000;3.07447;2
 50.01900; 12.93667;-6.797697e-005;50.00000;100.00000;3.07447;2
 50.01800; 13.28667;-3.911966e-004;50.00000;100.00000;3.07447;2
 50.01900; 13.63667;-6.328524e-004;50.00000;100.00000;3.07447;2
 50.01800; 13.98667;-8.319956e-004;50.00000;100.00000;3.07447;2
 50.01800; 14.33667;-9.723981e-004;50.00000;100.00000;3.07447;2
 50.01800; 14.68667;-1.122596e-003;50.00000;100.00000;3.07447;2
 50.01700; 15.03667;-1.217254e-003;50.00000;100.00000;3.07447;2
 50.01800; 15.38667;-1.289120e-003;50.00000;100.00000;3.07447;2
 50.01700; 15.73667;-1.354391e-003;50.00000;100.00000;3.07447;2
 50.01700; 16.08667;-1.439286e-003;50.00000;100.00000;3.07447;2
 50.01600; 16.43667;-1.439253e-003;50.00000;100.00000;3.07447;2
 50.01800; 16.78667;-1.481766e-003;50.00000;100.00000;3.07447;2
 50.01700; 17.13667;-1.491529e-003;50.00000;100.00000;3.07447;2
 50.01600; 17.48667;-1.517618e-003;50.00000;100.00000;3.07447;2
 50.01600; 17.83667;-1.524148e-003;50.00000;100.00000;3.07447;2
 50.01600; 18.18667;-1.560065e-003;50.00000;100.00000;3.07447;2
 50.01500; 18.53667;-1.563298e-003;50.00000;100.00000;3.07446;2
 50.11500; 18.88833;-4.792443e-003;50.00000;100.00000;3.07456;3
 50.74100; 19.23833;-1.021809e-002;50.00000;100.00000;3.07515;3
 51.83000; 19.58833; 4.069141e-003;50.00000;100.00000;3.07614;3
 53.17600; 19.93833; 3.587472e-002;50.00000;100.00000;3.07734;3
 54.66400; 20.28833; 7.397863e-002;50.00000;100.00000;3.07860;3
 56.23600; 20.63833;       0.11120;50.00000;100.00000;3.07987;3
 57.86300; 20.98833;       0.14434;50.00000;100.00000;3.08112;3
 59.52400; 21.33833;       0.17251;50.00000;100.00000;3.08233;3
 61.21500; 21.68833;       0.19582;50.00000;100.00000;3.08348;3
 62.92400; 22.03833;       0.21498;50.00000;100.00000;3.08457;3
 64.64400; 22.38833;       0.23064;50.00000;100.00000;3.08559;3
 66.37500; 22.73833;       0.24322;50.00000;100.00000;3.08655;3
 68.11300; 23.08833;       0.25331;50.00000;100.00000;3.08742;3
 69.85400; 23.43833;       0.26133;50.00000;100.00000;3.08822;3
 71.60000; 23.78833;       0.26771;50.00000;100.00000;3.08895;3
 73.34700; 24.13833;       0.27272;50.00000;100.00000;3.08959;3
 75.09900; 24.48833;       0.27667;50.00000;100.00000;3.09016;3
 76.84900; 24.83833;       0.27974;50.00000;100.00000;3.09064;3
 78.60100; 25.18833;       0.28219;50.00000;100.00000;3.09105;3
 80.35600; 25.53833;       0.28410;50.00000;100.00000;3.09137;3
 82.10800; 25.88833;       0.28557;50.00000;100.00000;3.09162;3
 83.86300; 26.23833;       0.28669;50.00000;100.00000;3.09179;3
 85.61800; 26.58833;       0.28765;50.00000;100.00000;3.09187;3
 87.37200; 26.93833;       0.28833;50.00000;100.00000;3.09188;3
 89.12700; 27.28833;       0.28896;50.00000;100.00000;3.09180;3
 90.88200; 27.63833;       0.28943;50.00000;100.00000;3.09165;3
 92.63700; 27.98833;       0.28983;50.00000;100.00000;3.09141;3
 94.39300; 28.33833;       0.29015;50.00000;100.00000;3.09109;3
 96.14700; 28.68833;       0.29049;50.00000;100.00000;3.09070;3
 97.90300; 29.03833;       0.29082;50.00000;100.00000;3.09022;3
 99.65800; 29.38833;       0.29111;50.00000;100.00000;3.08966;3
101.41300; 29.73833;       0.29138;50.00000;100.00000;3.08903;3
103.16900; 30.08833;       0.29161;50.00000;100.00000;3.08831;3
104.92300; 30.43833;       0.29179;50.00000;100.00000;3.08751;3
106.67800; 30.78833;       0.29200;50.00000;100.00000;3.08663;3
108.43400; 31.13833;       0.29221;50.00000;100.00000;3.08567;3
110.18800; 31.48833;       0.29232;50.00000;100.00000;3.08464;3
111.94400; 31.83833;       0.29243;50.00000;100.00000;3.08352;3
113.69900; 32.18833;       0.29248;50.00000;100.00000;3.08232;3
115.45500; 32.53833;       0.29258;50.00000;100.00000;3.08104;3
117.21000; 32.88833;       0.29267;50.00000;100.00000;3.07968;3
118.96400; 33.23833;       0.29278;50.00000;100.00000;3.07825;3
120.72000; 33.58833;       0.29295;50.00000;100.00000;3.07673;3
122.47500; 33.93833;       0.29315;50.00000;100.00000;3.07514;3
124.22900; 34.28833;       0.29337;50.00000;100.00000;3.07346;3
125.98500; 34.63833;       0.29363;50.00000;100.00000;3.07171;3
127.73900; 34.98833;       0.29398;50.00000;100.00000;3.06988;3
129.49300; 35.33833;       0.29431;50.00000;100.00000;3.06797;3
131.24800; 35.68833;       0.29473;50.00000;100.00000;3.06598;3
133.00000; 36.03833;       0.29508;50.00000;100.00000;3.06391;3
134.75700; 36.38833;       0.29554;50.00000;100.00000;3.06176;3
136.51100; 36.73833;       0.29603;50.00000;100.00000;3.05954;3
138.26500; 37.08833;       0.29658;50.00000;100.00000;3.05723;3
140.01700; 37.43833;       0.29718;50.00000;100.00000;3.05486;3
141.77299; 37.78833;       0.29786;50.00000;100.00000;3.05240;3
143.52600; 38.13833;       0.29867;50.00000;100.00000;3.04986;3
145.28101; 38.48833;       0.29960;50.00000;100.00000;3.04725;3
147.03500; 38.83833;       0.30071;50.00000;100.00000;3.04456;3
148.78900; 39.18833;       0.30195;50.00000;100.00000;3.04180;3
150.54100; 39.53833;       0.30329;50.00000;100.00000;3.03896;3
152.29500; 39.88833;       0.30493;50.00000;100.00000;3.03604;3
154.04800; 40.23833;       0.30681;50.00000;100.00000;3.03304;3
155.80099; 40.58833;       0.30910;50.00000;100.00000;3.02997;3
157.55400; 40.93833;       0.31175;50.00000;100.00000;3.02683;3
159.30800; 41.28833;       0.31495;50.00000;100.00000;3.02361;3
161.06100; 41.63833;       0.31821;50.00000;100.00000;3.02031;3
162.81300; 41.98833;       0.32247;50.00000;100.00000;3.01694;3
164.56599; 42.33833;       0.32731;50.00000;100.00000;3.01350;3
166.32001; 42.68833;       0.33384;50.00000;100.00000;3.00998;3
168.07401; 43.03833;       0.34337;50.00000;100.00000;3.00638;3
169.82800; 43.38833;       0.35406;50.00000;100.00000;3.00271;3
171.58200; 43.73833;       0.36293;50.00000;100.00000;2.99897;3
173.33400; 44.08833;       0.36539;50.00000;100.00000;2.99515;3
175.08501; 44.43833;       0.36076;50.00000;100.00000;2.99127;3
176.83800; 44.78833;       0.35286;50.00000;100.00000;2.98731;3
178.59200; 45.13833;       0.34783;50.00000;100.00000;2.98328;3
180.34700; 45.48833;       0.34453;50.00000;100.00000;2.97917;3
182.09900; 45.83833;       0.34224;50.00000;100.00000;2.97499;3
183.85201; 46.18833;       0.34022;50.00000;100.00000;2.97074;3
185.60500; 46.53833;       0.33882;50.00000;100.00000;2.96642;3
187.35600; 46.88833;       0.33767;50.00000;100.00000;2.96204;3
189.10800; 47.23833;       0.33677;50.00000;100.00000;2.95758;3
190.86099; 47.58833;       0.33620;50.00000;100.00000;2.95305;3
192.61301; 47.93833;       0.33585;50.00000;100.00000;2.94845;3
194.36400; 48.28833;       0.33566;50.00000;100.00000;2.94378;3
196.12399; 48.64000;       0.33546;50.00000;100.00000;2.93902;4
197.43500; 48.99000;       0.31612;50.00000;100.00000;2.93543;4
198.20100; 49.34000;       0.27205;50.00000;100.00000;2.93332;4
198.67500; 49.69000;       0.21970;50.00000;100.00000;2.93200;4
198.98199; 50.04000;       0.17017;50.00000;100.00000;2.93115;4
199.18500; 50.39000;       0.12795;50.00000;100.00000;2.93058;4
199.32201; 50.74000; 9.384451e-002;50.00000;100.00000;2.93020;4
199.41800; 51.09000; 6.713186e-002;50.00000;100.00000;2.92993;4
199.48300; 51.44000; 4.674287e-002;50.00000;100.00000;2.92975;4
199.53000; 51.79000; 3.129271e-002;50.00000;100.00000;2.92962;4
199.56400; 52.14000; 1.980614e-002;50.00000;100.00000;2.92952;4
199.59000; 52.49000; 1.133807e-002;50.00000;100.00000;2.92945;4
199.61099; 52.84000; 5.083504e-003;50.00000;100.00000;2.92939;4
199.62399; 53.19000; 5.801334e-004;50.00000;100.00000;2.92935;4
199.63699; 53.54000;-2.696494e-003;50.00000;100.00000;2.92932;4
199.64799; 53.89000;-5.071819e-003;50.00000;100.00000;2.92928;4
199.65401; 54.24000;-6.741018e-003;50.00000;100.00000;2.92927;4
199.66200; 54.59000;-7.951096e-003;50.00000;100.00000;2.92925;4
199.66499; 54.94000;-8.797707e-003;50.00000;100.00000;2.92924;4
199.67101; 55.29000;-9.346298e-003;50.00000;100.00000;2.92922;4
199.67599; 55.64000;-9.689226e-003;50.00000;100.00000;2.92921;4
199.68100; 55.99000;-9.898499e-003;50.00000;100.00000;2.92919;4
199.68401; 56.34000;-1.005628e-002;50.00000;100.00000;2.92918;4
199.68700; 56.69000;-1.013524e-002;50.00000;100.00000;2.92918;4
199.69000; 57.04000;-1.014565e-002;50.00000;100.00000;2.92917;4
199.69200; 57.39000;-1.014574e-002;50.00000;100.00000;2.92916;4
199.69501; 57.74000;-1.007733e-002;50.00000;100.00000;2.92915;4
199.69600; 58.09000;-1.003282e-002;50.00000;100.00000;2.92915;4
199.69800; 58.44000;-9.916385e-003;50.00000;100.00000;2.92914;4
199.70000; 58.79000;-9.858211e-003;50.00000;100.00000;2.92914;4
199.70100; 59.14000;-9.762293e-003;50.00000;100.00000;2.92914;4
199.70300; 59.49000;-9.652712e-003;50.00000;100.00000;2.92913;4
199.70399; 59.84000;-9.560221e-003;50.00000;100.00000;2.92913;4
199.70599; 60.19000;-9.474629e-003;50.00000;100.00000;2.92912;4
199.70700; 60.54000;-9.337585e-003;50.00000;100.00000;2.92912;4
199.70599; 60.89000;-9.224444e-003;50.00000;100.00000;2.92912;4
199.71001; 61.24000;-9.121801e-003;50.00000;100.00000;2.92911;4
199.71001; 61.59000;-8.984713e-003;50.00000;100.00000;2.92911;4
199.71201; 61.94000;-8.902546e-003;50.00000;100.00000;2.92910;4
199.71201; 62.29000;-8.779166e-003;50.00000;100.00000;2.92910;4
199.71100; 62.64000;-8.652315e-003;50.00000;100.00000;2.92911;4
199.71201; 62.99000;-8.539260e-003;50.00000;100.00000;2.92910;4
199.71201; 63.34000;-8.409026e-003;50.00000;100.00000;2.92910;4
199.71400; 63.69000;-8.296013e-003;50.00000;100.00000;2.92910;4
199.71300; 64.04000;-8.223999e-003;50.00000;100.00000;2.92910;4
199.71400; 64.39000;-8.110943e-003;50.00000;100.00000;2.92910;4
199.71600; 64.74000;-7.994501e-003;50.00000;100.00000;2.92909;4
199.71600; 65.09000;-7.891684e-003;50.00000;100.00000;2.92909;4
199.71700; 65.44000;-7.802619e-003;50.00000;100.00000;2.92909;4
199.71700; 65.79000;-7.692948e-003;50.00000;100.00000;2.92909;4
199.71800; 66.14000;-7.603881e-003;50.00000;100.00000;2.92909;4
199.71800; 66.49000;-7.501064e-003;50.00000;100.00000;2.92909;4
199.71800; 66.84000;-7.408529e-003;50.00000;100.00000;2.92909;4
199.71700; 67.19000;-7.298816e-003;50.00000;100.00000;2.92909;4
199.71700; 67.54000;-7.199426e-003;50.00000;100.00000;2.92909;4
199.71800; 67.89000;-7.103505e-003;50.00000;100.00000;2.92909;4
199.71800; 68.24000;-7.017824e-003;50.00000;100.00000;2.92909;4
199.71700; 68.59000;-6.911538e-003;50.00000;100.00000;2.92909;4
199.71700; 68.94000;-6.822430e-003;50.00000;100.00000;2.92909;4
199.71800; 69.29000;-6.729936e-003;50.00000;100.00000;2.92909;4
199.71800; 69.64000;-6.616837e-003;50.00000;100.00000;2.92909;4
199.71800; 69.99000;-6.544865e-003;50.00000;100.00000;2.92909;4
199.71800; 70.34000;-6.411203e-003;50.00000;100.00000;2.92909;4
199.71899; 70.69000;-6.325562e-003;50.00000;100.00000;2.92909;4
199.72000; 71.04000;-6.243349e-003;50.00000;100.00000;2.92908;4
199.72000; 71.39000;-6.154241e-003;50.00000;100.00000;2.92908;4
199.72099; 71.74000;-6.072027e-003;50.00000;100.00000;2.92908;4
199.72099; 72.09000;-6.006909e-003;50.00000;100.00000;2.92908;4
199.72099; 72.44000;-5.924655e-003;50.00000;100.00000;2.92908;4
199.72099; 72.79000;-5.866392e-003;50.00000;100.00000;2.92908;4
199.72000; 73.14000;-5.770389e-003;50.00000;100.00000;2.92908;4
199.72200; 73.49000;-5.688216e-003;50.00000;100.00000;2.92908;4
199.72099; 73.84000;-5.633339e-003;50.00000;100.00000;2.92908;4
199.72099; 74.19000;-5.520240e-003;50.00000;100.00000;2.92908;4
199.72099; 74.54000;-5.458550e-003;50.00000;100.00000;2.92908;4
199.72099; 74.89000;-5.403714e-003;50.00000;100.00000;2.92908;4
199.72200; 75.24000;-5.352346e-003;50.00000;100.00000;2.92908;4
199.72099; 75.59000;-5.290615e-003;50.00000;100.00000;2.92908;4
199.72099; 75.94000;-5.249488e-003;50.00000;100.00000;2.92908;4
199.72099; 76.29000;-5.156952e-003;50.00000;100.00000;2.92908;4
199.72200; 76.64000;-5.102156e-003;50.00000;100.00000;2.92908;4
199.72200; 76.99000;-5.040465e-003;50.00000;100.00000;2.92908;4
199.72000; 77.34000;-4.995832e-003;50.00000;100.00000;2.92908;4
199.71899; 77.69000;-4.937530e-003;50.00000;100.00000;2.92909;4
199.72099; 78.04000;-4.865636e-003;50.00000;100.00000;2.92908;4
199.72099; 78.39000;-4.800519e-003;50.00000;100.00000;2.92908;4
199.66901; 78.74167;-7.063779e-003;50.00000;100.00000;2.92923;5
198.88100; 79.09167;-4.138242e-002;50.00000;100.00000;2.93143;5
197.41701; 79.44167;      -0.10571;50.00000;100.00000;2.93548;5
195.57700; 79.79167;      -0.17799;50.00000;100.00000;2.94051;5
193.53000; 80.14167;      -0.24398;50.00000;100.00000;2.94601;5
191.37100; 80.49167;      -0.29821;50.00000;100.00000;2.95171;5
189.15100; 80.84167;      -0.34023;50.00000;100.00000;2.95747;5
186.90900; 81.19167;      -0.37105;50.00000;100.00000;2.96316;5
184.71400; 81.54167;      -0.39046;50.00000;100.00000;2.96863;5
182.62300; 81.89167;      -0.39854;50.00000;100.00000;2.97373;5
180.64799; 82.24167;      -0.39739;50.00000;100.00000;2.97845;5
178.78200; 82.59167;      -0.38983;50.00000;100.00000;2.98283;5
177.01700; 82.94167;      -0.37828;50.00000;100.00000;2.98690;5
175.34000; 83.29167;      -0.36470;50.00000;100.00000;2.99070;5
173.73801; 83.64167;      -0.35048;50.00000;100.00000;2.99427;5
172.20000; 83.99167;      -0.33645;50.00000;100.00000;2.99763;5
170.71700; 84.34167;      -0.32316;50.00000;100.00000;3.00082;5
169.28200; 84.69167;      -0.31086;50.00000;100.00000;3.00386;5
167.88901; 85.04167;      -0.29965;50.00000;100.00000;3.00676;5
166.53200; 85.39167;      -0.28957;50.00000;100.00000;3.00955;5
165.20799; 85.74167;      -0.28049;50.00000;100.00000;3.01222;5
163.91200; 86.09167;      -0.27237;50.00000;100.00000;3.01479;5
162.64400; 86.44167;      -0.26509;50.00000;100.00000;3.01727;5
161.39900; 86.79167;      -0.25847;50.00000;100.00000;3.01967;5
160.17700; 87.14167;      -0.25248;50.00000;100.00000;3.02198;5
158.97400; 87.49167;      -0.24701;50.00000;100.00000;3.02423;5
157.79201; 87.84167;      -0.24204;50.00000;100.00000;3.02640;5
156.63000; 88.19167;      -0.23735;50.00000;100.00000;3.02850;5
155.48300; 88.54167;      -0.23303;50.00000;100.00000;3.03054;5
154.35500; 88.89167;      -0.22896;50.00000;100.00000;3.03251;5
153.24200; 89.24167;      -0.22513;50.00000;100.00000;3.03443;5
152.14600; 89.59167;      -0.22143;50.00000;100.00000;3.03629;5
151.06300; 89.94167;      -0.21798;50.00000;100.00000;3.03810;5
149.99800; 90.29167;      -0.21467;50.00000;100.00000;3.03984;5
148.94600; 90.64167;      -0.21156;50.00000;100.00000;3.04154;5
147.90601; 90.99167;      -0.20854;50.00000;100.00000;3.04320;5
146.88200; 91.34167;      -0.20558;50.00000;100.00000;3.04480;5
145.87199; 91.69167;      -0.20275;50.00000;100.00000;3.04635;5
144.87399; 92.04167;      -0.20001;50.00000;100.00000;3.04786;5
143.88699; 92.39167;      -0.19733;50.00000;100.00000;3.04933;5
142.91499; 92.74167;      -0.19472;50.00000;100.00000;3.05076;5
141.95300; 93.09167;      -0.19221;50.00000;100.00000;3.05214;5
141.00400; 93.44167;      -0.18973;50.00000;100.00000;3.05348;5
140.06599; 93.79167;      -0.18733;50.00000;100.00000;3.05479;5
139.13800; 94.14167;      -0.18499;50.00000;100.00000;3.05606;5
138.22301; 94.49167;      -0.18267;50.00000;100.00000;3.05729;5
137.31799; 94.84167;      -0.18043;50.00000;100.00000;3.05849;5
136.42400; 95.19167;      -0.17827;50.00000;100.00000;3.05965;5
135.54201; 95.54167;      -0.17608;50.00000;100.00000;3.06078;5
134.66701; 95.89167;      -0.17401;50.00000;100.00000;3.06187;5
133.80400; 96.24167;      -0.17196;50.00000;100.00000;3.06294;5
132.95100; 96.59167;      -0.16993;50.00000;100.00000;3.06397;5
132.10800; 96.94167;      -0.16797;50.00000;100.00000;3.06497;5
131.27400; 97.29167;      -0.16596;50.00000;100.00000;3.06595;5
130.44901; 97.64167;      -0.16411;50.00000;100.00000;3.06689;5
129.63400; 97.99167;      -0.16230;50.00000;100.00000;3.06781;5
128.82600; 98.34167;      -0.16049;50.00000;100.00000;3.06870;5
128.02901; 98.69167;      -0.15877;50.00000;100.00000;3.06957;5
127.24000; 99.04167;      -0.15707;50.00000;100.00000;3.07041;5
126.46000; 99.39167;      -0.15531;50.00000;100.00000;3.07122;5
125.68700; 99.74167;      -0.15362;50.00000;100.00000;3.07201;5
124.57100;100.25500;      -0.15114;50.00000;100.00000;3.07313;6
122.33800;101.30500;      -0.14638;50.00000;100.00000;3.07526;6
120.17600;102.35500;      -0.14187;50.00000;100.00000;3.07721;6
118.08000;103.40500;      -0.13756;50.00000;100.00000;3.07898;6
116.04400;104.45500;      -0.13349;50.00000;100.00000;3.08060;6
114.07000;105.50500;      -0.12960;50.00000;100.00000;3.08206;6
112.15500;106.55500;      -0.12591;50.00000;100.00000;3.08338;6
110.29200;107.60500;      -0.12233;50.00000;100.00000;3.08457;6
108.48400;108.65500;      -0.11895;50.00000;100.00000;3.08565;6
106.72600;109.70500;      -0.11565;50.00000;100.00000;3.08661;6
105.01500;110.75500;      -0.11252;50.00000;100.00000;3.08747;6
103.35100;111.80500;      -0.10954;50.00000;100.00000;3.08823;6
101.73300;112.85500;      -0.10668;50.00000;100.00000;3.08890;6
100.15800;113.90500;      -0.10393;50.00000;100.00000;3.08949;6
 98.62400;114.95500;      -0.10123;50.00000;100.00000;3.09000;6
 97.13100;116.00500;-9.866161e-002;50.00000;100.00000;3.09044;6
 95.67600;117.05500;-9.617586e-002;50.00000;100.00000;3.09081;6
 94.25800;118.10500;-9.378475e-002;50.00000;100.00000;3.09112;6
 92.87500;119.15500;-9.151063e-002;50.00000;100.00000;3.09137;6
 91.53000;120.20500;-8.928193e-002;50.00000;100.00000;3.09157;6
 90.21500;121.25500;-8.715332e-002;50.00000;100.00000;3.09171;6
 88.93300;122.30500;-8.507923e-002;50.00000;100.00000;3.09181;6
 87.68400;123.35500;-8.311143e-002;50.00000;100.00000;3.09187;6
 86.46400;124.40500;-8.115220e-002;50.00000;100.00000;3.09188;6
 85.27100;125.45500;-7.932797e-002;50.00000;100.00000;3.09186;6
 84.10800;126.50500;-7.750882e-002;50.00000;100.00000;3.09180;6
 82.97400;127.55500;-7.576928e-002;50.00000;100.00000;3.09171;6
 81.86400;128.60500;-7.407987e-002;50.00000;100.00000;3.09159;6
 80.78100;129.65500;-7.241784e-002;50.00000;100.00000;3.09144;6
 79.72200;130.70500;-7.080251e-002;50.00000;100.00000;3.09126;6
 78.68800;131.75500;-6.929226e-002;50.00000;100.00000;3.09107;6
 77.67700;132.80500;-6.775709e-002;50.00000;100.00000;3.09084;6
 76.69300;133.85500;-6.629771e-002;50.00000;100.00000;3.09060;6
 75.72500;134.90500;-6.487155e-002;50.00000;100.00000;3.09034;6
 74.78100;135.95500;-6.350476e-002;50.00000;100.00000;3.09006;6
 73.85700;137.00500;-6.216794e-002;50.00000;100.00000;3.08976;6
 72.95700;138.05500;-6.087092e-002;50.00000;100.00000;3.08945;6
 72.07400;139.10500;-5.958098e-002;50.00000;100.00000;3.08913;6
 71.21100;140.15500;-5.836315e-002;50.00000;100.00000;3.08879;6
 70.36600;141.20500;-5.717838e-002;50.00000;100.00000;3.08844;6
 69.53900;142.25500;-5.600712e-002;50.00000;100.00000;3.08808;6
 68.72800;143.30500;-5.488505e-002;50.00000;100.00000;3.08771;6
 67.93500;144.35500;-5.378623e-002;50.00000;100.00000;3.08734;6
 67.16200;145.40500;-5.270090e-002;50.00000;100.00000;3.08695;6
 66.40000;146.45500;-5.162883e-002;50.00000;100.00000;3.08656;6
 65.65900;147.50500;-5.061580e-002;50.00000;100.00000;3.08616;6
 64.93000;148.55500;-4.961927e-002;50.00000;100.00000;3.08576;6
 64.21800;149.60500;-4.866541e-002;50.00000;100.00000;3.08535;6
 63.52000;150.65500;-4.769230e-002;50.00000;100.00000;3.08494;6
 62.83900;151.70500;-4.673254e-002;50.00000;100.00000;3.08452;6
 62.16800;152.75500;-4.582826e-002;50.00000;100.00000;3.08410;6
 61.51200;153.80500;-4.496658e-002;50.00000;100.00000;3.08368;6
 60.86700;154.85500;-4.413438e-002;50.00000;100.00000;3.08325;6
 60.23900;155.90500;-4.331878e-002;50.00000;100.00000;3.08282;6
 59.62200;156.95500;-4.247079e-002;50.00000;100.00000;3.08240;6
 59.01500;158.00500;-4.168155e-002;50.00000;100.00000;3.08197;6
 58.42100;159.05500;-4.089903e-002;50.00000;100.00000;3.08153;6
 57.84000;160.10500;-4.017210e-002;50.00000;100.00000;3.08110;6
 57.26900;161.15500;-3.942902e-002;50.00000;100.00000;3.08067;6
 56.71000;162.20500;-3.868937e-002;50.00000;100.00000;3.08024;6
 56.16300;163.25500;-3.795641e-002;50.00000;100.00000;3.07981;6
 55.62600;164.30500;-3.726596e-002;50.00000;100.00000;3.07939;6
 55.09800;165.35500;-3.657560e-002;50.00000;100.00000;3.07896;6
 54.58300;166.40500;-3.589523e-002;50.00000;100.00000;3.07853;6
 54.07800;167.45500;-3.522149e-002;50.00000;100.00000;3.07811;6
 53.58200;168.50500;-3.456090e-002;50.00000;100.00000;3.07769;6
 53.09600;169.55500;-3.394611e-002;50.00000;100.00000;3.07727;6
 52.62000;170.60500;-3.335428e-002;50.00000;100.00000;3.07685;6
 52.15100;171.65500;-3.275926e-002;50.00000;100.00000;3.07643;6
 51.69000;172.70500;-3.221002e-002;50.00000;100.00000;3.07602;6
 51.24000;173.75500;-3.161524e-002;50.00000;100.00000;3.07561;6
 50.79900;174.80500;-3.102710e-002;50.00000;100.00000;3.07520;6
 50.36400;175.85500;-3.048470e-002;50.00000;100.00000;3.07479;6
 50.01500;176.90500;-2.726353e-002;50.00000;100.00000;3.07446;6
 49.95100;177.95500;-1.552341e-002;50.00000;100.00000;3.07440;6
 49.97500;179.00500;-6.564316e-003;50.00000;100.00000;3.07443;6
 49.98500;180.05500;-3.452880e-003;50.00000;100.00000;3.07444;6
 49.98700;181.10500;-2.509299e-003;50.00000;100.00000;3.07444;6
 49.98800;182.15500;-2.084854e-003;50.00000;100.00000;3.07444;6
 49.99000;183.20500;-1.921658e-003;50.00000;100.00000;3.07444;6
 49.99200;184.25500;-1.879276e-003;50.00000;100.00000;3.07444;6
 49.99200;185.30500;-1.876010e-003;50.00000;100.00000;3.07444;6
 49.99200;186.35500;-1.859684e-003;50.00000;100.00000;3.07444;6
 49.99200;187.40500;-1.879276e-003;50.00000;100.00000;3.07444;6
 49.99200;188.45500;-1.856419e-003;50.00000;100.00000;3.07444;6
 49.99500;189.50500;-1.836925e-003;50.00000;100.00000;3.07445;6
 49.99600;190.55500;-1.830427e-003;50.00000;100.00000;3.07445;6
 49.99500;191.60500;-1.849986e-003;50.00000;100.00000;3.07445;6
 49.99700;192.65500;-1.823929e-003;50.00000;100.00000;3.07445;6
 49.99700;193.70500;-1.784747e-003;50.00000;100.00000;3.07445;6
 49.99800;194.75500;-1.840288e-003;50.00000;100.00000;3.07445;6
 49.99800;195.80500;-1.837022e-003;50.00000;100.00000;3.07445;6
 49.99600;196.85500;-1.810836e-003;50.00000;100.00000;3.07445;6
 49.99800;197.90500;-1.804370e-003;50.00000;100.00000;3.07445;6
 49.99900;198.95500;-1.778281e-003;50.00000;100.00000;3.07445;6
 50.00000;200.00500;-1.797905e-003;50.00000;100.00000;3.07445;6
 49.99900;201.05500;-1.778281e-003;50.00000;100.00000;3.07445;6
 50.00000;202.10500;-1.765253e-003;50.00000;100.00000;3.07445;6
 49.99900;203.15500;-1.761955e-003;50.00000;100.00000;3.07445;6
 50.00100;204.20500;-1.735898e-003;50.00000;100.00000;3.07445;6
 50.00100;205.25500;-1.739164e-003;50.00000;100.00000;3.07445;6
 50.00000;206.30500;-1.771783e-003;50.00000;100.00000;3.07445;6
 50.00000;207.35500;-1.784844e-003;50.00000;100.00000;3.07445;6
 50.00100;208.40500;-1.748959e-003;50.00000;100.00000;3.07445;6
 50.00000;209.45500;-1.709744e-003;50.00000;100.00000;3.07445;6
 50.00100;210.50500;-1.739164e-003;50.00000;100.00000;3.07445;6
 50.00100;211.55500;-1.719573e-003;50.00000;100.00000;3.07445;6
 50.00200;212.60500;-1.709809e-003;50.00000;100.00000;3.07445;6
 50.00000;213.65500;-1.713010e-003;50.00000;100.00000;3.07445;6
 49.99900;214.70500;-1.722773e-003;50.00000;100.00000;3.07445;6
 50.00100;215.75500;-1.713042e-003;50.00000;100.00000;3.07445;6
 50.00200;216.80500;-1.686953e-003;50.00000;100.00000;3.07445;6
 50.00300;217.85500;-1.683720e-003;50.00000;100.00000;3.07445;6
 50.00200;218.90500;-1.680423e-003;50.00000;100.00000;3.07445;6
 50.00400;219.95500;-1.690283e-003;50.00000;100.00000;3.07445;6
 50.00400;221.00500;-1.673957e-003;50.00000;100.00000;3.07445;6
 50.00400;222.05500;-1.654366e-003;50.00000;100.00000;3.07445;6
 50.00400;223.10500;-1.641305e-003;50.00000;100.00000;3.07445;6
 50.00500;224.15500;-1.660929e-003;50.00000;100.00000;3.07445;6
 50.00400;225.20500;-1.673957e-003;50.00000;100.00000;3.07445;6
 50.00400;226.25500;-1.664162e-003;50.00000;100.00000;3.07445;6
 50.00400;227.30500;-1.660896e-003;50.00000;100.00000;3.07445;6
 50.00300;228.35500;-1.641273e-003;50.00000;100.00000;3.07445;6
 50.00500;229.40500;-1.664194e-003;50.00000;100.00000;3.07445;6
 50.00400;230.45500;-1.657631e-003;50.00000;100.00000;3.07445;6
 50.00600;231.50500;-1.615249e-003;50.00000;100.00000;3.07446;6
 50.00500;232.55500;-1.667459e-003;50.00000;100.00000;3.07445;6
 50.00500;233.60500;-1.631542e-003;50.00000;100.00000;3.07445;6
 50.00500;234.65500;-1.634807e-003;50.00000;100.00000;3.07445;6
 50.00600;235.70500;-1.595657e-003;50.00000;100.00000;3.07446;6
 50.00800;236.75500;-1.615313e-003;50.00000;100.00000;3.07446;6
 50.00800;237.80500;-1.628374e-003;50.00000;100.00000;3.07446;6
 50.00700;238.85500;-1.647933e-003;50.00000;100.00000;3.07446;6
 50.00600;239.90500;-1.615249e-003;50.00000;100.00000;3.07446;6
 50.00900;240.95500;-1.608816e-003;50.00000;100.00000;3.07446;6
 50.00700;242.00500;-1.608751e-003;50.00000;100.00000;3.07446;6
 50.00700;243.05500;-1.608751e-003;50.00000;100.00000;3.07446;6
 50.00700;244.10500;-1.631607e-003;50.00000;100.00000;3.07446;6
 50.00800;245.15500;-1.589192e-003;50.00000;100.00000;3.07446;6
 50.00700;246.20500;-1.602220e-003;50.00000;100.00000;3.07446;6
 50.00900;247.25500;-1.579429e-003;50.00000;100.00000;3.07446;6
 50.00800;248.30500;-1.605518e-003;50.00000;100.00000;3.07446;6
 50.00700;249.35500;-1.654463e-003;50.00000;100.00000;3.07446;6
 50.00800;250.40500;-1.579396e-003;50.00000;100.00000;3.07446;6
 50.00900;251.45500;-1.576164e-003;50.00000;100.00000;3.07446;6
 50.00700;252.50500;-1.576099e-003;50.00000;100.00000;3.07446;6
 50.00800;253.55500;-1.618579e-003;50.00000;100.00000;3.07446;6
 50.00800;254.60500;-1.556540e-003;50.00000;100.00000;3.07446;6
 50.01200;255.65500;-1.556670e-003;50.00000;100.00000;3.07446;6
 50.00900;256.70500;-1.582694e-003;50.00000;100.00000;3.07446;6
 50.01000;257.75500;-1.599053e-003;50.00000;100.00000;3.07446;6
 50.01000;258.80500;-1.572931e-003;50.00000;100.00000;3.07446;6
 50.01000;259.85500;-1.589257e-003;50.00000;100.00000;3.07446;6
 50.01000;260.90500;-1.592522e-003;50.00000;100.00000;3.07446;6
 50.01000;261.95500;-1.576196e-003;50.00000;100.00000;3.07446;6
 50.01000;263.00500;-1.566401e-003;50.00000;100.00000;3.07446;6
 50.01200;264.05500;-1.553405e-003;50.00000;100.00000;3.07446;6
 50.01100;265.10500;-1.579494e-003;50.00000;100.00000;3.07446;6
 50.01000;266.15500;-1.572931e-003;50.00000;100.00000;3.07446;6
 50.00900;267.20500;-1.569633e-003;50.00000;100.00000;3.07446;6
 50.00900;268.25500;-1.553307e-003;50.00000;100.00000;3.07446;6
 50.01100;269.30500;-1.550107e-003;50.00000;100.00000;3.07446;6
 50.00900;270.35500;-1.530451e-003;50.00000;100.00000;3.07446;6
 50.01100;271.40500;-1.556637e-003;50.00000;100.00000;3.07446;6
 50.01100;272.45500;-1.546842e-003;50.00000;100.00000;3.07446;6
 50.01300;273.50500;-1.546907e-003;50.00000;100.00000;3.07446;6
 50.01200;274.55500;-1.550140e-003;50.00000;100.00000;3.07446;6
 50.01500;275.60500;-1.540442e-003;50.00000;100.00000;3.07446;6
 50.01200;276.65500;-1.550140e-003;50.00000;100.00000;3.07446;6
 50.01200;277.70500;-1.556670e-003;50.00000;100.00000;3.07446;6
 50.01300;278.75500;-1.533846e-003;50.00000;100.00000;3.07446;6
 50.01200;279.80500;-1.553405e-003;50.00000;100.00000;3.07446;6
 50.01100;280.85500;-1.533781e-003;50.00000;100.00000;3.07446;6
 50.01100;281.90500;-1.543577e-003;50.00000;100.00000;3.07446;6
 50.01100;282.95500;-1.543577e-003;50.00000;100.00000;3.07446;6
 50.01100;284.00500;-1.517455e-003;50.00000;100.00000;3.07446;6
 50.01200;285.05500;-1.439123e-003;50.00000;100.00000;3.07446;6
 50.01400;286.10500;-1.530613e-003;50.00000;100.00000;3.07446;6
 50.01300;287.15500;-1.595885e-003;50.00000;100.00000;3.07446;6
 50.01100;288.20500;-1.540312e-003;50.00000;100.00000;3.07446;6
 50.01400;289.25500;-1.546939e-003;50.00000;100.00000;3.07446;6
 50.01200;290.30500;-1.540344e-003;50.00000;100.00000;3.07446;6
 50.01200;291.35500;-1.530549e-003;50.00000;100.00000;3.07446;6
 50.01400;292.40500;-1.530613e-003;50.00000;100.00000;3.07446;6
 50.01300;293.45500;-1.504459e-003;50.00000;100.00000;3.07446;6
 50.01200;294.50500;-1.527283e-003;50.00000;100.00000;3.07446;6
 50.01200;295.55500;-1.527283e-003;50.00000;100.00000;3.07446;6
 50.01300;296.60500;-1.537111e-003;50.00000;100.00000;3.07446;6
 50.01200;297.65500;-1.520753e-003;50.00000;100.00000;3.07446;6
 50.01200;298.70500;-1.510958e-003;50.00000;100.00000;3.07446;6
 50.01200;299.75500;-1.494632e-003;50.00000;100.00000;3.07446;6
 50.01300;300.80500;-1.527316e-003;50.00000;100.00000;3.07446;6
 50.01400;301.85500;-1.514288e-003;50.00000;100.00000;3.07446;6
 50.01500;302.90500;-1.471873e-003;50.00000;100.00000;3.07446;6
 50.01300;303.95500;-1.540376e-003;50.00000;100.00000;3.07446;6
 50.01400;305.00500;-1.563265e-003;50.00000;100.00000;3.07446;6
 50.01400;306.05500;-1.550205e-003;50.00000;100.00000;3.07446;6
 50.01200;307.10500;-1.546875e-003;50.00000;100.00000;3.07446;6
 50.01200;308.15500;-1.543609e-003;50.00000;100.00000;3.07446;6
 50.01100;309.20500;-1.517455e-003;50.00000;100.00000;3.07446;6
 50.01400;310.25500;-1.530613e-003;50.00000;100.00000;3.07446;6
 50.01400;311.30500;-1.501227e-003;50.00000;100.00000;3.07446;6
 50.01400;312.35500;-1.514288e-003;50.00000;100.00000;3.07446;6
 50.01400;313.40500;-1.497962e-003;50.00000;100.00000;3.07446;6
 50.01500;314.45500;-1.507790e-003;50.00000;100.00000;3.07446;6
 50.01500;315.50500;-1.491464e-003;50.00000;100.00000;3.07446;6
 50.01500;316.55500;-1.501259e-003;50.00000;100.00000;3.07446;6
 50.01300;317.60500;-1.524051e-003;50.00000;100.00000;3.07446;6
 50.01200;318.65500;-1.537079e-003;50.00000;100.00000;3.07446;6
 50.01400;319.70500;-1.517553e-003;50.00000;100.00000;3.07446;6
 50.01300;320.75500;-1.520785e-003;50.00000;100.00000;3.07446;6
 50.01600;321.80500;-1.498027e-003;50.00000;100.00000;3.07447;6
 50.01500;322.85500;-1.546972e-003;50.00000;100.00000;3.07446;6
 50.01400;323.90500;-1.540409e-003;50.00000;100.00000;3.07446;6
 50.01500;324.95500;-1.501259e-003;50.00000;100.00000;3.07446;6
 50.01500;326.00500;-1.514320e-003;50.00000;100.00000;3.07446;6
 50.01600;327.05500;-1.514352e-003;50.00000;100.00000;3.07447;6
 50.01700;328.10500;-1.517650e-003;50.00000;100.00000;3.07447;6
 50.01500;329.15500;-1.520851e-003;50.00000;100.00000;3.07446;6
 50.01500;330.20500;-1.504525e-003;50.00000;100.00000;3.07446;6
 50.01600;331.25500;-1.524148e-003;50.00000;100.00000;3.07447;6
 50.01400;332.30500;-1.520818e-003;50.00000;100.00000;3.07446;6
 50.01600;333.35500;-1.501292e-003;50.00000;100.00000;3.07447;6
 50.01600;334.40500;-1.501292e-003;50.00000;100.00000;3.07447;6
 50.01500;335.45500;-1.543707e-003;50.00000;100.00000;3.07446;6
 50.01500;336.50500;-1.520851e-003;50.00000;100.00000;3.07446;6
 50.01500;337.55500;-1.488199e-003;50.00000;100.00000;3.07446;6
 50.01500;338.60500;-1.494729e-003;50.00000;100.00000;3.07446;6
 50.01600;339.65500;-1.507822e-003;50.00000;100.00000;3.07447;6
 50.05300;340.24000;-1.148087e-004;50.00000;100.00000;3.07450;7
 50.53000;340.59000; 1.691104e-002;50.00000;100.00000;3.07495;7
 51.53100;340.94000; 5.270171e-002;50.00000;100.00000;3.07587;7
 52.82900;341.29000; 9.748806e-002;50.00000;100.00000;3.07703;7
 54.29300;341.64000;       0.14201;50.00000;100.00000;3.07829;7
 55.84900;341.99000;       0.18158;50.00000;100.00000;3.07956;7
 57.46800;342.34000;       0.21484;50.00000;100.00000;3.08082;7
 59.12400;342.69000;       0.24195;50.00000;100.00000;3.08204;7
 60.81100;343.04000;       0.26363;50.00000;100.00000;3.08321;7
 62.51600;343.39000;       0.28076;50.00000;100.00000;3.08432;7
 64.23700;343.74000;       0.29416;50.00000;100.00000;3.08536;7
 65.96600;344.09000;       0.30458;50.00000;100.00000;3.08633;7
 67.70300;344.44000;       0.31258;50.00000;100.00000;3.08722;7
 69.44600;344.79000;       0.31870;50.00000;100.00000;3.08804;7
 71.19200;345.14000;       0.32335;50.00000;100.00000;3.08878;7
 72.94200;345.49000;       0.32686;50.00000;100.00000;3.08945;7
 74.69100;345.84000;       0.32947;50.00000;100.00000;3.09003;7
 76.44300;346.19000;       0.33139;50.00000;100.00000;3.09054;7
 78.19300;346.54000;       0.33281;50.00000;100.00000;3.09096;7
 79.94800;346.89000;       0.33384;50.00000;100.00000;3.09131;7
 81.70100;347.24000;       0.33458;50.00000;100.00000;3.09157;7
 83.45500;347.59000;       0.33511;50.00000;100.00000;3.09175;7
 85.21000;347.94000;       0.33547;50.00000;100.00000;3.09186;7
 86.96500;348.29000;       0.33571;50.00000;100.00000;3.09188;7
 88.72000;348.64000;       0.33586;50.00000;100.00000;3.09183;7
 90.47500;348.99000;       0.33597;50.00000;100.00000;3.09169;7
 92.23200;349.34000;       0.33598;50.00000;100.00000;3.09147;7
 93.98600;349.69000;       0.33599;50.00000;100.00000;3.09117;7
 95.74300;350.04000;       0.33594;50.00000;100.00000;3.09080;7
 97.49800;350.39000;       0.33589;50.00000;100.00000;3.09034;7
 99.25200;350.74000;       0.33582;50.00000;100.00000;3.08980;7
101.00700;351.09000;       0.33579;50.00000;100.00000;3.08918;7
102.76300;351.44000;       0.33574;50.00000;100.00000;3.08848;7
104.51700;351.79000;       0.33567;50.00000;100.00000;3.08770;7
106.27200;352.14000;       0.33562;50.00000;100.00000;3.08684;7
108.02800;352.49000;       0.33558;50.00000;100.00000;3.08590;7
109.78300;352.84000;       0.33554;50.00000;100.00000;3.08488;7
111.53700;353.19000;       0.33552;50.00000;100.00000;3.08378;7
113.29300;353.54000;       0.33551;50.00000;100.00000;3.08260;7
115.04800;353.89000;       0.33550;50.00000;100.00000;3.08135;7
116.80300;354.24000;       0.33550;50.00000;100.00000;3.08001;7
118.55800;354.59000;       0.33553;50.00000;100.00000;3.07859;7
120.31300;354.94000;       0.33555;50.00000;100.00000;3.07709;7
122.06900;355.29000;       0.33559;50.00000;100.00000;3.07551;7
123.82100;355.64000;       0.33559;50.00000;100.00000;3.07386;7
125.57500;355.99000;       0.33563;50.00000;100.00000;3.07212;7
127.33100;356.34000;       0.33574;50.00000;100.00000;3.07031;7
129.08501;356.69000;       0.33578;50.00000;100.00000;3.06842;7
130.83800;357.04000;       0.33586;50.00000;100.00000;3.06645;7
132.59300;357.39000;       0.33595;50.00000;100.00000;3.06440;7
134.34700;357.74000;       0.33604;50.00000;100.00000;3.06227;7
136.10100;358.09000;       0.33617;50.00000;100.00000;3.06006;7
137.85500;358.44000;       0.33629;50.00000;100.00000;3.05778;7
139.60899;358.79000;       0.33643;50.00000;100.00000;3.05542;7
141.36301;359.14000;       0.33660;50.00000;100.00000;3.05298;7
143.11700;359.49000;       0.33676;50.00000;100.00000;3.05046;7
144.87100;359.84000;       0.33698;50.00000;100.00000;3.04787;7
146.62399;360.19000;       0.33726;50.00000;100.00000;3.04520;7
148.37801;360.54000;       0.33754;50.00000;100.00000;3.04245;7
150.13200;360.89000;       0.33785;50.00000;100.00000;3.03963;7
151.88600;361.24000;       0.33817;50.00000;100.00000;3.03672;7
153.63901;361.59000;       0.33858;50.00000;100.00000;3.03375;7
155.39301;361.94000;       0.33898;50.00000;100.00000;3.03070;7
157.14600;362.29000;       0.33944;50.00000;100.00000;3.02757;7
158.89999;362.64000;       0.33995;50.00000;100.00000;3.02436;7
160.65300;362.99000;       0.34050;50.00000;100.00000;3.02109;7
162.40700;363.34000;       0.34109;50.00000;100.00000;3.01773;7
164.15900;363.69000;       0.34176;50.00000;100.00000;3.01430;7
165.91200;364.04000;       0.34191;50.00000;100.00000;3.01080;7
167.66499;364.39000;       0.34152;50.00000;100.00000;3.00723;7
169.41701;364.74000;       0.34146;50.00000;100.00000;3.00358;7
171.16901;365.09000;       0.34148;50.00000;100.00000;2.99986;7
172.92200;365.44000;       0.34166;50.00000;100.00000;2.99606;7
174.67400;365.79000;       0.34189;50.00000;100.00000;2.99219;7
176.42500;366.14000;       0.34220;50.00000;100.00000;2.98825;7
178.17999;366.49000;       0.34251;50.00000;100.00000;2.98423;7
179.93201;366.84000;       0.34285;50.00000;100.00000;2.98014;7
181.68401;367.19000;       0.34325;50.00000;100.00000;2.97599;7
183.43500;367.54000;       0.34363;50.00000;100.00000;2.97176;7
185.18600;367.89000;       0.34405;50.00000;100.00000;2.96746;7
186.94000;368.24000;       0.34449;50.00000;100.00000;2.96308;7
188.69299;368.59000;       0.34490;50.00000;100.00000;2.95864;7
190.44400;368.94000;       0.34535;50.00000;100.00000;2.95413;7
192.19501;369.29000;       0.34580;50.00000;100.00000;2.94955;7
193.94701;369.64000;       0.34629;50.00000;100.00000;2.94490;7
195.69701;369.99000;       0.34680;50.00000;100.00000;2.94018;7
197.18500;370.34167;       0.33522;50.00000;100.00000;2.93612;8
198.05000;370.69167;       0.29596;50.00000;100.00000;2.93373;8
198.57800;371.04167;       0.24458;50.00000;100.00000;2.93227;8
198.91701;371.39167;       0.19412;50.00000;100.00000;2.93133;8
199.14101;371.74167;       0.15026;50.00000;100.00000;2.93070;8
199.29100;372.09167;       0.11441;50.00000;100.00000;2.93028;8
199.39400;372.44167; 8.609845e-002;50.00000;100.00000;2.93000;8
199.46500;372.79167; 6.421394e-002;50.00000;100.00000;2.92980;8
199.51700;373.14167; 4.754846e-002;50.00000;100.00000;2.92965;8
199.55299;373.49167; 3.504826e-002;50.00000;100.00000;2.92955;8
199.58099;373.84167; 2.566226e-002;50.00000;100.00000;2.92947;8
199.60100;374.19167; 1.876037e-002;50.00000;100.00000;2.92942;8
199.61600;374.54167; 1.364719e-002;50.00000;100.00000;2.92937;8
199.63000;374.89167; 9.825836e-003;50.00000;100.00000;2.92933;8
199.64000;375.24167; 7.056584e-003;50.00000;100.00000;2.92931;8
199.64799;375.59167; 4.969313e-003;50.00000;100.00000;2.92928;8
199.65500;375.94167; 3.454357e-003;50.00000;100.00000;2.92926;8
199.66100;376.29167; 2.326670e-003;50.00000;100.00000;2.92925;8
199.66701;376.64167; 1.456000e-003;50.00000;100.00000;2.92923;8
199.67200;376.99167; 8.389583e-004;50.00000;100.00000;2.92922;8
199.67599;377.34167; 3.213311e-004;50.00000;100.00000;2.92921;8
199.67900;377.69167;-5.918083e-005;50.00000;100.00000;2.92920;8
199.68300;378.04167;-3.780418e-004;50.00000;100.00000;2.92919;8
199.68600;378.39167;-5.974831e-004;50.00000;100.00000;2.92918;8
199.68900;378.74167;-7.758000e-004;50.00000;100.00000;2.92917;8
199.69099;379.09167;-9.266651e-004;50.00000;100.00000;2.92916;8
199.69299;379.44167;-1.067250e-003;50.00000;100.00000;2.92916;8
199.69501;379.79167;-1.159854e-003;50.00000;100.00000;2.92915;8
199.69701;380.14167;-1.204479e-003;50.00000;100.00000;2.92915;8
199.69901;380.49167;-1.293657e-003;50.00000;100.00000;2.92914;8
199.70100;380.84167;-1.310864e-003;50.00000;100.00000;2.92914;8
199.70100;381.19167;-1.365699e-003;50.00000;100.00000;2.92914;8
199.70399;381.54167;-1.406933e-003;50.00000;100.00000;2.92913;8
199.70500;381.89167;-1.427532e-003;50.00000;100.00000;2.92912;8
199.70500;382.24167;-1.472086e-003;50.00000;100.00000;2.92912;8
199.70799;382.59167;-1.492757e-003;50.00000;100.00000;2.92912;8
199.70799;382.94167;-1.513320e-003;50.00000;100.00000;2.92912;8
199.70900;383.29167;-1.551056e-003;50.00000;100.00000;2.92911;8
199.70900;383.64167;-1.581900e-003;50.00000;100.00000;2.92911;8
199.71001;383.99167;-1.575082e-003;50.00000;100.00000;2.92911;8
199.71100;384.34167;-1.588827e-003;50.00000;100.00000;2.92911;8
199.71300;384.69167;-1.609463e-003;50.00000;100.00000;2.92910;8
199.71400;385.04167;-1.626635e-003;50.00000;100.00000;2.92910;8
199.71400;385.39167;-1.599217e-003;50.00000;100.00000;2.92910;8
199.71400;385.74167;-1.643771e-003;50.00000;100.00000;2.92910;8
199.71400;386.09167;-1.688325e-003;50.00000;100.00000;2.92910;8
199.71500;386.44167;-1.678079e-003;50.00000;100.00000;2.92910;8
199.71600;386.79167;-1.698679e-003;50.00000;100.00000;2.92909;8
199.71600;387.14167;-1.681543e-003;50.00000;100.00000;2.92909;8
199.71500;387.49167;-1.674652e-003;50.00000;100.00000;2.92910;8
199.71500;387.84167;-1.726060e-003;50.00000;100.00000;2.92910;8
199.71500;388.19167;-1.739769e-003;50.00000;100.00000;2.92910;8
199.71500;388.54167;-1.743197e-003;50.00000;100.00000;2.92910;8
199.71600;388.89167;-1.722670e-003;50.00000;100.00000;2.92909;8
199.71500;389.24167;-1.708924e-003;50.00000;100.00000;2.92910;8
199.71600;389.59167;-1.705533e-003;50.00000;100.00000;2.92909;8
199.71600;389.94167;-1.688397e-003;50.00000;100.00000;2.92909;8
199.71800;390.29167;-1.657625e-003;50.00000;100.00000;2.92909;8
199.71700;390.64167;-1.657588e-003;50.00000;100.00000;2.92909;8
199.71800;390.99167;-1.671334e-003;50.00000;100.00000;2.92909;8
199.71800;391.34167;-1.671334e-003;50.00000;100.00000;2.92909;8
199.71800;391.69167;-1.664479e-003;50.00000;100.00000;2.92909;8
199.71899;392.04167;-1.661088e-003;50.00000;100.00000;2.92909;8
199.71899;392.39167;-1.664515e-003;50.00000;100.00000;2.92909;8
199.72000;392.74167;-1.654270e-003;50.00000;100.00000;2.92908;8
199.71899;393.09167;-1.647379e-003;50.00000;100.00000;2.92909;8
199.71899;393.44167;-1.674797e-003;50.00000;100.00000;2.92909;8
199.71899;393.79167;-1.640525e-003;50.00000;100.00000;2.92909;8
199.72000;394.14167;-1.647415e-003;50.00000;100.00000;2.92908;8
199.72000;394.49167;-1.654270e-003;50.00000;100.00000;2.92908;8
199.72099;394.84167;-1.637170e-003;50.00000;100.00000;2.92908;8
199.72099;395.19167;-1.633742e-003;50.00000;100.00000;2.92908;8
199.72099;395.54167;-1.630315e-003;50.00000;100.00000;2.92908;8
199.72000;395.89167;-1.633706e-003;50.00000;100.00000;2.92908;8
199.72099;396.24167;-1.613179e-003;50.00000;100.00000;2.92908;8
199.72000;396.59167;-1.647415e-003;50.00000;100.00000;2.92908;8
199.72099;396.94167;-1.650879e-003;50.00000;100.00000;2.92908;8
199.71899;397.29167;-1.633670e-003;50.00000;100.00000;2.92909;8
199.72000;397.64167;-1.650842e-003;50.00000;100.00000;2.92908;8
199.72000;397.99167;-1.633706e-003;50.00000;100.00000;2.92908;8
199.72000;398.34167;-1.630279e-003;50.00000;100.00000;2.92908;8
199.72099;398.69167;-1.644024e-003;50.00000;100.00000;2.92908;8
199.72099;399.04167;-1.616606e-003;50.00000;100.00000;2.92908;8
199.72000;399.39167;-1.647415e-003;50.00000;100.00000;2.92908;8
199.72000;399.74167;-1.613143e-003;50.00000;100.00000;2.92908;8
199.71600;400.09333;-1.811778e-003;50.00000;100.00000;2.92909;9
199.14600;400.44333;-2.666952e-002;50.00000;100.00000;2.93069;9
197.80800;400.79333;-8.593073e-002;50.00000;100.00000;2.93440;9
196.03600;401.14333;      -0.15792;50.00000;100.00000;2.93926;9
194.02699;401.49333;      -0.22636;50.00000;100.00000;2.94468;9
191.89000;401.84333;      -0.28383;50.00000;100.00000;2.95035;9
189.68300;402.19333;      -0.32891;50.00000;100.00000;2.95610;9
187.44200;402.54333;      -0.36250;50.00000;100.00000;2.96182;9
185.23100;402.89333;      -0.38490;50.00000;100.00000;2.96735;9
183.11600;403.24333;      -0.39576;50.00000;100.00000;2.97253;9
181.11400;403.59333;      -0.39675;50.00000;100.00000;2.97735;9
179.22400;403.94333;      -0.39071;50.00000;100.00000;2.98180;9
177.43700;404.29333;      -0.38007;50.00000;100.00000;2.98594;9
175.74200;404.64333;      -0.36700;50.00000;100.00000;2.98980;9
174.12399;404.99333;      -0.35297;50.00000;100.00000;2.99341;9
172.57201;405.34333;      -0.33896;50.00000;100.00000;2.99682;9
171.07899;405.69333;      -0.32557;50.00000;100.00000;3.00005;9
169.63400;406.04333;      -0.31311;50.00000;100.00000;3.00312;9
168.23199;406.39333;      -0.30175;50.00000;100.00000;3.00605;9
166.86600;406.74333;      -0.29148;50.00000;100.00000;3.00887;9
165.53600;407.09333;      -0.28222;50.00000;100.00000;3.01156;9
164.23500;407.44333;      -0.27391;50.00000;100.00000;3.01415;9
162.95900;407.79333;      -0.26647;50.00000;100.00000;3.01666;9
161.71100;408.14333;      -0.25974;50.00000;100.00000;3.01907;9
160.48399;408.49333;      -0.25365;50.00000;100.00000;3.02141;9
159.27699;408.84333;      -0.24813;50.00000;100.00000;3.02367;9
158.09100;409.19333;      -0.24304;50.00000;100.00000;3.02585;9
156.92400;409.54333;      -0.23831;50.00000;100.00000;3.02797;9
155.77600;409.89333;      -0.23393;50.00000;100.00000;3.03002;9
154.64301;410.24333;      -0.22981;50.00000;100.00000;3.03201;9
153.52699;410.59333;      -0.22597;50.00000;100.00000;3.03394;9
152.42799;410.94333;      -0.22229;50.00000;100.00000;3.03581;9
151.34399;411.29333;      -0.21883;50.00000;100.00000;3.03763;9
150.27499;411.64333;      -0.21549;50.00000;100.00000;3.03939;9
149.22099;411.99333;      -0.21230;50.00000;100.00000;3.04110;9
148.17999;412.34333;      -0.20924;50.00000;100.00000;3.04277;9
147.15199;412.69333;      -0.20628;50.00000;100.00000;3.04438;9
146.13800;413.04333;      -0.20341;50.00000;100.00000;3.04595;9
145.13800;413.39333;      -0.20065;50.00000;100.00000;3.04747;9
144.14900;413.74333;      -0.19795;50.00000;100.00000;3.04895;9
143.17300;414.09333;      -0.19535;50.00000;100.00000;3.05038;9
142.20900;414.44333;      -0.19282;50.00000;100.00000;3.05177;9
141.25800;414.79333;      -0.19032;50.00000;100.00000;3.05313;9
140.31700;415.14333;      -0.18791;50.00000;100.00000;3.05444;9
139.38901;415.49333;      -0.18557;50.00000;100.00000;3.05572;9
138.47200;415.84333;      -0.18320;50.00000;100.00000;3.05696;9
137.56400;416.19333;      -0.18100;50.00000;100.00000;3.05816;9
136.66901;416.54333;      -0.17878;50.00000;100.00000;3.05933;9
135.78300;416.89333;      -0.17665;50.00000;100.00000;3.06047;9
134.90900;417.24333;      -0.17451;50.00000;100.00000;3.06157;9
134.04401;417.59333;      -0.17248;50.00000;100.00000;3.06264;9
133.18600;417.94333;      -0.17042;50.00000;100.00000;3.06369;9
132.34200;418.29333;      -0.16848;50.00000;100.00000;3.06470;9
131.50600;418.64333;      -0.16655;50.00000;100.00000;3.06568;9
130.67799;418.99333;      -0.16465;50.00000;100.00000;3.06663;9
129.85899;419.34333;      -0.16283;50.00000;100.00000;3.06756;9
129.05200;419.69333;      -0.16103;50.00000;100.00000;3.06845;9
128.25301;420.04333;      -0.15927;50.00000;100.00000;3.06932;9
127.46100;420.39333;      -0.15755;50.00000;100.00000;3.07017;9
126.68000;420.74333;      -0.15584;50.00000;100.00000;3.07099;9
125.90600;421.09333;      -0.15416;50.00000;100.00000;3.07179;9
125.17600;421.42667;      -0.15258;50.00000;100.00000;3.07253;9