File: examples/data/B_2.txt
#EXPORTTYPE:DATA ALL
#FILE:
#FORMAT:NETZSCH5
#FTYPE:ANSI
#IDENTITY:
#DECIMAL:POINT
#SEPARATOR:SEMICOLON
#MTYPE:DSC
#INSTRUMENT:NETZSCH DSC 200F3
#PROJECT:
#DATE/TIME:13.05.2025 15:53
#CORR. FILE:
#TEMPCAL:temp_cal_5Kmin.ngb-td5
#SENSITIVITY:sens_cal_5Kmin.ngb-ed5
#LABORATORY:
#OPERATOR:
#REMARK:tot 1433.2
#SAMPLE:
#SAMPLE MASS /mg:75.2
#MATERIAL:
#REFERENCE:Ref.
#REFERENCE MASS /mg:0
#TYPE OF CRUCIBLE:High pressure, steel
#SAMPLE CRUCIBLE MASS /mg:1358.4
#REFERENCE CRUCIBLE MASS /mg:1385.5
#M.RANGE /�V:5000
#TAU-R:---
#CORR. CODE:000
#EXO:-1
#RANGE:25�C....200�C/-7.0....7.0K/min
#SEGMENT:S1-5/5
#SEG. 1:25�C/7.0(K/min)/50�C
#SEG. 2:50�C/00:15/50�C
#SEG. 3:50�C/5.0(K/min)/200�C
#SEG. 4:200�C/00:30/200�C
#SEG. 5:200�C/7.0(K/min)/50�C

##Temp./C;Time/min;DSC/(mW/mg);Gas Flow(purge2)/(ml/min);Gas Flow(protective)/(ml/min);Sensit./(uV/mW);Segment
 47.80600; 0.00000; 0.32816;50.00000;100.00000;3.07231;1
 47.82500; 0.13333; 0.29429;50.00000;100.00000;3.07232;1
 47.83900; 0.26667; 0.26412;50.00000;100.00000;3.07234;1
 47.84900; 0.40000; 0.23676;50.00000;100.00000;3.07235;1
 47.85600; 0.53333; 0.21202;50.00000;100.00000;3.07236;1
 47.85900; 0.66667; 0.18961;50.00000;100.00000;3.07236;1
 47.85700; 0.80000; 0.16927;50.00000;100.00000;3.07236;1
 47.85200; 0.93333; 0.15079;50.00000;100.00000;3.07235;1
 47.84400; 1.06667; 0.13398;50.00000;100.00000;3.07234;1
 47.83400; 1.20000; 0.11875;50.00000;100.00000;3.07233;1
 47.81900; 1.33333; 0.10486;50.00000;100.00000;3.07232;1
 47.80300; 1.46667; 9.224983e-002;50.00000;100.00000;3.07230;1
 47.78500; 1.60000; 8.078884e-002;50.00000;100.00000;3.07228;1
 47.76400; 1.73333; 7.035819e-002;50.00000;100.00000;3.07226;1
 47.74100; 1.86667; 6.087857e-002;50.00000;100.00000;3.07224;1
 47.71600; 2.00000; 5.225421e-002;50.00000;100.00000;3.07221;1
 47.69000; 2.13333; 4.439590e-002;50.00000;100.00000;3.07219;1
 47.66300; 2.26667; 3.727394e-002;50.00000;100.00000;3.07216;1
 47.63300; 2.40000; 3.080586e-002;50.00000;100.00000;3.07213;1
 47.60300; 2.53333; 2.488586e-002;50.00000;100.00000;3.07210;1
 47.57200; 2.66667; 1.948428e-002;50.00000;100.00000;3.07207;1
 47.53900; 2.80000; 1.456813e-002;50.00000;100.00000;3.07204;1
 47.50700; 2.93333; 1.007457e-002;50.00000;100.00000;3.07200;1
 47.47500; 3.06667; 6.172075e-003;50.00000;100.00000;3.07197;1
 47.46400; 3.20000; 3.794588e-003;50.00000;100.00000;3.07196;1
 47.50700; 3.33333; 5.163663e-003;50.00000;100.00000;3.07200;1
 47.64700; 3.46667; 1.289300e-002;50.00000;100.00000;3.07215;1
 47.87700; 3.58750; 2.685579e-002;50.00000;100.00000;3.07238;2
 48.22000; 3.72083; 4.845488e-002;50.00000;100.00000;3.07272;2
 48.55200; 3.85417; 6.940936e-002;50.00000;100.00000;3.07305;2
 48.83500; 3.98750; 8.571117e-002;50.00000;100.00000;3.07333;2
 49.07000; 4.12083; 9.693648e-002;50.00000;100.00000;3.07356;2
 49.26300; 4.25417; 0.10353;50.00000;100.00000;3.07374;2
 49.41600; 4.38750; 0.10633;50.00000;100.00000;3.07389;2
 49.53600; 4.52083; 0.10602;50.00000;100.00000;3.07401;2
 49.62900; 4.65417; 0.10343;50.00000;100.00000;3.07410;2
 49.70000; 4.78750; 9.917348e-002;50.00000;100.00000;3.07416;2
 49.75300; 4.92083; 9.377429e-002;50.00000;100.00000;3.07421;2
 49.79800; 5.05417; 8.773223e-002;50.00000;100.00000;3.07426;2
 49.83000; 5.18750; 8.139078e-002;50.00000;100.00000;3.07429;2
 49.85400; 5.32083; 7.499382e-002;50.00000;100.00000;3.07431;2
 49.87400; 5.45417; 6.871598e-002;50.00000;100.00000;3.07433;2
 49.89100; 5.58750; 6.269577e-002;50.00000;100.00000;3.07435;2
 49.90300; 5.72083; 5.696958e-002;50.00000;100.00000;3.07436;2
 49.91300; 5.85417; 5.163624e-002;50.00000;100.00000;3.07437;2
 49.92200; 5.98750; 4.678149e-002;50.00000;100.00000;3.07438;2
 49.93200; 6.12083; 4.233591e-002;50.00000;100.00000;3.07439;2
 49.93900; 6.25417; 3.818419e-002;50.00000;100.00000;3.07439;2
 49.94600; 6.38750; 3.448129e-002;50.00000;100.00000;3.07440;2
 49.95200; 6.52083; 3.105234e-002;50.00000;100.00000;3.07440;2
 49.95700; 6.65417; 2.797325e-002;50.00000;100.00000;3.07441;2
 49.96100; 6.78750; 2.513181e-002;50.00000;100.00000;3.07441;2
 49.96500; 6.92083; 2.253787e-002;50.00000;100.00000;3.07442;2
 49.97100; 7.05417; 2.022436e-002;50.00000;100.00000;3.07442;2
 49.97300; 7.18750; 1.815520e-002;50.00000;100.00000;3.07442;2
 49.97600; 7.32083; 1.624441e-002;50.00000;100.00000;3.07443;2
 49.98000; 7.45417; 1.454148e-002;50.00000;100.00000;3.07443;2
 49.98200; 7.58750; 1.298713e-002;50.00000;100.00000;3.07443;2
 49.98600; 7.72083; 1.160761e-002;50.00000;100.00000;3.07444;2
 49.98900; 7.85417; 1.037992e-002;50.00000;100.00000;3.07444;2
 49.99200; 7.98750; 9.205029e-003;50.00000;100.00000;3.07444;2
 49.99200; 8.12083; 8.112749e-003;50.00000;100.00000;3.07444;2
 49.99400; 8.25417; 7.135896e-003;50.00000;100.00000;3.07444;2
 49.99600; 8.38750; 6.228342e-003;50.00000;100.00000;3.07445;2
 49.99500; 8.52083; 5.456192e-003;50.00000;100.00000;3.07445;2
 49.99800; 8.65417; 4.700403e-003;50.00000;100.00000;3.07445;2
 49.99900; 8.78750; 4.030482e-003;50.00000;100.00000;3.07445;2
 49.99800; 8.92083; 3.416729e-003;50.00000;100.00000;3.07445;2
 50.00000; 9.05417; 2.888671e-003;50.00000;100.00000;3.07445;2
 50.00000; 9.18750; 2.387081e-003;50.00000;100.00000;3.07445;2
 50.00200; 9.32083; 1.882124e-003;50.00000;100.00000;3.07445;2
 50.00000; 9.45417; 1.449901e-003;50.00000;100.00000;3.07445;2
 49.99800; 9.58750; 1.024277e-003;50.00000;100.00000;3.07445;2
 49.99900; 9.72083; 6.480509e-004;50.00000;100.00000;3.07445;2
 49.99900; 9.85417; 2.949581e-004;50.00000;100.00000;3.07445;2
 49.99700; 9.98750;-1.516894e-005;50.00000;100.00000;3.07445;2
 49.99900;10.12083;-2.693303e-004;50.00000;100.00000;3.07445;2
 49.99700;10.25417;-4.969594e-004;50.00000;100.00000;3.07445;2
 49.99700;10.38750;-7.213549e-004;50.00000;100.00000;3.07445;2
 49.99800;10.52083;-8.731850e-004;50.00000;100.00000;3.07445;2
 49.99700;10.65417;-1.028249e-003;50.00000;100.00000;3.07445;2
 49.99700;10.78750;-1.143747e-003;50.00000;100.00000;3.07445;2
 49.99700;10.92083;-1.193246e-003;50.00000;100.00000;3.07445;2
 50.00000;11.05417;-1.289042e-003;50.00000;100.00000;3.07445;2
 50.00000;11.18750;-1.361641e-003;50.00000;100.00000;3.07445;2
 50.00000;11.32083;-1.397940e-003;50.00000;100.00000;3.07445;2
 49.99900;11.45417;-1.454006e-003;50.00000;100.00000;3.07445;2
 50.00000;11.58750;-1.526637e-003;50.00000;100.00000;3.07445;2
 50.00000;11.72083;-1.559637e-003;50.00000;100.00000;3.07445;2
 49.99900;11.85417;-1.602503e-003;50.00000;100.00000;3.07445;2
 50.00000;11.98750;-1.658635e-003;50.00000;100.00000;3.07445;2
 50.00000;12.12083;-1.734533e-003;50.00000;100.00000;3.07445;2
 50.00100;12.25417;-1.800565e-003;50.00000;100.00000;3.07445;2
 50.00000;12.38750;-1.820331e-003;50.00000;100.00000;3.07445;2
 50.00100;12.52083;-1.863263e-003;50.00000;100.00000;3.07445;2
 50.00000;12.65417;-1.922629e-003;50.00000;100.00000;3.07445;2
 50.00000;12.78750;-2.011727e-003;50.00000;100.00000;3.07445;2
 50.00000;12.92083;-2.038127e-003;50.00000;100.00000;3.07445;2
 50.00000;13.05417;-2.057926e-003;50.00000;100.00000;3.07445;2
 50.00000;13.18750;-2.097526e-003;50.00000;100.00000;3.07445;2
 50.00100;13.32083;-2.107458e-003;50.00000;100.00000;3.07445;2
 49.99900;13.45417;-2.113993e-003;50.00000;100.00000;3.07445;2
 49.99900;13.58750;-2.127192e-003;50.00000;100.00000;3.07445;2
 49.99900;13.72083;-2.133792e-003;50.00000;100.00000;3.07445;2
 50.00000;13.85417;-2.150324e-003;50.00000;100.00000;3.07445;2
 50.00000;13.98750;-2.166824e-003;50.00000;100.00000;3.07445;2
 50.00000;14.12083;-2.176724e-003;50.00000;100.00000;3.07445;2
 49.99900;14.25417;-2.186591e-003;50.00000;100.00000;3.07445;2
 49.99900;14.38750;-2.209691e-003;50.00000;100.00000;3.07445;2
 49.99800;14.52083;-2.232758e-003;50.00000;100.00000;3.07445;2
 49.99900;14.65417;-2.222890e-003;50.00000;100.00000;3.07445;2
 49.99900;14.78750;-2.222890e-003;50.00000;100.00000;3.07445;2
 49.99800;14.92083;-2.193158e-003;50.00000;100.00000;3.07445;2
 50.00000;15.05417;-2.196523e-003;50.00000;100.00000;3.07445;2
 49.99900;15.18750;-2.160192e-003;50.00000;100.00000;3.07445;2
 50.00100;15.32083;-2.170157e-003;50.00000;100.00000;3.07445;2
 50.00100;15.45417;-2.147057e-003;50.00000;100.00000;3.07445;2
 50.00100;15.58750;-2.137157e-003;50.00000;100.00000;3.07445;2
 50.00100;15.72083;-2.137157e-003;50.00000;100.00000;3.07445;2
 50.00000;15.85417;-2.140425e-003;50.00000;100.00000;3.07445;2
 49.99900;15.98750;-2.179991e-003;50.00000;100.00000;3.07445;2
 50.00000;16.12083;-2.170124e-003;50.00000;100.00000;3.07445;2
 50.00000;16.25417;-2.199823e-003;50.00000;100.00000;3.07445;2
 50.00000;16.38750;-2.170124e-003;50.00000;100.00000;3.07445;2
 50.00000;16.52083;-2.186624e-003;50.00000;100.00000;3.07445;2
 50.00000;16.65417;-2.206423e-003;50.00000;100.00000;3.07445;2
 50.00000;16.78750;-2.186624e-003;50.00000;100.00000;3.07445;2
 50.00100;16.92083;-2.160257e-003;50.00000;100.00000;3.07445;2
 50.00000;17.05417;-2.176724e-003;50.00000;100.00000;3.07445;2
 50.00000;17.18750;-2.186624e-003;50.00000;100.00000;3.07445;2
 50.00000;17.32083;-2.209723e-003;50.00000;100.00000;3.07445;2
 50.00200;17.45417;-2.203189e-003;50.00000;100.00000;3.07445;2
 50.00100;17.58750;-2.193256e-003;50.00000;100.00000;3.07445;2
 50.00000;17.72083;-2.206423e-003;50.00000;100.00000;3.07445;2
 50.00000;17.85417;-2.216323e-003;50.00000;100.00000;3.07445;2
 50.00300;17.98750;-2.206521e-003;50.00000;100.00000;3.07445;2
 50.00200;18.12083;-2.193289e-003;50.00000;100.00000;3.07445;2
 50.00100;18.25417;-2.199856e-003;50.00000;100.00000;3.07445;2
 50.00200;18.38750;-2.206489e-003;50.00000;100.00000;3.07445;2
 50.00300;18.52083;-2.242820e-003;50.00000;100.00000;3.07445;2
 50.00300;18.65583;-2.239520e-003;50.00000;100.00000;3.07445;3
 50.03200;18.78917;-6.664145e-004;50.00000;100.00000;3.07448;3
 50.14200;18.92250; 5.873422e-003;50.00000;100.00000;3.07458;3
 50.35000;19.05583; 1.900833e-002;50.00000;100.00000;3.07478;3
 50.65300;19.18917; 3.826754e-002;50.00000;100.00000;3.07506;3
 51.03500;19.32250; 6.222676e-002;50.00000;100.00000;3.07542;3
 51.47700;19.45583; 8.910605e-002;50.00000;100.00000;3.07582;3
 51.96700;19.58917; 0.11743;50.00000;100.00000;3.07627;3
 52.49000;19.72250; 0.14610;50.00000;100.00000;3.07673;3
 53.04000;19.85583; 0.17424;50.00000;100.00000;3.07722;3
 53.60900;19.98917; 0.20131;50.00000;100.00000;3.07771;3
 54.19200;20.12250; 0.22701;50.00000;100.00000;3.07820;3
 54.78800;20.25583; 0.25125;50.00000;100.00000;3.07870;3
 55.39700;20.38917; 0.27388;50.00000;100.00000;3.07920;3
 56.01300;20.52250; 0.29491;50.00000;100.00000;3.07970;3
 56.63400;20.65583; 0.31428;50.00000;100.00000;3.08018;3
 57.26000;20.78917; 0.33210;50.00000;100.00000;3.08067;3
 57.89300;20.92250; 0.34845;50.00000;100.00000;3.08114;3
 58.53100;21.05583; 0.36347;50.00000;100.00000;3.08162;3
 59.17200;21.18917; 0.37724;50.00000;100.00000;3.08208;3
 59.81500;21.32250; 0.38978;50.00000;100.00000;3.08253;3
 60.46400;21.45583; 0.40127;50.00000;100.00000;3.08298;3
 61.11300;21.58917; 0.41168;50.00000;100.00000;3.08341;3
 61.76500;21.72250; 0.42113;50.00000;100.00000;3.08384;3
 62.41800;21.85583; 0.42978;50.00000;100.00000;3.08426;3
 63.07600;21.98917; 0.43757;50.00000;100.00000;3.08467;3
 63.73400;22.12250; 0.44468;50.00000;100.00000;3.08506;3
 64.39200;22.25583; 0.45112;50.00000;100.00000;3.08545;3
 65.05100;22.38917; 0.45692;50.00000;100.00000;3.08583;3
 65.71100;22.52250; 0.46216;50.00000;100.00000;3.08619;3
 66.37300;22.65583; 0.46689;50.00000;100.00000;3.08654;3
 67.03500;22.78917; 0.47111;50.00000;100.00000;3.08689;3
 67.69900;22.92250; 0.47495;50.00000;100.00000;3.08722;3
 68.36100;23.05583; 0.47840;50.00000;100.00000;3.08754;3
 69.02500;23.18917; 0.48147;50.00000;100.00000;3.08785;3
 69.69000;23.32250; 0.48422;50.00000;100.00000;3.08815;3
 70.35400;23.45583; 0.48673;50.00000;100.00000;3.08844;3
 71.01800;23.58917; 0.48896;50.00000;100.00000;3.08871;3
 71.68400;23.72250; 0.49094;50.00000;100.00000;3.08898;3
 72.35100;23.85583; 0.49273;50.00000;100.00000;3.08923;3
 73.01700;23.98917; 0.49434;50.00000;100.00000;3.08947;3
 73.68500;24.12250; 0.49576;50.00000;100.00000;3.08971;3
 74.35100;24.25583; 0.49701;50.00000;100.00000;3.08992;3
 75.01700;24.38917; 0.49813;50.00000;100.00000;3.09013;3
 75.68300;24.52250; 0.49909;50.00000;100.00000;3.09033;3
 76.35100;24.65583; 0.49997;50.00000;100.00000;3.09051;3
 77.01600;24.78917; 0.50076;50.00000;100.00000;3.09068;3
 77.68600;24.92250; 0.50139;50.00000;100.00000;3.09085;3
 78.35200;25.05583; 0.50195;50.00000;100.00000;3.09099;3
 79.01900;25.18917; 0.50247;50.00000;100.00000;3.09113;3
 79.68800;25.32250; 0.50298;50.00000;100.00000;3.09126;3
 80.35500;25.45583; 0.50338;50.00000;100.00000;3.09137;3
 81.02200;25.58917; 0.50367;50.00000;100.00000;3.09148;3
 81.69000;25.72250; 0.50392;50.00000;100.00000;3.09157;3
 82.35800;25.85583; 0.50413;50.00000;100.00000;3.09165;3
 83.02500;25.98917; 0.50435;50.00000;100.00000;3.09172;3
 83.69600;26.12250; 0.50451;50.00000;100.00000;3.09177;3
 84.36200;26.25583; 0.50464;50.00000;100.00000;3.09182;3
 85.02900;26.38917; 0.50475;50.00000;100.00000;3.09185;3
 85.69800;26.52250; 0.50483;50.00000;100.00000;3.09187;3
 86.36600;26.65583; 0.50486;50.00000;100.00000;3.09188;3
 87.03400;26.78917; 0.50492;50.00000;100.00000;3.09188;3
 87.70300;26.92250; 0.50498;50.00000;100.00000;3.09187;3
 88.37200;27.05583; 0.50501;50.00000;100.00000;3.09184;3
 89.03900;27.18917; 0.50501;50.00000;100.00000;3.09181;3
 89.70600;27.32250; 0.50494;50.00000;100.00000;3.09176;3
 90.37600;27.45583; 0.50493;50.00000;100.00000;3.09170;3
 91.04600;27.58917; 0.50492;50.00000;100.00000;3.09163;3
 91.71400;27.72250; 0.50489;50.00000;100.00000;3.09154;3
 92.38100;27.85583; 0.50479;50.00000;100.00000;3.09145;3
 93.05100;27.98917; 0.50474;50.00000;100.00000;3.09134;3
 93.71900;28.12250; 0.50462;50.00000;100.00000;3.09123;3
 94.38700;28.25583; 0.50454;50.00000;100.00000;3.09110;3
 95.05400;28.38917; 0.50442;50.00000;100.00000;3.09095;3
 95.72200;28.52250; 0.50431;50.00000;100.00000;3.09080;3
 96.39100;28.65583; 0.50424;50.00000;100.00000;3.09064;3
 97.06000;28.78917; 0.50416;50.00000;100.00000;3.09046;3
 97.72800;28.92250; 0.50404;50.00000;100.00000;3.09027;3
 98.39400;29.05583; 0.50391;50.00000;100.00000;3.09007;3
 99.06300;29.18917; 0.50378;50.00000;100.00000;3.08986;3
 99.73100;29.32250; 0.50370;50.00000;100.00000;3.08964;3
100.40100;29.45583; 0.50362;50.00000;100.00000;3.08940;3
101.06800;29.58917; 0.50350;50.00000;100.00000;3.08916;3
101.73600;29.72250; 0.50340;50.00000;100.00000;3.08890;3
102.40300;29.85583; 0.50331;50.00000;100.00000;3.08863;3
103.07200;29.98917; 0.50320;50.00000;100.00000;3.08835;3
103.74100;30.12250; 0.50309;50.00000;100.00000;3.08806;3
104.41100;30.25583; 0.50301;50.00000;100.00000;3.08775;3
105.07800;30.38917; 0.50296;50.00000;100.00000;3.08744;3
105.74500;30.52250; 0.50287;50.00000;100.00000;3.08711;3
106.41400;30.65583; 0.50278;50.00000;100.00000;3.08677;3
107.08500;30.78917; 0.50265;50.00000;100.00000;3.08642;3
107.75100;30.92250; 0.50252;50.00000;100.00000;3.08606;3
108.41900;31.05583; 0.50242;50.00000;100.00000;3.08568;3
109.08700;31.18917; 0.50229;50.00000;100.00000;3.08530;3
109.75500;31.32250; 0.50215;50.00000;100.00000;3.08490;3
110.42300;31.45583; 0.50205;50.00000;100.00000;3.08449;3
111.09200;31.58917; 0.50199;50.00000;100.00000;3.08407;3
111.76000;31.72250; 0.50197;50.00000;100.00000;3.08364;3
112.43000;31.85583; 0.50190;50.00000;100.00000;3.08319;3
113.09800;31.98917; 0.50182;50.00000;100.00000;3.08274;3
113.76600;32.12250; 0.50176;50.00000;100.00000;3.08227;3
114.43400;32.25583; 0.50162;50.00000;100.00000;3.08179;3
115.10100;32.38917; 0.50147;50.00000;100.00000;3.08131;3
115.76800;32.52250; 0.50133;50.00000;100.00000;3.08081;3
116.43600;32.65583; 0.50125;50.00000;100.00000;3.08029;3
117.10500;32.78917; 0.50119;50.00000;100.00000;3.07977;3
117.77200;32.92250; 0.50116;50.00000;100.00000;3.07923;3
118.44100;33.05583; 0.50115;50.00000;100.00000;3.07869;3
119.11000;33.18917; 0.50106;50.00000;100.00000;3.07813;3
119.77800;33.32250; 0.50101;50.00000;100.00000;3.07756;3
120.44600;33.45583; 0.50093;50.00000;100.00000;3.07697;3
121.11400;33.58917; 0.50088;50.00000;100.00000;3.07638;3
121.78100;33.72250; 0.50080;50.00000;100.00000;3.07578;3
122.45000;33.85583; 0.50070;50.00000;100.00000;3.07516;3
123.11600;33.98917; 0.50067;50.00000;100.00000;3.07453;3
123.78500;34.12250; 0.50060;50.00000;100.00000;3.07389;3
124.45300;34.25583; 0.50056;50.00000;100.00000;3.07324;3
125.12100;34.38917; 0.50047;50.00000;100.00000;3.07258;3
125.79000;34.52250; 0.50046;50.00000;100.00000;3.07191;3
126.45900;34.65583; 0.50047;50.00000;100.00000;3.07122;3
127.12500;34.78917; 0.50040;50.00000;100.00000;3.07053;3
127.79300;34.92250; 0.50031;50.00000;100.00000;3.06982;3
128.46001;35.05583; 0.50022;50.00000;100.00000;3.06910;3
129.12900;35.18917; 0.50016;50.00000;100.00000;3.06837;3
129.79601;35.32250; 0.50015;50.00000;100.00000;3.06763;3
130.46300;35.45583; 0.50011;50.00000;100.00000;3.06688;3
131.13300;35.58917; 0.50010;50.00000;100.00000;3.06611;3
131.80000;35.72250; 0.50009;50.00000;100.00000;3.06533;3
132.46700;35.85583; 0.50002;50.00000;100.00000;3.06455;3
133.13400;35.98917; 0.49996;50.00000;100.00000;3.06375;3
133.80000;36.12250; 0.49995;50.00000;100.00000;3.06294;3
134.47000;36.25583; 0.50003;50.00000;100.00000;3.06212;3
135.14000;36.38917; 0.50009;50.00000;100.00000;3.06128;3
135.80701;36.52250; 0.50007;50.00000;100.00000;3.06044;3
136.47701;36.65583; 0.50007;50.00000;100.00000;3.05958;3
137.14301;36.78917; 0.50001;50.00000;100.00000;3.05872;3
137.81100;36.92250; 0.49998;50.00000;100.00000;3.05784;3
138.47900;37.05583; 0.50001;50.00000;100.00000;3.05695;3
139.14700;37.18917; 0.50002;50.00000;100.00000;3.05605;3
139.81400;37.32250; 0.50006;50.00000;100.00000;3.05514;3
140.48399;37.45583; 0.50005;50.00000;100.00000;3.05421;3
141.15199;37.58917; 0.50002;50.00000;100.00000;3.05328;3
141.81599;37.72250; 0.49991;50.00000;100.00000;3.05234;3
142.48500;37.85583; 0.49997;50.00000;100.00000;3.05138;3
143.15300;37.98917; 0.49999;50.00000;100.00000;3.05041;3
143.82201;38.12250; 0.50002;50.00000;100.00000;3.04943;3
144.48801;38.25583; 0.49992;50.00000;100.00000;3.04844;3
145.15401;38.38917; 0.49988;50.00000;100.00000;3.04744;3
145.82300;38.52250; 0.49988;50.00000;100.00000;3.04643;3
146.48801;38.65583; 0.49987;50.00000;100.00000;3.04541;3
147.15900;38.78917; 0.49988;50.00000;100.00000;3.04437;3
147.82500;38.92250; 0.49996;50.00000;100.00000;3.04333;3
148.49400;39.05583; 0.49997;50.00000;100.00000;3.04227;3
149.16200;39.18917; 0.49997;50.00000;100.00000;3.04120;3
149.82800;39.32250; 0.49995;50.00000;100.00000;3.04012;3
150.49699;39.45583; 0.49992;50.00000;100.00000;3.03903;3
151.16499;39.58917; 0.49990;50.00000;100.00000;3.03793;3
151.83200;39.72250; 0.49992;50.00000;100.00000;3.03682;3
152.50000;39.85583; 0.49996;50.00000;100.00000;3.03569;3
153.16701;39.98917; 0.50001;50.00000;100.00000;3.03456;3
153.83501;40.12250; 0.50014;50.00000;100.00000;3.03341;3
154.50400;40.25583; 0.50018;50.00000;100.00000;3.03225;3
155.17101;40.38917; 0.50020;50.00000;100.00000;3.03109;3
155.83800;40.52250; 0.50030;50.00000;100.00000;3.02991;3
156.50600;40.65583; 0.50039;50.00000;100.00000;3.02872;3
157.17500;40.78917; 0.50046;50.00000;100.00000;3.02752;3
157.84100;40.92250; 0.50055;50.00000;100.00000;3.02631;3
158.50800;41.05583; 0.50058;50.00000;100.00000;3.02509;3
159.17599;41.18917; 0.50059;50.00000;100.00000;3.02385;3
159.84300;41.32250; 0.50064;50.00000;100.00000;3.02261;3
160.50999;41.45583; 0.50070;50.00000;100.00000;3.02136;3
161.17700;41.58917; 0.50075;50.00000;100.00000;3.02009;3
161.84599;41.72250; 0.50081;50.00000;100.00000;3.01881;3
162.51300;41.85583; 0.50086;50.00000;100.00000;3.01753;3
163.18100;41.98917; 0.50091;50.00000;100.00000;3.01623;3
163.84700;42.12250; 0.50096;50.00000;100.00000;3.01492;3
164.51700;42.25583; 0.50101;50.00000;100.00000;3.01360;3
165.18300;42.38917; 0.50114;50.00000;100.00000;3.01227;3
165.85001;42.52250; 0.50122;50.00000;100.00000;3.01093;3
166.51801;42.65583; 0.50131;50.00000;100.00000;3.00957;3
167.18500;42.78917; 0.50139;50.00000;100.00000;3.00821;3
167.85300;42.92250; 0.50144;50.00000;100.00000;3.00684;3
168.51900;43.05583; 0.50149;50.00000;100.00000;3.00546;3
169.18800;43.18917; 0.50163;50.00000;100.00000;3.00406;3
169.85600;43.32250; 0.50172;50.00000;100.00000;3.00265;3
170.52200;43.45583; 0.50181;50.00000;100.00000;3.00124;3
171.19000;43.58917; 0.50192;50.00000;100.00000;2.99981;3
171.85699;43.72250; 0.50200;50.00000;100.00000;2.99837;3
172.52400;43.85583; 0.50225;50.00000;100.00000;2.99693;3
173.19200;43.98917; 0.50235;50.00000;100.00000;2.99547;3
173.85800;44.12250; 0.50245;50.00000;100.00000;2.99400;3
174.52600;44.25583; 0.50255;50.00000;100.00000;2.99252;3
175.19200;44.38917; 0.50266;50.00000;100.00000;2.99103;3
175.86000;44.52250; 0.50276;50.00000;100.00000;2.98953;3
176.52699;44.65583; 0.50289;50.00000;100.00000;2.98802;3
177.19299;44.78917; 0.50298;50.00000;100.00000;2.98650;3
177.85899;44.92250; 0.50308;50.00000;100.00000;2.98497;3
178.52901;45.05583; 0.50324;50.00000;100.00000;2.98342;3
179.19701;45.18917; 0.50337;50.00000;100.00000;2.98187;3
179.86400;45.32250; 0.50352;50.00000;100.00000;2.98030;3
180.53101;45.45583; 0.50367;50.00000;100.00000;2.97873;3
181.19901;45.58917; 0.50379;50.00000;100.00000;2.97714;3
181.86400;45.72250; 0.50385;50.00000;100.00000;2.97555;3
182.53101;45.85583; 0.50392;50.00000;100.00000;2.97395;3
183.20000;45.98917; 0.50409;50.00000;100.00000;2.97233;3
183.86700;46.12250; 0.50424;50.00000;100.00000;2.97071;3
184.53300;46.25583; 0.50436;50.00000;100.00000;2.96907;3
185.20100;46.38917; 0.50451;50.00000;100.00000;2.96742;3
185.86700;46.52250; 0.50466;50.00000;100.00000;2.96577;3
186.53400;46.65583; 0.50482;50.00000;100.00000;2.96410;3
187.20100;46.78917; 0.50496;50.00000;100.00000;2.96243;3
187.86800;46.92250; 0.50509;50.00000;100.00000;2.96074;3
188.53500;47.05583; 0.50523;50.00000;100.00000;2.95904;3
189.20200;47.18917; 0.50536;50.00000;100.00000;2.95734;3
189.86900;47.32250; 0.50551;50.00000;100.00000;2.95562;3
190.53400;47.45583; 0.50569;50.00000;100.00000;2.95390;3
191.20200;47.58917; 0.50589;50.00000;100.00000;2.95216;3
191.86800;47.72250; 0.50610;50.00000;100.00000;2.95041;3
192.53500;47.85583; 0.50634;50.00000;100.00000;2.94865;3
193.20200;47.98917; 0.50654;50.00000;100.00000;2.94689;3
193.87000;48.12250; 0.50676;50.00000;100.00000;2.94510;3
194.53600;48.25583; 0.50702;50.00000;100.00000;2.94332;3
195.20399;48.38917; 0.50727;50.00000;100.00000;2.94152;3
195.87100;48.52250; 0.50748;50.00000;100.00000;2.93971;3
196.53900;48.65750; 0.50743;50.00000;100.00000;2.93789;4
197.10500;48.79083; 0.50017;50.00000;100.00000;2.93634;4
197.54300;48.92417; 0.48140;50.00000;100.00000;2.93513;4
197.88300;49.05750; 0.45496;50.00000;100.00000;2.93420;4
198.15800;49.19083; 0.42444;50.00000;100.00000;2.93344;4
198.38100;49.32417; 0.39224;50.00000;100.00000;2.93282;4
198.56500;49.45750; 0.35982;50.00000;100.00000;2.93231;4
198.71500;49.59083; 0.32812;50.00000;100.00000;2.93189;4
198.84200;49.72417; 0.29783;50.00000;100.00000;2.93154;4
198.95100;49.85750; 0.26933;50.00000;100.00000;2.93123;4
199.04201;49.99083; 0.24263;50.00000;100.00000;2.93098;4
199.11900;50.12417; 0.21796;50.00000;100.00000;2.93076;4
199.18500;50.25750; 0.19534;50.00000;100.00000;2.93058;4
199.24001;50.39083; 0.17464;50.00000;100.00000;2.93043;4
199.28799;50.52417; 0.15578;50.00000;100.00000;2.93029;4
199.33200;50.65750; 0.13861;50.00000;100.00000;2.93017;4
199.36700;50.79083; 0.12317;50.00000;100.00000;2.93007;4
199.39799;50.92417; 0.10928;50.00000;100.00000;2.92998;4
199.42599;51.05750; 9.670465e-002;50.00000;100.00000;2.92991;4
199.45000;51.19083; 8.543112e-002;50.00000;100.00000;2.92984;4
199.47000;51.32417; 7.531354e-002;50.00000;100.00000;2.92978;4
199.49100;51.45750; 6.626910e-002;50.00000;100.00000;2.92972;4
199.50700;51.59083; 5.814536e-002;50.00000;100.00000;2.92968;4
199.52100;51.72417; 5.091828e-002;50.00000;100.00000;2.92964;4
199.53400;51.85750; 4.441131e-002;50.00000;100.00000;2.92960;4
199.54300;51.99083; 3.861066e-002;50.00000;100.00000;2.92958;4
199.55400;52.12417; 3.351292e-002;50.00000;100.00000;2.92955;4
199.56400;52.25750; 2.895187e-002;50.00000;100.00000;2.92952;4
199.57201;52.39083; 2.486176e-002;50.00000;100.00000;2.92950;4
199.58000;52.52417; 2.132224e-002;50.00000;100.00000;2.92947;4
199.58900;52.65750; 1.817745e-002;50.00000;100.00000;2.92945;4
199.59500;52.79083; 1.537209e-002;50.00000;100.00000;2.92943;4
199.60100;52.92417; 1.287145e-002;50.00000;100.00000;2.92942;4
199.60699;53.05750; 1.062362e-002;50.00000;100.00000;2.92940;4
199.61099;53.19083; 8.590537e-003;50.00000;100.00000;2.92939;4
199.61600;53.32417; 6.799847e-003;50.00000;100.00000;2.92937;4
199.62000;53.45750; 5.192728e-003;50.00000;100.00000;2.92936;4
199.62399;53.59083; 3.786473e-003;50.00000;100.00000;2.92935;4
199.62700;53.72417; 2.560337e-003;50.00000;100.00000;2.92934;4
199.62900;53.85750; 1.465837e-003;50.00000;100.00000;2.92934;4
199.63400;53.99083; 5.132292e-004;50.00000;100.00000;2.92932;4
199.63800;54.12417;-3.354495e-004;50.00000;100.00000;2.92931;4
199.64000;54.25750;-1.052452e-003;50.00000;100.00000;2.92931;4
199.64200;54.39083;-1.765993e-003;50.00000;100.00000;2.92930;4
199.64301;54.52417;-2.417158e-003;50.00000;100.00000;2.92930;4
199.64600;54.65750;-2.985277e-003;50.00000;100.00000;2.92929;4
199.64900;54.79083;-3.439105e-003;50.00000;100.00000;2.92928;4
199.64999;54.92417;-3.924030e-003;50.00000;100.00000;2.92928;4
199.65300;55.05750;-4.232396e-003;50.00000;100.00000;2.92927;4
199.65500;55.19083;-4.457600e-003;50.00000;100.00000;2.92926;4
199.65900;55.32417;-4.717520e-003;50.00000;100.00000;2.92925;4
199.65900;55.45750;-4.963429e-003;50.00000;100.00000;2.92925;4
199.66000;55.59083;-5.254403e-003;50.00000;100.00000;2.92925;4
199.66299;55.72417;-5.438089e-003;50.00000;100.00000;2.92924;4
199.66299;55.85750;-5.600874e-003;50.00000;100.00000;2.92924;4
199.66400;55.99083;-5.801798e-003;50.00000;100.00000;2.92924;4
199.66600;56.12417;-5.909249e-003;50.00000;100.00000;2.92923;4
199.66701;56.25750;-5.968169e-003;50.00000;100.00000;2.92923;4
199.66901;56.39083;-6.065230e-003;50.00000;100.00000;2.92923;4
199.67000;56.52417;-6.193421e-003;50.00000;100.00000;2.92922;4
199.67101;56.65750;-6.283514e-003;50.00000;100.00000;2.92922;4
199.67200;56.79083;-6.314727e-003;50.00000;100.00000;2.92922;4
199.67400;56.92417;-6.349445e-003;50.00000;100.00000;2.92921;4
199.67599;57.05750;-6.401480e-003;50.00000;100.00000;2.92921;4
199.67799;57.19083;-6.432734e-003;50.00000;100.00000;2.92920;4
199.67900;57.32417;-6.415458e-003;50.00000;100.00000;2.92920;4
199.68100;57.45750;-6.474421e-003;50.00000;100.00000;2.92919;4
199.67900;57.59083;-6.547073e-003;50.00000;100.00000;2.92920;4
199.67999;57.72417;-6.647558e-003;50.00000;100.00000;2.92919;4
199.67999;57.85750;-6.751465e-003;50.00000;100.00000;2.92919;4
199.68300;57.99083;-6.678854e-003;50.00000;100.00000;2.92919;4
199.68300;58.12417;-6.706563e-003;50.00000;100.00000;2.92919;4
199.68300;58.25750;-6.734271e-003;50.00000;100.00000;2.92919;4
199.68401;58.39083;-6.730849e-003;50.00000;100.00000;2.92918;4
199.68700;58.52417;-6.696337e-003;50.00000;100.00000;2.92918;4
199.68401;58.65750;-6.786267e-003;50.00000;100.00000;2.92918;4
199.68500;58.79083;-6.869434e-003;50.00000;100.00000;2.92918;4
199.68800;58.92417;-6.855704e-003;50.00000;100.00000;2.92917;4
199.68800;59.05750;-6.841850e-003;50.00000;100.00000;2.92917;4
199.68900;59.19083;-6.834965e-003;50.00000;100.00000;2.92917;4
199.68900;59.32417;-6.900773e-003;50.00000;100.00000;2.92917;4
199.68900;59.45750;-6.966581e-003;50.00000;100.00000;2.92917;4
199.69000;59.59083;-6.886960e-003;50.00000;100.00000;2.92917;4
199.69099;59.72417;-6.880074e-003;50.00000;100.00000;2.92916;4
199.69000;59.85750;-6.855787e-003;50.00000;100.00000;2.92917;4
199.69200;59.99083;-6.866261e-003;50.00000;100.00000;2.92916;4
199.69200;60.12417;-6.921679e-003;50.00000;100.00000;2.92916;4
199.69099;60.25750;-6.918173e-003;50.00000;100.00000;2.92916;4
199.69200;60.39083;-6.963242e-003;50.00000;100.00000;2.92916;4
199.69200;60.52417;-6.945924e-003;50.00000;100.00000;2.92916;4
199.69400;60.65750;-6.894054e-003;50.00000;100.00000;2.92916;4
199.69501;60.79083;-6.862922e-003;50.00000;100.00000;2.92915;4
199.69299;60.92417;-6.862839e-003;50.00000;100.00000;2.92916;4
199.69501;61.05750;-6.866385e-003;50.00000;100.00000;2.92915;4
199.69600;61.19083;-6.862964e-003;50.00000;100.00000;2.92915;4
199.69501;61.32417;-6.876776e-003;50.00000;100.00000;2.92915;4
199.69800;61.45750;-6.859584e-003;50.00000;100.00000;2.92914;4
199.69701;61.59083;-6.845688e-003;50.00000;100.00000;2.92915;4
199.69901;61.72417;-6.866552e-003;50.00000;100.00000;2.92914;4
199.69901;61.85750;-6.883870e-003;50.00000;100.00000;2.92914;4
199.70000;61.99083;-6.811175e-003;50.00000;100.00000;2.92914;4
199.69901;62.12417;-6.852697e-003;50.00000;100.00000;2.92914;4
199.70000;62.25750;-6.915084e-003;50.00000;100.00000;2.92914;4
199.69901;62.39083;-6.925434e-003;50.00000;100.00000;2.92914;4
199.70100;62.52417;-6.918590e-003;50.00000;100.00000;2.92914;4
199.70000;62.65750;-6.873520e-003;50.00000;100.00000;2.92914;4
199.70100;62.79083;-6.887417e-003;50.00000;100.00000;2.92914;4
199.69901;62.92417;-6.883870e-003;50.00000;100.00000;2.92914;4
199.70100;63.05750;-6.901271e-003;50.00000;100.00000;2.92914;4
199.70000;63.19083;-6.967039e-003;50.00000;100.00000;2.92914;4
199.70100;63.32417;-6.946299e-003;50.00000;100.00000;2.92914;4
199.70300;63.45750;-6.908282e-003;50.00000;100.00000;2.92913;4
199.70300;63.59083;-6.897891e-003;50.00000;100.00000;2.92913;4
199.70300;63.72417;-6.863254e-003;50.00000;100.00000;2.92913;4
199.70399;63.85750;-6.835587e-003;50.00000;100.00000;2.92913;4
199.70399;63.99083;-6.929105e-003;50.00000;100.00000;2.92913;4
199.70200;64.12417;-6.974050e-003;50.00000;100.00000;2.92913;4
199.70500;64.25750;-6.991492e-003;50.00000;100.00000;2.92912;4
199.70399;64.39083;-7.008769e-003;50.00000;100.00000;2.92913;4
199.70300;64.52417;-7.022582e-003;50.00000;100.00000;2.92913;4
199.70399;64.65750;-7.046869e-003;50.00000;100.00000;2.92913;4
199.70399;64.79083;-7.036479e-003;50.00000;100.00000;2.92913;4
199.70300;64.92417;-7.036437e-003;50.00000;100.00000;2.92913;4
199.70300;65.05750;-7.147273e-003;50.00000;100.00000;2.92913;4
199.70399;65.19083;-7.098824e-003;50.00000;100.00000;2.92913;4
199.70500;65.32417;-7.039984e-003;50.00000;100.00000;2.92912;4
199.70399;65.45750;-7.057260e-003;50.00000;100.00000;2.92913;4
199.70599;65.59083;-7.040026e-003;50.00000;100.00000;2.92912;4
199.70399;65.72417;-7.026088e-003;50.00000;100.00000;2.92913;4
199.70599;65.85750;-7.043489e-003;50.00000;100.00000;2.92912;4
199.70599;65.99083;-6.998462e-003;50.00000;100.00000;2.92912;4
199.70500;66.12417;-7.019202e-003;50.00000;100.00000;2.92912;4
199.70700;66.25750;-7.043531e-003;50.00000;100.00000;2.92912;4
199.70599;66.39083;-7.029635e-003;50.00000;100.00000;2.92912;4
199.70599;66.52417;-7.060807e-003;50.00000;100.00000;2.92912;4
199.70599;66.65750;-7.053880e-003;50.00000;100.00000;2.92912;4
199.70799;66.79083;-7.060891e-003;50.00000;100.00000;2.92912;4
199.70700;66.92417;-7.074704e-003;50.00000;100.00000;2.92912;4
199.70700;67.05750;-7.053922e-003;50.00000;100.00000;2.92912;4
199.70799;67.19083;-7.060891e-003;50.00000;100.00000;2.92912;4
199.70700;67.32417;-7.012358e-003;50.00000;100.00000;2.92912;4
199.70700;67.45750;-6.946549e-003;50.00000;100.00000;2.92912;4
199.70900;67.59083;-6.911995e-003;50.00000;100.00000;2.92911;4
199.70799;67.72417;-6.925808e-003;50.00000;100.00000;2.92912;4
199.70799;67.85750;-6.953517e-003;50.00000;100.00000;2.92912;4
199.71001;67.99083;-6.963991e-003;50.00000;100.00000;2.92911;4
199.70900;68.12417;-6.901604e-003;50.00000;100.00000;2.92911;4
199.70799;68.25750;-7.005472e-003;50.00000;100.00000;2.92912;4
199.70700;68.39083;-7.040067e-003;50.00000;100.00000;2.92912;4
199.70900;68.52417;-7.047078e-003;50.00000;100.00000;2.92911;4
199.70900;68.65750;-7.043614e-003;50.00000;100.00000;2.92911;4
199.70799;68.79083;-7.015863e-003;50.00000;100.00000;2.92912;4
199.71001;68.92417;-6.995164e-003;50.00000;100.00000;2.92911;4
199.70900;69.05750;-7.015905e-003;50.00000;100.00000;2.92911;4
199.70900;69.19083;-7.005514e-003;50.00000;100.00000;2.92911;4
199.71001;69.32417;-7.029801e-003;50.00000;100.00000;2.92911;4
199.70900;69.45750;-7.012441e-003;50.00000;100.00000;2.92911;4
199.70900;69.59083;-7.029760e-003;50.00000;100.00000;2.92911;4
199.70799;69.72417;-7.092064e-003;50.00000;100.00000;2.92912;4
199.70799;69.85750;-7.154410e-003;50.00000;100.00000;2.92912;4
199.70900;69.99083;-7.123279e-003;50.00000;100.00000;2.92911;4
199.70799;70.12417;-7.098991e-003;50.00000;100.00000;2.92912;4
199.70700;70.25750;-7.119732e-003;50.00000;100.00000;2.92912;4
199.71001;70.39083;-7.057511e-003;50.00000;100.00000;2.92911;4
199.71001;70.52417;-6.998628e-003;50.00000;100.00000;2.92911;4
199.71001;70.65750;-6.977846e-003;50.00000;100.00000;2.92911;4
199.71201;70.79083;-6.964075e-003;50.00000;100.00000;2.92910;4
199.71201;70.92417;-6.960611e-003;50.00000;100.00000;2.92910;4
199.71100;71.05750;-6.960569e-003;50.00000;100.00000;2.92911;4
199.71100;71.19083;-6.967496e-003;50.00000;100.00000;2.92911;4
199.71100;71.32417;-6.988278e-003;50.00000;100.00000;2.92911;4
199.71001;71.45750;-6.998628e-003;50.00000;100.00000;2.92911;4
199.71100;71.59083;-7.033306e-003;50.00000;100.00000;2.92911;4
199.71001;71.72417;-7.099075e-003;50.00000;100.00000;2.92911;4
199.70900;71.85750;-7.116351e-003;50.00000;100.00000;2.92911;4
199.70900;71.99083;-7.119815e-003;50.00000;100.00000;2.92911;4
199.70900;72.12417;-7.130206e-003;50.00000;100.00000;2.92911;4
199.71100;72.25750;-7.050625e-003;50.00000;100.00000;2.92911;4
199.71001;72.39083;-7.064438e-003;50.00000;100.00000;2.92911;4
199.71100;72.52417;-7.095652e-003;50.00000;100.00000;2.92911;4
199.71100;72.65750;-7.112971e-003;50.00000;100.00000;2.92911;4
199.71100;72.79083;-7.106043e-003;50.00000;100.00000;2.92911;4
199.71100;72.92417;-7.088725e-003;50.00000;100.00000;2.92911;4
199.71001;73.05750;-7.029801e-003;50.00000;100.00000;2.92911;4
199.71201;73.19083;-7.067985e-003;50.00000;100.00000;2.92910;4
199.71100;73.32417;-7.106043e-003;50.00000;100.00000;2.92911;4
199.71001;73.45750;-7.071365e-003;50.00000;100.00000;2.92911;4
199.71100;73.59083;-7.061016e-003;50.00000;100.00000;2.92911;4
199.71100;73.72417;-7.099116e-003;50.00000;100.00000;2.92911;4
199.71201;73.85750;-7.123404e-003;50.00000;100.00000;2.92910;4
199.71001;73.99083;-7.119857e-003;50.00000;100.00000;2.92911;4
199.71201;74.12417;-7.078377e-003;50.00000;100.00000;2.92910;4
199.71201;74.25750;-7.040276e-003;50.00000;100.00000;2.92910;4
199.71100;74.39083;-7.078334e-003;50.00000;100.00000;2.92911;4
199.71100;74.52417;-7.147607e-003;50.00000;100.00000;2.92911;4
199.71001;74.65750;-7.241085e-003;50.00000;100.00000;2.92911;4
199.70900;74.79083;-7.289535e-003;50.00000;100.00000;2.92911;4
199.70900;74.92417;-7.303389e-003;50.00000;100.00000;2.92911;4
199.71001;75.05750;-7.265331e-003;50.00000;100.00000;2.92911;4
199.71001;75.19083;-7.178739e-003;50.00000;100.00000;2.92911;4
199.71001;75.32417;-7.178739e-003;50.00000;100.00000;2.92911;4
199.71001;75.45750;-7.157957e-003;50.00000;100.00000;2.92911;4
199.71001;75.59083;-7.161421e-003;50.00000;100.00000;2.92911;4
199.71001;75.72417;-7.137175e-003;50.00000;100.00000;2.92911;4
199.71001;75.85750;-7.133711e-003;50.00000;100.00000;2.92911;4
199.71001;75.99083;-7.144102e-003;50.00000;100.00000;2.92911;4
199.71100;76.12417;-7.130289e-003;50.00000;100.00000;2.92911;4
199.71100;76.25750;-7.099116e-003;50.00000;100.00000;2.92911;4
199.71001;76.39083;-7.064438e-003;50.00000;100.00000;2.92911;4
199.71100;76.52417;-7.050625e-003;50.00000;100.00000;2.92911;4
199.71201;76.65750;-6.995248e-003;50.00000;100.00000;2.92910;4
199.71300;76.79083;-6.998753e-003;50.00000;100.00000;2.92910;4
199.71001;76.92417;-7.060974e-003;50.00000;100.00000;2.92911;4
199.71100;77.05750;-7.106043e-003;50.00000;100.00000;2.92911;4
199.71201;77.19083;-7.144186e-003;50.00000;100.00000;2.92910;4
199.71100;77.32417;-7.164926e-003;50.00000;100.00000;2.92911;4
199.71001;77.45750;-7.234158e-003;50.00000;100.00000;2.92911;4
199.70900;77.59083;-7.289535e-003;50.00000;100.00000;2.92911;4
199.71001;77.72417;-7.303431e-003;50.00000;100.00000;2.92911;4
199.71001;77.85750;-7.244549e-003;50.00000;100.00000;2.92911;4
199.71100;77.99083;-7.140680e-003;50.00000;100.00000;2.92911;4
199.71001;78.12417;-7.123320e-003;50.00000;100.00000;2.92911;4
199.71100;78.25750;-7.033306e-003;50.00000;100.00000;2.92911;4
199.71100;78.39083;-7.050625e-003;50.00000;100.00000;2.92911;4
199.71201;78.52417;-7.061058e-003;50.00000;100.00000;2.92910;4
199.70599;78.65917;-7.313654e-003;50.00000;100.00000;2.92912;5
199.59399;78.79250;-1.496282e-002;50.00000;100.00000;2.92944;5
199.31900;78.92583;-3.566468e-002;50.00000;100.00000;2.93021;5
198.90601;79.05917;-6.701034e-002;50.00000;100.00000;2.93136;5
198.39000;79.19250;-0.10539;50.00000;100.00000;2.93279;5
197.78900;79.32583;-0.14768;50.00000;100.00000;2.93446;5
197.12601;79.45917;-0.19152;50.00000;100.00000;2.93628;5
196.41400;79.59250;-0.23519;50.00000;100.00000;2.93823;5
195.66600;79.72583;-0.27742;50.00000;100.00000;2.94027;5
194.88800;79.85917;-0.31744;50.00000;100.00000;2.94237;5
194.08600;79.99250;-0.35477;50.00000;100.00000;2.94453;5
193.26900;80.12583;-0.38923;50.00000;100.00000;2.94671;5
192.44000;80.25917;-0.42070;50.00000;100.00000;2.94890;5
191.59900;80.39250;-0.44919;50.00000;100.00000;2.95112;5
190.75000;80.52583;-0.47492;50.00000;100.00000;2.95333;5
189.89600;80.65917;-0.49796;50.00000;100.00000;2.95555;5
189.03700;80.79250;-0.51844;50.00000;100.00000;2.95776;5
188.17700;80.92583;-0.53656;50.00000;100.00000;2.95996;5
187.31400;81.05917;-0.55238;50.00000;100.00000;2.96214;5
186.45799;81.19250;-0.56587;50.00000;100.00000;2.96429;5
185.61200;81.32583;-0.57670;50.00000;100.00000;2.96640;5
184.78101;81.45917;-0.58480;50.00000;100.00000;2.96846;5
183.96700;81.59250;-0.59033;50.00000;100.00000;2.97046;5
183.17200;81.72583;-0.59345;50.00000;100.00000;2.97240;5
182.39301;81.85917;-0.59443;50.00000;100.00000;2.97428;5
181.63300;81.99250;-0.59361;50.00000;100.00000;2.97611;5
180.89000;82.12583;-0.59105;50.00000;100.00000;2.97788;5
180.16499;82.25917;-0.58719;50.00000;100.00000;2.97960;5
179.45500;82.39250;-0.58218;50.00000;100.00000;2.98126;5
178.76100;82.52583;-0.57628;50.00000;100.00000;2.98288;5
178.08200;82.65917;-0.56964;50.00000;100.00000;2.98446;5
177.41701;82.79250;-0.56242;50.00000;100.00000;2.98599;5
176.76401;82.92583;-0.55482;50.00000;100.00000;2.98748;5
176.12500;83.05917;-0.54691;50.00000;100.00000;2.98893;5
175.49800;83.19250;-0.53884;50.00000;100.00000;2.99034;5
174.88100;83.32583;-0.53066;50.00000;100.00000;2.99173;5
174.27499;83.45917;-0.52248;50.00000;100.00000;2.99308;5
173.67900;83.59250;-0.51438;50.00000;100.00000;2.99440;5
173.09300;83.72583;-0.50638;50.00000;100.00000;2.99568;5
172.51500;83.85917;-0.49853;50.00000;100.00000;2.99695;5
171.94400;83.99250;-0.49085;50.00000;100.00000;2.99819;5
171.38200;84.12583;-0.48338;50.00000;100.00000;2.99940;5
170.82600;84.25917;-0.47615;50.00000;100.00000;3.00059;5
170.27699;84.39250;-0.46914;50.00000;100.00000;3.00176;5
169.73500;84.52583;-0.46236;50.00000;100.00000;3.00291;5
169.20000;84.65917;-0.45588;50.00000;100.00000;3.00403;5
168.67101;84.79250;-0.44961;50.00000;100.00000;3.00514;5
168.14600;84.92583;-0.44362;50.00000;100.00000;3.00623;5
167.62700;85.05917;-0.43784;50.00000;100.00000;3.00730;5
167.11200;85.19250;-0.43228;50.00000;100.00000;3.00836;5
166.60201;85.32583;-0.42698;50.00000;100.00000;3.00940;5
166.09900;85.45917;-0.42187;50.00000;100.00000;3.01042;5
165.59801;85.59250;-0.41699;50.00000;100.00000;3.01144;5
165.10201;85.72583;-0.41236;50.00000;100.00000;3.01243;5
164.61000;85.85917;-0.40784;50.00000;100.00000;3.01341;5
164.12100;85.99250;-0.40355;50.00000;100.00000;3.01438;5
163.63600;86.12583;-0.39939;50.00000;100.00000;3.01534;5
163.15401;86.25917;-0.39540;50.00000;100.00000;3.01628;5
162.67599;86.39250;-0.39158;50.00000;100.00000;3.01721;5
162.20399;86.52583;-0.38791;50.00000;100.00000;3.01812;5
161.73199;86.65917;-0.38435;50.00000;100.00000;3.01903;5
161.26601;86.79250;-0.38094;50.00000;100.00000;3.01992;5
160.80099;86.92583;-0.37765;50.00000;100.00000;3.02081;5
160.34000;87.05917;-0.37450;50.00000;100.00000;3.02168;5
159.88300;87.19250;-0.37140;50.00000;100.00000;3.02254;5
159.42700;87.32583;-0.36845;50.00000;100.00000;3.02339;5
158.97501;87.45917;-0.36558;50.00000;100.00000;3.02423;5
158.52499;87.59250;-0.36278;50.00000;100.00000;3.02506;5
158.07700;87.72583;-0.36009;50.00000;100.00000;3.02588;5
157.63400;87.85917;-0.35749;50.00000;100.00000;3.02668;5
157.19299;87.99250;-0.35490;50.00000;100.00000;3.02748;5
156.75400;88.12583;-0.35245;50.00000;100.00000;3.02827;5
156.31700;88.25917;-0.35002;50.00000;100.00000;3.02906;5
155.88400;88.39250;-0.34767;50.00000;100.00000;3.02983;5
155.45200;88.52583;-0.34540;50.00000;100.00000;3.03059;5
155.02200;88.65917;-0.34313;50.00000;100.00000;3.03135;5
154.59599;88.79250;-0.34095;50.00000;100.00000;3.03209;5
154.17200;88.92583;-0.33880;50.00000;100.00000;3.03283;5
153.75200;89.05917;-0.33669;50.00000;100.00000;3.03356;5
153.33200;89.19250;-0.33464;50.00000;100.00000;3.03428;5
152.91400;89.32583;-0.33262;50.00000;100.00000;3.03499;5
152.50000;89.45917;-0.33065;50.00000;100.00000;3.03569;5
152.08800;89.59250;-0.32869;50.00000;100.00000;3.03639;5
151.67599;89.72583;-0.32680;50.00000;100.00000;3.03708;5
151.26801;89.85917;-0.32493;50.00000;100.00000;3.03776;5
150.86200;89.99250;-0.32309;50.00000;100.00000;3.03843;5
150.45700;90.12583;-0.32128;50.00000;100.00000;3.03909;5
150.05499;90.25917;-0.31949;50.00000;100.00000;3.03975;5
149.65401;90.39250;-0.31773;50.00000;100.00000;3.04040;5
149.25500;90.52583;-0.31601;50.00000;100.00000;3.04105;5
148.86099;90.65917;-0.31430;50.00000;100.00000;3.04168;5
148.46700;90.79250;-0.31260;50.00000;100.00000;3.04231;5
148.07300;90.92583;-0.31101;50.00000;100.00000;3.04293;5
147.68401;91.05917;-0.30934;50.00000;100.00000;3.04355;5
147.29500;91.19250;-0.30774;50.00000;100.00000;3.04416;5
146.90900;91.32583;-0.30613;50.00000;100.00000;3.04476;5
146.52400;91.45917;-0.30459;50.00000;100.00000;3.04535;5
146.14200;91.59250;-0.30302;50.00000;100.00000;3.04594;5
145.76100;91.72583;-0.30151;50.00000;100.00000;3.04652;5
145.38200;91.85917;-0.30002;50.00000;100.00000;3.04710;5
145.00500;91.99250;-0.29850;50.00000;100.00000;3.04767;5
144.63000;92.12583;-0.29699;50.00000;100.00000;3.04823;5
144.25500;92.25917;-0.29552;50.00000;100.00000;3.04879;5
143.88400;92.39250;-0.29407;50.00000;100.00000;3.04934;5
143.51401;92.52583;-0.29260;50.00000;100.00000;3.04988;5
143.14600;92.65917;-0.29118;50.00000;100.00000;3.05042;5
142.78000;92.79250;-0.28973;50.00000;100.00000;3.05095;5
142.41400;92.92583;-0.28834;50.00000;100.00000;3.05148;5
142.05200;93.05917;-0.28694;50.00000;100.00000;3.05200;5
141.69000;93.19250;-0.28557;50.00000;100.00000;3.05252;5
141.33099;93.32583;-0.28421;50.00000;100.00000;3.05302;5
140.97301;93.45917;-0.28281;50.00000;100.00000;3.05353;5
140.61600;93.59250;-0.28149;50.00000;100.00000;3.05403;5
140.26300;93.72583;-0.28016;50.00000;100.00000;3.05452;5
139.90900;93.85917;-0.27882;50.00000;100.00000;3.05501;5
139.55800;93.99250;-0.27751;50.00000;100.00000;3.05549;5
139.20700;94.12583;-0.27620;50.00000;100.00000;3.05597;5
138.86099;94.25917;-0.27490;50.00000;100.00000;3.05643;5
138.51401;94.39250;-0.27364;50.00000;100.00000;3.05690;5
138.16800;94.52583;-0.27238;50.00000;100.00000;3.05736;5
137.82500;94.65917;-0.27111;50.00000;100.00000;3.05782;5
137.48500;94.79250;-0.26988;50.00000;100.00000;3.05827;5
137.14400;94.92583;-0.26865;50.00000;100.00000;3.05871;5
136.80499;95.05917;-0.26743;50.00000;100.00000;3.05916;5
136.46800;95.19250;-0.26624;50.00000;100.00000;3.05959;5
136.13200;95.32583;-0.26502;50.00000;100.00000;3.06002;5
135.79700;95.45917;-0.26382;50.00000;100.00000;3.06045;5
135.46400;95.59250;-0.26264;50.00000;100.00000;3.06087;5
135.13300;95.72583;-0.26143;50.00000;100.00000;3.06129;5
134.80499;95.85917;-0.26028;50.00000;100.00000;3.06170;5
134.47600;95.99250;-0.25916;50.00000;100.00000;3.06211;5
134.14900;96.12583;-0.25801;50.00000;100.00000;3.06251;5
133.82201;96.25917;-0.25685;50.00000;100.00000;3.06291;5
133.49899;96.39250;-0.25572;50.00000;100.00000;3.06331;5
133.17599;96.52583;-0.25462;50.00000;100.00000;3.06370;5
132.85400;96.65917;-0.25351;50.00000;100.00000;3.06409;5
132.53600;96.79250;-0.25242;50.00000;100.00000;3.06446;5
132.21500;96.92583;-0.25132;50.00000;100.00000;3.06485;5
131.89900;97.05917;-0.25022;50.00000;100.00000;3.06522;5
131.58400;97.19250;-0.24912;50.00000;100.00000;3.06559;5
131.26801;97.32583;-0.24810;50.00000;100.00000;3.06595;5
130.95599;97.45917;-0.24701;50.00000;100.00000;3.06631;5
130.64400;97.59250;-0.24592;50.00000;100.00000;3.06667;5
130.33501;97.72583;-0.24486;50.00000;100.00000;3.06702;5
130.02600;97.85917;-0.24384;50.00000;100.00000;3.06737;5
129.71700;97.99250;-0.24279;50.00000;100.00000;3.06772;5
129.41100;98.12583;-0.24175;50.00000;100.00000;3.06806;5
129.10600;98.25917;-0.24075;50.00000;100.00000;3.06839;5
128.80200;98.39250;-0.23971;50.00000;100.00000;3.06873;5
128.50000;98.52583;-0.23871;50.00000;100.00000;3.06906;5
128.19901;98.65917;-0.23770;50.00000;100.00000;3.06938;5
127.90000;98.79250;-0.23673;50.00000;100.00000;3.06970;5
127.59900;98.92583;-0.23574;50.00000;100.00000;3.07003;5
127.30200;99.05917;-0.23476;50.00000;100.00000;3.07034;5
127.00600;99.19250;-0.23380;50.00000;100.00000;3.07065;5
126.71000;99.32583;-0.23284;50.00000;100.00000;3.07096;5
126.41500;99.45917;-0.23187;50.00000;100.00000;3.07127;5
126.12200;99.59250;-0.23090;50.00000;100.00000;3.07157;5
125.83100;99.72583;-0.22997;50.00000;100.00000;3.07186;5
125.54100;99.85917;-0.22907;50.00000;100.00000;3.07216;5
125.25200;99.99250;-0.22813;50.00000;100.00000;3.07245;5